Workbook

Sheet 동구 은어송삼성성남가양
A1: 날짜 | B1: 26.12.25(토) | C1: 데이 | R1: 2026.4.25.토
B2: 시간 | C2: 0.375 | G2: 0.4375 | J2: 0.48611111 | N2: 0.60416667 | R2: 그늘
R3: 0.66666667
B4: 동 | N4: 4/23 계약
A5: 아파트명 | C5: 신흥SK뷰 | D5: 신흥SK뷰 | E5: 신흥SK뷰 | F5: 신흥SK뷰 | G5: 은어송하늘채리버뷰 | H5: 은어송하늘채리버뷰 | I5: 은어송하늘채리버뷰 | J5: 은어송2단지하늘채 | K5: 은어송2단지하늘채 | L5: 은어송2단지하늘채 | M5: 은어송3단지아이파크 | N5: 힐스테이트가양더와이즈 | O5: 힐스테이트가양더와이즈 | P5: 힐스테이트가양더와이즈 | Q5: 힐스테이트가양더와이즈 | R5: 한밭자이 | S5: 한밭자이 | T5: 한밭자이 | U5: 스마트뷰 | V5: 스마트뷰 | W5: 스마트뷰 | X5: 아침LH | Y5: 아침LH | Z5: 아침LH | AA5: 아침LH
A6: No. | C6: =COLUMN()-2 -> 1 | D6: =COLUMN()-2 -> 2 | E6: =COLUMN()-2 -> 3 | F6: =COLUMN()-2 -> 4 | G6: =COLUMN()-2 -> 5 | H6: =COLUMN()-2 -> 6 | I6: =COLUMN()-2 -> 7 | J6: =COLUMN()-2 -> 8 | ... DE6: =COLUMN()-2 -> 107
A7: 중개 | B7: 부동산 | C7: 어진마을공인 | D7: 어진마을공인 | E7: 어진마을공인 | F7: 어진마을공인 | G7: 하늘채박사공인(남) | H7: 하늘채박사공인(남) | I7: 하늘채박사공인(남) | J7: 코오롱하늘채공인 | K7: 코오롱하늘채공인 | L7: 코오롱하늘채공인 | M7: 코오롱하늘채공인 | N7: 착한공인 | O7: 착한공인 | P7: 착한공인 | Q7: 착한공인 | R7: 삼성자이 | S7: 삼성자이 | T7: 삼성자이 | U7: 스마트뷰대박 | V7: 스마트뷰대박 | W7: 스마트뷰대박 | X7: 아침현대공인 | Y7: 아침현대공인 | Z7: 아침현대공인 | AA7: 아침현대공인
B8: 연락처 | C8: 010-9784-3360 | D8: 010-9784-3360 | E8: 010-9784-3360 | F8: 010-9784-3360 | G8: 010-9490-7442 | H8: 010-9490-7442 | I8: 010-9490-7442 | J8: 010-5463-2025 | K8: 010-5463-2025 | L8: 010-5463-2025 | M8: 010-5463-2025 | N8: 010-7799-1554 | O8: 010-7799-1554 | P8: 010-7799-1554 | Q8: 010-7799-1554 | R8: 010-7627-4247 | S8: 010-7627-4247 | T8: 010-7627-4247 | U8: 042-635-4545 | V8: 042-635-4545 | W8: 042-635-4545 | X8: 010-3062-8207 | Y8: 010-3062-8207 | Z8: 010-3062-8208 | AA8: 010-3062-8209
B9: 주소 및 만남장소 | C9: 신흥SK뷰 지하2층 106동 1라인 | D9: 부동산주소: 동구 계족로 65 상가동 102동 (인동, 어진마을A) | F9: 대전 동구 대전로 357 은어송하늘채리버뷰아파트 근린상가 105호 | J9: 대전시 동구 동구청로35, 상가동103호 (대성동, 은어송마을2단지) | N9: 힐스테이트 1층 에스컬레이터 앞 (부동산주소: 대전시 동구 대동 160-1번지 3층)
A10: 아파트 | B10: 연식 | C10: 2022 | D10: 2022 | E10: 2022 | F10: 2022 | G10: 2024 | H10: 2024 | I10: 2024 | J10: 2007 | K10: 2007 | L10: 2007 | M10: 2006 | N10: 2024 | O10: 2024 | P10: 2024 | Q10: 2024 | R10: 2006 | S10: 2006 | T10: 2006 | U10: 2011 | V10: 2011 | W10: 2011 | X10: 2011 | Y10: 2011 | Z10: 2011 | AA10: 2011
B11: 세대수 | C11: 1588 | D11: 1588 | E11: 1588 | F11: 1588 | G11: 934 | H11: 934 | I11: 934 | J11: 1241 | K11: 1241 | L11: 1241 | M11: 696 | N11: 358 | O11: 358 | P11: 358 | Q11: 358 | R11: 1063 | S11: 1063 | T11: 1063 | U11: 1115 | V11: 1115 | W11: 1115 | X11: 1025 | Y11: 1025 | Z11: 1025 | AA11: 1025
B12: 평형 | C12: 24A | D12: 24A | E12: 24A | F12: 24B | G12: 33A | H12: 33A | I12: 33C | J12: 33A | K12: 33A | L12: 33B | M12: 36A | N12: 34B | O12: 34A | P12: 34A | Q12: 34A | R12: 35 | S12: 35 | T12: 35 | U12: 33b | V12: 33b | W12: 33b | X12: 34A-1 | Y12: 34A-1 | Z12: 34A-2 | AA12: 34A-3
B13: 동호수 | C13: 111-9 | D13: 106-7 | E13: 104-501 | G13: 107-15 | H13: 108-1904 | I13: 101-5 | J13: 202-고 | K13: 205-10 | M13: 304-17 | N13: 102-41 | O13: 101-1201 | P13: 102-501 | R13: 102-4층 | U13: 107-1001 | V13: 103-2302 | W13: 104-401 | X13: 116-6 | Y13: 103-15 | Z13: 102-13 | AA13: 116-14
B14: 구조 | C14: 계단식 | D14: 계단식 | E14: 계단식 | F14: 계단식 | G14: 계단식 | H14: 계단식 | I14: 계단식 | J14: 계단식 | K14: 계단식 | L14: 계단식 | M14: 계단식 | N14: 계단식 | O14: 계단식 | P14: 계단식 | Q14: 계단식 | R14: 계단식 | S14: 계단식 | T14: 계단식 | U14: 계단식 | V14: 계단식 | W14: 계단식 | X14: 계단식 | Y14: 계단식 | Z14: 계단식 | AA14: 계단식
B15: 타입 | C15: 방3화2 | D15: 방3화2 | E15: 방3화2 | F15: 방3화2 | G15: 방3화2 | H15: 방3화2 | I15: 방3화2 | J15: 방3화2 | K15: 방3화2 | L15: 방3화2 | M15: 방3화2 | N15: 방3화2 | O15: 방3화2 | P15: 방3화2 | Q15: 방3화2 | R15: 방3화2 | S15: 방3화2 | T15: 방3화2 | U15: 방3화2 | V15: 방3화2 | W15: 방3화2 | X15: 방3화2 | Y15: 방3화2 | Z15: 방3화2 | AA15: 방3화2
B16: 방향 | C16: 남동향 | D16: 남동향 | E16: 남동향 | G16: 남동향 | H16: 남서향 | I16: 남동향 | J16: 남동향 | K16: 남서향 | M16: 남동향 | N16: 남동향 | O16: 남동향 | P16: 남서향 | R16: 남동향 | U16: 남동향 | V16: 남동향 | W16: 남동향 | X16: 남향 | Y16: 남동향 | Z16: 남동향 | AA16: 남동향
A17: 상황 | B17: 거주자 | C17: 집주인 | D17: 세입자 | E17: 세입자 | J17: 집주인 | N17: 공실 | O17: 집주인 | P17: 집주인 | U17: 세입자 | V17: 세입자 | W17: 세입자 | X17: 공실
B18: 이사사유 | C18: 2.부부 다큰남자애 | D18: 1.남자혼자 시에2 | E18: 3.아들2애기
B19: 만기일 | C19: 에4 | D19: 26.6.29 이사 | E19: 26.6.8 이사 | V19: 2026.7
B20: 특이사항 | C20: 전망좋음(사이뷰, 정원뷰) 중간라인 시에4대, 줄눈, 집관리 굿, 상태최상, 현재 공실이라 전세 맞추기 굿. 24평 전세가 3억~3.2억 가능. 24평 천변뷰107,108,109 벽지하자많 | D20: 로얄동 로얄층. (정문,지하철 근접) 시에 2대, 정원전망, 햇볓 잘 들고 관리잘됨. 현재 세입자 있지만 26.6월29일 만기 퇴거 현 시세 신규계약 가능. 전세 3.2억 자신있으심. | E20: 정문 가까운 동. 교통 상권 편리 정원뷰, 사이 트인 식장산뷰, 상태 굿. 현재 세입자 있지만 26.6월8일 만기 퇴거 현 시세 신규계약 가능. 전세 3.2억 자신있으심. 시에없어 기본 관리는잘돼중학교뷰 | G20: 천변뷰 A형 시스템에어컨등 옵션다수 가격 조정 가능 (4.65) 33평 전세가 3.3~3.5억 가능 전세대기자 2명. 다 천-천오백정도 깎아야 | H20: 시스템에어컨4대 등 풀옵션, 인근 초중교 위치, 천변뷰와 식장산뷰 어우러진 최고의 뷰. 풀인테리어. (화이트) | I20: 초등학교 인근 101동, 에어컨 4개 등 옵션 다수, 가격 조율 가능 | J20: 로얄동 로얄층 A형구조 방1 확장. | K20: 로얄동, 로얄층, 기본형 | M20: 선호동,입구동,기본형, 전실 큰 구조. | N20: 매도인이 잔금 못쳐서 전매된 물건. 급매. 공실 된지 5개월 B타입은 거실이 약간 사선이라서 요게 단점. | O20: 12층.84A최저가. 마피2천960만원. 밝은거실 에어컨5. 첫입주 | P20: 신축첫입주. 84A타입 발코니 무상지원 | R20: 선호동 | U20: 조용한동.전실,중문.전세 안고 매매 | V20: 로얄동로얄층.주출입구인접한조용한동.상태깨끗.7월중협의입주 층이높아개방감있음 | W20: 전세끼고매매 소액으로 투자가능 올수리 깔끔해요 | X20: 조망좋은 앞라인, 보일러교체, 집상태 좋음, 즉시입주가능 초등인접 | Y20: 선호동,층 밝고 환한집, 협의입주. | Z20: 구조좋은 로얄층, 생활 편의시설 이용하기 좋은동, 즉시입주 | AA20: 조망좋은 앞라인 따뜻한 집, 협의입주 관리 잘되어깔끔.
A21: 가격 | B21: 매매가 | C21: 40500 | D21: 41000 | E21: 41000 | G21: 48000 | H21: 48000 | I21: 46500 | J21: 36000 | K21: 36500 | M21: 34000 | N21: 49000 | O21: 52000 | P21: 52500 | R21: 33000 | U21: 36000 | V21: 34000 | W21: 36000 | X21: 37000 | Y21: 38000 | Z21: 37000 | AA21: 37500
B22: 협의매매가 | C22: 39500 | D22: 40000 | E22: 40500 | G22: 46500 | H22: 47000 | I22: 45000 | J22: 35000 | K22: 35500 | M22: 33000 | N22: 49000 | O22: 52000 | P22: 52000 | R22: 33000 | X22: 36000
B23: 전세가 | C23: 32000 | D23: 32000 | E23: 32000 | F23: 32000 | G23: 33000 | H23: 33000 | I23: 33000 | J23: 30000 | K23: 30000 | L23: 30000 | N23: 38000 | O23: 38000 | P23: 38000 | R23: 27000 | W23: 26000
B24: 매전차이 | C24: =C22-C23 -> 7500 | D24: =D22-D23 -> 8000 | E24: =E22-E23 -> 8500 | F24: =F22-F23 -> -32000 | G24: =G22-G23 -> 13500 | H24: =H22-H23 -> 14000 | I24: =I22-I23 -> 12000 | J24: =J22-J23 -> 5000 | ... P24: =P22-P23 -> 14000 | R24: =R22-R23 -> 6000 | S24: =S22-S23 -> 0 | T24: =T22-T23 -> 0 | U24: =U22-U23 -> 0 | V24: =V22-V23 -> 0 | W24: =W22-W23 -> -26000 | X24: =X22-X23 -> 36000 | Y24: =Y22-Y23 -> 0 | ... DE24: =DE22-DE23 -> 0
B25: 전세가율 | C25: =C23/C21 -> 0.79012346 | D25: =D23/D21 -> 0.7804878 | E25: =E23/E21 -> 0.7804878 | F25: =F23/F21 -> #DIV/0! | G25: =G23/G21 -> 0.6875 | H25: =H23/H21 -> 0.6875 | I25: =I23/I21 -> 0.70967742 | J25: =J23/J21 -> 0.83333333 | ... P25: =P23/P21 -> 0.72380952 | R25: =R23/R21 -> 0.81818182 | S25: =S23/S21 -> #DIV/0! | T25: =T23/T21 -> #DIV/0! | U25: =U23/U21 -> 0 | V25: =V23/V21 -> 0 | W25: =W23/W21 -> 0.72222222 | X25: =X23/X21 -> 0 | Y25: =Y23/Y21 -> 0 | ... AY25: =AY23/AY21 -> #DIV/0!
B26: 부동산 복비(0.4%) | C26: =C22*0.004 -> 158 | D26: =D22*0.004 -> 160 | E26: =E22*0.004 -> 162 | F26: =F22*0.004 -> 0 | G26: =G22*0.004 -> 186 | H26: =H22*0.004 -> 188 | I26: =I22*0.004 -> 180 | J26: =J22*0.004 -> 140 | ... P26: =P22*0.004 -> 208 | R26: =R22*0.004 -> 132 | S26: =S22*0.004 -> 0 | T26: =T22*0.004 -> 0 | U26: =U22*0.004 -> 0 | V26: =V22*0.004 -> 0 | W26: =W22*0.004 -> 0 | X26: =X22*0.004 -> 144 | Y26: =Y22*0.004 -> 0 | ... DE26: =DE22*0.004 -> 0
B27: 법무 등기비(20) | C27: 20 | D27: 20 | E27: 20 | F27: 20 | G27: 20 | H27: 20 | I27: 20 | J27: 20 | K27: 20 | L27: 20 | M27: 20 | N27: 20 | O27: 20 | P27: 20 | R27: 20 | S27: 20 | T27: 20 | U27: 20 | V27: 20 | W27: 20 | X27: 20 | Y27: 20 | Z27: 20 | AA27: 20 | AB27: 20 | AC27: 20 | AD27: 20 | AE27: 20 | AF27: 20 | AG27: 20 | AH27: 20 | AI27: 20 | AJ27: 20 | AK27: 20 | AL27: 20 | AM27: 20 | AN27: 20 | AO27: 20 | AP27: 20 | AQ27: 20 | AR27: 20 | AS27: 20 | AT27: 20 | AU27: 20 | AV27: 20 | AW27: 20 | AX27: 20 | AY27: 20 | AZ27: 20 | BA27: 20 | BB27: 20 | BC27: 20 | BD27: 20 | BE27: 20 | BF27: 20 | BG27: 20 | BH27: 20 | BI27: 20 | BJ27: 20 | BK27: 20 | BL27: 20 | BM27: 20 | BN27: 20 | BO27: 20 | BP27: 20 | BQ27: 20 | BR27: 20 | BS27: 20 | BT27: 20 | BU27: 20 | BV27: 20 | BW27: 20 | BX27: 20 | BY27: 20 | BZ27: 20 | CA27: 20 | CB27: 20 | CC27: 20 | CD27: 20 | CE27: 20 | CF27: 20 | CG27: 20 | CH27: 20 | CI27: 20 | CJ27: 20 | CK27: 20 | CL27: 20 | CM27: 20 | CN27: 20 | CO27: 20 | CP27: 20 | CQ27: 20 | CR27: 20 | CS27: 20 | CT27: 20 | CU27: 20 | CV27: 20 | CW27: 20 | CX27: 20 | CY27: 20 | CZ27: 20 | DA27: 20 | DB27: 20 | DC27: 20 | DD27: 20 | DE27: 20
B28: 취득세(1.1%) | C28: =C22*0.011 -> 434.5 | D28: =D22*0.011 -> 440 | E28: =E22*0.011 -> 445.5 | F28: =F22*0.011 -> 0 | G28: =G22*0.011 -> 511.5 | H28: =H22*0.011 -> 517 | I28: =I22*0.011 -> 495 | J28: =J22*0.011 -> 385 | ... P28: =P22*0.011 -> 572 | R28: =R22*0.011 -> 363 | S28: =S22*0.011 -> 0 | T28: =T22*0.011 -> 0 | U28: =U22*0.011 -> 0 | V28: =V22*0.011 -> 0 | W28: =W22*0.011 -> 0 | X28: =X22*0.011 -> 396 | Y28: =Y22*0.011 -> 0 | ... DE28: =DE22*0.011 -> 0
B29: 예상 수리비 | C29: =C43 -> 0 | D29: =D43 -> 0 | E29: =E43 -> 0 | F29: =F43 -> 0 | G29: =G43 -> 0 | H29: =H43 -> 0 | I29: =I43 -> 0 | J29: =J43 -> 0 | ... P29: =P43 | R29: =R43 -> 0 | S29: =S43 -> 0 | T29: =T43 -> 0 | U29: =U43 -> #REF! | V29: =V43 -> 0 | W29: =W43 -> 0 | X29: =X43 -> 0 | Y29: =Y43 -> 0 | ... DE29: =DE43 -> 0
B30: 실 투자금 | C30: =sum(C24,C26,C27,C28,C29) -> 8112.5 | D30: =sum(D24,D26,D27,D28,D29) -> 8620 | E30: =sum(E24,E26,E27,E28,E29) -> 9127.5 | F30: =sum(F24,F26,F27,F28,F29) -> -31980 | G30: =sum(G24,G26,G27,G28,G29) -> 14217.5 | H30: =sum(H24,H26,H27,H28,H29) -> 14725 | I30: =sum(I24,I26,I27,I28,I29) -> 12695 | J30: =sum(J24,J26,J27,J28,J29) -> 5545 | ... P30: =sum(P24,P26,P27,P28,P29) -> 14800 | R30: =sum(R24,R26,R27,R28,R29) -> 6515 | S30: =sum(S24,S26,S27,S28,S29) -> 20 | T30: =sum(T24,T26,T27,T28,T29) -> 20 | U30: =sum(U24,U26,U27,U28,U29) -> #REF! | V30: =sum(V24,V26,V27,V28,V29) -> 20 | W30: =sum(W24,W26,W27,W28,W29) -> -25980 | X30: =sum(X24,X26,X27,X28,X29) -> 36560 | Y30: =sum(Y24,Y26,Y27,Y28,Y29) -> 20 | ... DE30: =sum(DE24,DE26,DE27,DE28,DE29) -> 20
B31: 200% 수익 매도가 | C31: =C22+C30*2 -> 55725 | D31: =D22+D30*2 -> 57240 | E31: =E22+E30*2 -> 58755 | F31: =F22+F30*2 -> -63960 | G31: =G22+G30*2 -> 74935 | H31: =H22+H30*2 -> 76450 | I31: =I22+I30*2 -> 70390 | J31: =J22+J30*2 -> 46090 | ... P31: =P22+P30*2 -> 81600 | R31: =R22+R30*2 -> 46030 | S31: =S22+S30*2 -> 40 | T31: =T22+T30*2 -> 40 | U31: =U22+U30*2 -> #REF! | V31: =V22+V30*2 -> 40 | W31: =W22+W30*2 -> -51960 | X31: =X22+X30*2 -> 109120 | Y31: =Y22+Y30*2 -> 40 | ... DE31: =DE22+DE30*2 -> 40
B32: 특이사항
A33: 수리 | B33: 욕실
B34: UBR욕실
B35: 싱크대
B36: 신발장
B37: 도배,장판
B38: 샷시
B39: 베란다수납장
B40: 조명
...

Sheet 동구 신흥판암
A1: 날짜 | B1: 2026.4.18(토)
B3: 시간 | C3: 0.39583333 | E3: 0.59722222 | H3: 0.45833333 | K3: 0.54166667 | L3: 0.55208333 | M3: 0.5625 | O3: 0.625 | T3: 0.6875 | Z3: 0.75
C4: 대동 | D4: 대동 | E4: 대동 | F4: 대동 | G4: 대동 | H4: 신흥동 | I4: 신흥동 | J4: 신흥동 | K4: 신흥동 | L4: 신흥동 | M4: 대동 | N4: 신흥동 | O4: 천동 | P4: 천동 | Q4: 천동 | R4: 천동 | S4: 천동 | T4: 용운동 | X4: x | Z4: 판암동
A5: 아파트명 | C5: 이스트시티1단지 | D5: 이스트시티1단지 | E5: 이스트시티1단지 | F5: 이스트시티1단지 | G5: 이스트시티1단지 | H5: 신흥SK뷰 | I5: 신흥SK뷰 | J5: 신흥SK뷰 | K5: 신흥SK뷰 | L5: 신흥SK뷰 | M5: 새들뫼휴먼시아1단지 | N5: 이스트시티2단지 | O5: 리더스시티4 | P5: 리더스시티4 | Q5: 리더스시티4 | R5: 리더스시티5 | S5: 리더스시티5 | T5: 이편한세상대전에코포레 | U5: 이편한세상대전에코포레 | V5: 이편한세상대전에코포레 | W5: 이편한세상대전에코포레 | X5: 이편한세상대전에코포레 | Y5: 이편한세상대전에코포레 | Z5: 판암삼정그린코아1단지 | AA5: 판암삼정그린코아1단지 | AB5: 판암삼정그린코아1단지 | AC5: 판암삼정그린코아1단지 | AD5: 판암삼정그린코아1단지 | AE5: 판암삼정그린코아2단지 | AF5: 판암삼정그린코아2단지
A6: No. | C6: =COLUMN()-2 -> 1 | D6: =COLUMN()-2 -> 2 | E6: =COLUMN()-2 -> 3 | F6: =COLUMN()-2 -> 4 | G6: =COLUMN()-2 -> 5 | H6: =COLUMN()-2 -> 6 | I6: =COLUMN()-2 -> 7 | J6: =COLUMN()-2 -> 8 | ... U6: =COLUMN()-2 -> 19 | V6: 19 | W6: 20 | X6: 21 | Z6: 22 | AA6: 23 | AB6: =COLUMN()-2 -> 26 | AC6: =COLUMN()-2 -> 27 | AD6: =COLUMN()-2 -> 28 | AE6: =COLUMN()-2 -> 29 | AF6: =COLUMN()-2 -> 30 | AO6: =COLUMN()-2 -> 39 | AP6: =COLUMN()-2 -> 40 | AQ6: =COLUMN()-2 -> 41 | AR6: =COLUMN()-2 -> 42 | AS6: =COLUMN()-2 -> 43 | AT6: =COLUMN()-2 -> 44 | AU6: =COLUMN()-2 -> 45 | AV6: =COLUMN()-2 -> 46 | ... CZ6: =COLUMN()-2 -> 102
A7: 중개 | B7: 부동산 | C7: 이스트사랑 | D7: 이스트사랑 | E7: 이스트사랑 | F7: 이스트사랑 | G7: 이스트사랑 | H7: 이스트박사 | I7: 이스트박사 | J7: 이스트박사 | K7: 이스트박사 | L7: 이스트박사 | M7: 새들뫼공인중개 | N7: 새들뫼공인중개 | O7: 리더스시티공인 | P7: 리더스시티공인 | Q7: 리더스시티공인 | R7: 리더스시티공인 | S7: 리더스시티공인 | T7: 에코포레합동/에코포레공인 | U7: 에코포레합동/에코포레공인 | V7: 에코포레합동/에코포레공인 | W7: 에코포레합동/에코포레공인 | X7: 에코포레합동/에코포레공인 | Y7: 에코포레합동/에코포레공인 | Z7: 삼정코아행복공인 | AA7: 삼정코아행복공인 | AB7: 삼정코아행복공인 | AC7: 삼정코아행복공인 | AD7: 삼정코아행복공인 | AE7: 삼정코아행복공인 | AF7: 삼정코아행복공인
B8: 연락처 | C8: 010-9767-3823 | D8: 010-9767-3823 | E8: 010-9767-3823 | F8: 010-9767-3823 | G8: 010-9767-3823 | H8: 010-6371-5951 | I8: 010-6371-5951 | J8: 010-6371-5951 | K8: 010-6371-5951 | L8: 010-6371-5951 | M8: 010-3270-6200 | N8: 010-3270-6200 | O8: 010-6759-9050 | P8: 010-6759-9050 | Q8: 010-6759-9050 | R8: 010-6759-9050 | S8: 010-6759-9050 | T8: 010-3466-9100 | U8: 010-3466-9100 | V8: 010-3466-9100 | W8: 010-3466-9100 | X8: 010-3466-9100 | Y8: 010-3466-9101 | Z8: 010-5388-8266 | AA8: 010-5388-8266 | AB8: 010-5388-8266 | AC8: 010-5388-8266 | AD8: 010-5388-8266 | AE8: 010-5388-8266 | AF8: 010-5388-8266
B9: 주소 및 만남장소 | C9: 대전광역시 동구 동대전로46번길 30, 상가동 103호 (대동, 이스트시티1단지) | H9: 대전광역시 동구 동대전로46번길 30(대동, 이스트시티1단지),상가 105호 | M9: 대전 동구 대동527 새들뫼휴먼시아상가동103호 | O9: 대전광역시 동구 안샘로 11, 리더스시티4BL근린생활시설상가 4동, 104호 | T9: 대전 동구 용운로203, 에코포레아파트 단지상가 108호 | Z9: 대전시 동구 새울로19, 1층 (판암동 734번지 삼정그린코아포레스트아파트2단지 상가1층 (판암성당뒷편)
A10: 아파트 | B10: 연식 | C10: 2018 | D10: 2018 | E10: 2018 | F10: 2018 | G10: 2018 | H10: 2022 | I10: 2022 | J10: 2022 | K10: 2022 | L10: 2022 | M10: 2010 | N10: 2018 | O10: 2024.07 | P10: 2024.07 | Q10: 2024.07 | R10: 2024.12 | S10: 2024.12 | T10: 2020 | U10: 2020 | V10: 2020 | W10: 2020 | X10: 2020 | Y10: 2020 | Z10: 2018 | AA10: 2018 | AB10: 2018 | AC10: 2018 | AD10: 2018 | AE10: 2018 | AF10: 2018
B11: 세대수 | C11: 1345 | D11: 1345 | E11: 1345 | F11: 1345 | G11: 1345 | H11: 1588 | I11: 1588 | J11: 1588 | K11: 1588 | L11: 1588 | M11: 897 | N11: 636 | O11: 1328 | P11: 1328 | Q11: 1328 | R11: 2135 (임대 712^) | S11: 2135 (임대 712^) | T11: 2267 | U11: 2267 | V11: 2267 | W11: 2267 | X11: 2267 | Y11: 2267 | Z11: 1245 | AA11: 1245 | AB11: 1245 | AC11: 1245 | AD11: 1245 | AE11: 320 | AF11: 320
B12: 평형 | C12: 26A | D12: 30B | E12: 30A | F12: 34A | G12: 34B | H12: 30 | I12: 34 | J12: 34 | K12: 30 | L12: 34 | M12: 34A | N12: 34C (4베이) | O12: 24A | P12: 24C | Q12: 33A | R12: 24B | S12: 34A | T12: 25 | U12: 33 | V12: 33 | W12: 33 | X12: 33 | Y12: 25 | Z12: 31 | AA12: 31 | AB12: 29 | AC12: 29 | AD12: 24A(판) | AE12: 24A(판) | AF12: 29
B13: 동호수 | C13: 107-2801 | D13: 112-401 | E13: 110-703 | F13: 102-404 | G13: 104-1401 | H13: 108-23 | I13: 103-12 | J13: 103-19 | K13: 111-고 | L13: 107-25 | M13: 110-중 | N13: 201-고 | O13: 402-205 | P13: 402-1506 | Q13: 409-19 | R13: 507-2405 | S13: 505-중 | T13: 101-2405 | U13: 104-2302 | V13: 105-2801 | W13: 105-2301 | X13: 106-1505 | Z13: 105-1403 | AA13: 105-901 | AB13: 116-702 | AC13: 104-1903 | AD13: 113-2202 | AE13: 201-605 | AF13: 202-905
B14: 구조 | C14: 계단식 | D14: 계단식 | E14: 계단식 | F14: 계단식 | G14: 계단식 | H14: 계단식 | I14: 계단식 | J14: 계단식 | K14: 계단식 | L14: 계단식 | M14: 계단식 | N14: 계단식 | O14: 계단식 | P14: 계단식 | Q14: 계단식 | R14: 계단식 | S14: 계단식 | T14: 계단식 | U14: 계단식 | V14: 계단식 | W14: 계단식 | X14: 계단식 | Y14: 계단식 | Z14: 계단식 | AA14: 계단식 | AB14: 계단식 | AC14: 계단식 | AD14: 계단식 | AE14: 계단식 | AF14: 계단식
B15: 타입 | C15: 방3화2 | D15: 방3화2 | E15: 방3화2 | F15: 방3화2 | G15: 방3화2 | H15: 방3화2 | I15: 방3화2 | J15: 방3화2 | K15: 방3화2 | L15: 방3화2 | M15: 방3화2 | N15: 방3화2 | O15: 방3화2 | P15: 방3화2 | Q15: 방3화2 | R15: 방3화2 | S15: 방3화2 | T15: 방3화2 | U15: 방3화2 | V15: 방3화2 | W15: 방3화2 | X15: 방3화2 | Y15: 방3화2 | Z15: 방3화2 | AA15: 방3화2 | AB15: 방3화2 | AC15: 방3화2 | AD15: 방3화2 | AE15: 방3화2 | AF15: 방3화2
B16: 방향 | C16: 남동향 | D16: 남동향 | E16: 남동향 | F16: 남동향 | G16: 남서향 | I16: 남동향 | J16: 남동향 | L16: 남서향 | M16: 남향 | N16: 남서향 | O16: 남서향 | P16: 남서향 | Q16: 남서향 | R16: 남서향 | S16: 남동향 | U16: 남동향 | V16: 남동향 | W16: 남동향 | X16: 남서향 | Z16: 남서향 | AA16: 남동향 | AB16: 남동향 | AC16: 남동향 | AD16: 남동향 | AE16: 남향 | AF16: 남향
A17: 상황 | B17: 거주자 | C17: 세입자 | D17: 세입자 | E17: 집주인 | F17: 세입자 | G17: 집주인 | J17: 공실 | K17: 세입자 | Q17: 집주인 | R17: 세입자 | S17: 세입자 | T17: 집주인 | U17: 집주인 | V17: 공실 | W17: 집주인 | X17: 집주인 | Z17: 집주인 | AA17: 집주인 | AB17: 세입자 | AC17: 집주인 | AD17: 세입자 | AE17: 집주인 | AF17: 공실
B18: 이사사유 | Q18: 서구 관저동 이사 (직장,기존거주) | Z18: 딸넷
B19: 만기일 | C19: 27년2월 | D19: 27년3월 | E19: 27년 9월 하순 | F19: 27년7월 | G19: 27년2월 이후 아무때나 | K19: 26.11월 초 | Q19: 26.8월 말 잔금 희망(2년) | R19: 27년1월(갱x) | S19: 27년3월 (갱x) | T19: 27년1월 하순 | U19: 28년8월 협의 입주 | AD19: 27년1월6일 (갱O)
B20: 특이사항 | C20: 전망일조 최상 안쪽라인 따뜻하고 환한집 전세안고, 선호라인, 신혼부부에 인사잘하는애기, 거실화장실깨진타일, 안방 누수또는 곰팡이 | D20: 안정적인 정원뷰, 채광좋고 구조, 전세승계 냄새심한할아버지집 | E20: 앞동으로 전망좋고 채광 굿, 전세승계 형식, 초품아, 더블역세권 엄마 아들 사진 보이고, 거실에서 지하차도랑 2단지 보임. | F20: 급매. 전세안고. 생활권 편리한 동. 관리최상 알파룸까지 방4개 집 상태 깨끗 로얄동, 상가 및 정문 가까운동 중문없. 쌍둥이남아2 중1여아1 단지내친정 계속살기원함 | G20: 선호동 교통 상권 편리 깨끗하고 예쁜집 협의입주 해잘드는 양창구조 말많은남자주인+애기 타일,유리수리예정 중문있 ㄱ자창(거실) | H20: 고층 멋진뷰, 차없는 지상, 초,중학교 인근, 상태최상 전망최상 중문 탄성, 엘베2대라인 햇볕 잘듦. 중문,줄눈,미세방충망, 고층뷰로 컨디션 좋은집 | I20: 정원뷰, 채광좋고 주인거주로 관리잘된 집, 상태최상, 전망최상, 로얄동로얄층 | J20: 시스템에어컨4대, 중문, 도배,줄눈,탄성,식세기,인덕션, 앞조망 사이조망 시원하게 나옴. | K20: 세입자 계속 거주 희망. 11월초입주, 막힘없는 뷰, 에어컨 4대, 앞이 가려지지 않아서 전망과 채광이좋음, | L20: 시스템4대.줄눈 탄성 엔지니어스톤 밝고 환한집, 시원한 천변뷰, 7월말 협의, 선호동, 남서향 조문산 뷰 좋은 집, 로얄동 로얄층 | M20: 남향, A형구조, 욕실1칸 수리, 대동지하철, 초역세권 전세1개 3.5억 | N20: 확트인 전망. 햇빛풍부. 시스템에어컨 4대. 중문. 미세방충망. LED | O20: 층간소음 걱정없는 59 A타입의 귀한 피로티, 시스템에어컨전실,환풍기등 에어컨4대,중문 | P20: 풀옵션 전망좋고 예쁘고 깔끔 | Q20: 34평 2월 전세가 4억 찍음(최고가) 34평 전세대기자는 없고 보수적으로 3.5억이면 나감. 3.8억 전세 1개 있는 것 안나가고 있음. 409동 로얄동(트인뷰) 로얄층, 시에4대,주방수납강화, 옵션다수,깔끔관리, 가격 네고는 x 잔금: 26.8월 말 이후 (2년) | R20: 24평 전세 2.8억 가능 24평 전세가 훨씬 수요가 많고 잘나감. 시에4대, 중문, 식장산뷰, 햇살잘듦 신혼부부 추천. | S20: 24평 전세 3.5억 가능 전세대기자는 없음. 505동 막힌뷰. 전세 가장 늦게 나감. 세입자 출산한지 얼마 안됨. 잘 안보여줘서 매매가 낮음. | T20: 전세가 2.5억 가능 | U20: 시스템에어컨 4대, 중문, 방4개구조 (선호) 인기동, 로얄층, | V20: 거실확장형, 알파룸 유리, 에어컨 3대, 중문, 인덕션하이브리드, | W20: 거실 사이뷰, 내부상태 깨끗, 상가 이용편리한동 가격조율 빠른입주가능 | X20: 로얄동,로얄층,선호구조, 팬트리구조,맨앞동,뻥뷰, 최고의 조망권, 시에2대,중문,인덕션 | Z20: 전세대기자 있음. 전세가 보수적 3.2 (이상가능) *사장님 추천매물 50대 가족 거주 31평은 희소성 있음. 매매가 잘 안떨어짐. 확트인뷰,조망권최상, 앞동,선호동,관리굿 중문,보일러교체,탄성. | AA20: 40대 애기엄마 가족. 탁 트인 뷰(식장산뻥뷰), 중문 설치, 주인 거주로 컨디션 굿. 앞동,선호동,안정감(9층) 중문,보일러교체 고양이집 | AB20: 안정감있고,아주깨끗한 집. 중심동, 절충가능(3.7억까지) 고사리 | AC20: 29평 샘플로 보여주심. | AD20: 24평 로얄동, 로얄층. 부동산에 올리지도 않은 장부매물. 24평은 무조건 A타입 선호 (매도나음) 지금 좋은 물건이 요거하나 나머지는 매도 힘드니 31평 추천! 24평 전세가 2.8억 가능. 이건 낮게 껴있음. 세입자: 어르신 2분. 세입자 관리 잘함 | AE20: 매매,전세 1단지 우선. 24평 이 물건은 진짜 좋음. 공원보이는 트인 뷰. 정남향. 판암IC 바로 빠지고 어르신 실거주로 제격인 물건. 전세가 31 2.6(보수)~2.7억. 1단지랑 매매가 4천 차이 (상승에선 2천) 전세가 현재 2천 차이로 보심. 여기를3억정도에사면좋다 | AF20: 앞동,남향집, 전망최상, 상태 굿, 공실.
A21: 가격 | B21: 매매가 | C21: 37000 | D21: 47000 | E21: 45000 | F21: 49500 | G21: 55000 | H21: 50000 | I21: 57000 | J21: 58000 | K21: 50500 | L21: 59000 | M21: 43000 | N21: 43000 | O21: 37500 | P21: 38000 | Q21: 55000 | R21: 39000 | S21: 50000 | T21: 31000 | U21: 44000 | V21: 44500 | W21: 45500 | X21: 46000 | Z21: 42000 | AA21: 42000 | AB21: 37700 | AC21: 40000 | AD21: 34000 | AE21: 32000 | AF21: 36000
B22: 협의매매가 | C22: 37000 | D22: 45000 | E22: 45000 | F22: 49500 | G22: 52000 | H22: 50000 | I22: 57000 | J22: 58000 | K22: 50500 | L22: 59000 | M22: 43000 | N22: 43000 | O22: 37000 | P22: 37500 | Q22: 55000 | R22: 39000 | S22: 50000 | T22: 31000 | U22: 43000 | V22: 44000 | W22: 45000 | X22: 45000 | Z22: 41000 | AA22: 41000 | AB22: 37000 | AC22: 39000 | AD22: 33000 | AE22: 30000 | AF22: 34000
B23: 전세가 | C23: 24000 | D23: 29000 | E23: 33000 | F23: 30000 | G23: 38000 | H23: 33000 | I23: 35000 | J23: 35000 | L23: 35000 | M23: 33000 | N23: 31000 | O23: 28000 | P23: 28000 | Q23: 35000 | R23: 28000 | S23: 27000 | T23: 22000 | U23: 30000 | V23: 30000 | W23: 30000 | X23: 30000 | Z23: 32000-3.3 | AA23: 32000 | AB23: 26000 | AC23: 32000 | AD23: 24000 | AE23: 22000
B24: 매전차이 | C24: =C22-C23 -> 13000 | D24: =D22-D23 -> 16000 | E24: =E22-E23 -> 12000 | F24: =F22-F23 -> 19500 | G24: =G22-G23 -> 14000 | H24: =H22-H23 -> 17000 | I24: =I22-I23 -> 22000 | J24: =J22-J23 -> 23000 | ... X24: =X22-X23 -> 15000 | Z24: =Z22-Z23 -> #VALUE! | AA24: =AA22-AA23 -> 9000 | AB24: =AB22-AB23 -> 11000 | AC24: =AC22-AC23 -> 7000 | AD24: =AD22-AD23 -> 9000 | AE24: =AE22-AE23 -> 8000 | AF24: =AF22-AF23 -> 34000 | AG24: ='동구 은어송삼성성남가양'!R22-'동구 은어송삼성성남가양'!R23 -> 6000 | AH24: ='동구 은어송삼성성남가양'!S22-'동구 은어송삼성성남가양'!S23 -> 0 | AI24: ='동구 은어송삼성성남가양'!T22-'동구 은어송삼성성남가양'!T23 -> 0 | AJ24: ='동구 은어송삼성성남가양'!U22-'동구 은어송삼성성남가양'!U23 -> 0 | AK24: ='동구 은어송삼성성남가양'!V22-'동구 은어송삼성성남가양'!V23 -> 0 | AL24: ='동구 은어송삼성성남가양'!W22-'동구 은어송삼성성남가양'!W23 -> -26000 | AM24: ='동구 은어송삼성성남가양'!X22-'동구 은어송삼성성남가양'!X23 -> 36000 | AN24: ='동구 은어송삼성성남가양'!Y22-'동구 은어송삼성성남가양'!Y23 -> 0 | AO24: =AO22-AO23 -> 0 | AP24: =AP22-AP23 -> 0 | AQ24: =AQ22-AQ23 -> 0 | AR24: =AR22-AR23 -> 0 | AS24: =AS22-AS23 -> 0 | AT24: =AT22-AT23 -> 0 | AU24: =AU22-AU23 -> 0 | AV24: =AV22-AV23 -> 0 | ... CZ24: =CZ22-CZ23 -> 0
B25: 전세가율 | C25: =C23/C21 -> 0.64864865 | D25: =D23/D21 -> 0.61702128 | E25: =E23/E21 -> 0.73333333 | F25: =F23/F21 -> 0.60606061 | G25: =G23/G21 -> 0.69090909 | H25: =H23/H21 -> 0.66 | I25: =I23/I21 -> 0.61403509 | J25: =J23/J21 -> 0.60344828 | ... X25: =X23/X21 -> 0.65217391 | Z25: =Z23/Z21 -> #VALUE! | AA25: =AA23/AA21 -> 0.76190476 | AB25: =AB23/AB21 -> 0.68965517 | AC25: =AC23/AC21 -> 0.8 | AD25: =AD23/AD21 -> 0.70588235 | AE25: =AE23/AE21 -> 0.6875 | AF25: =AF23/AF21 -> 0 | AG25: ='동구 은어송삼성성남가양'!R23/'동구 은어송삼성성남가양'!R21 -> 0.81818182 | AH25: ='동구 은어송삼성성남가양'!S23/'동구 은어송삼성성남가양'!S21 -> #DIV/0! | AI25: ='동구 은어송삼성성남가양'!T23/'동구 은어송삼성성남가양'!T21 -> #DIV/0! | AJ25: ='동구 은어송삼성성남가양'!U23/'동구 은어송삼성성남가양'!U21 -> 0 | AK25: ='동구 은어송삼성성남가양'!V23/'동구 은어송삼성성남가양'!V21 -> 0 | AL25: ='동구 은어송삼성성남가양'!W23/'동구 은어송삼성성남가양'!W21 -> 0.72222222 | AM25: ='동구 은어송삼성성남가양'!X23/'동구 은어송삼성성남가양'!X21 -> 0 | AN25: ='동구 은어송삼성성남가양'!Y23/'동구 은어송삼성성남가양'!Y21 -> 0 | AO25: =AO23/AO21 -> #DIV/0! | AP25: =AP23/AP21 -> #DIV/0! | AQ25: =AQ23/AQ21 -> #DIV/0! | AR25: =AR23/AR21 -> #DIV/0! | AS25: =AS23/AS21 -> #DIV/0! | AT25: =AT23/AT21 -> #DIV/0!
B26: 부동산 복비(0.4%) | C26: =C22*0.004 -> 148 | D26: =D22*0.004 -> 180 | E26: =E22*0.004 -> 180 | F26: =F22*0.004 -> 198 | G26: =G22*0.004 -> 208 | H26: =H22*0.004 -> 200 | I26: =I22*0.004 -> 228 | J26: =J22*0.004 -> 232 | ... X26: =X22*0.004 -> 180 | Z26: =Z22*0.004 -> 164 | AA26: =AA22*0.004 -> 164 | AB26: =AB22*0.004 -> 148 | AC26: =AC22*0.004 -> 156 | AD26: =AD22*0.004 -> 132 | AE26: =AE22*0.004 -> 120 | AF26: =AF22*0.004 -> 136 | AG26: ='동구 은어송삼성성남가양'!R22*0.004 -> 132 | AH26: ='동구 은어송삼성성남가양'!S22*0.004 -> 0 | AI26: ='동구 은어송삼성성남가양'!T22*0.004 -> 0 | AJ26: ='동구 은어송삼성성남가양'!U22*0.004 -> 0 | AK26: ='동구 은어송삼성성남가양'!V22*0.004 -> 0 | AL26: ='동구 은어송삼성성남가양'!W22*0.004 -> 0 | AM26: ='동구 은어송삼성성남가양'!X22*0.004 -> 144 | AN26: ='동구 은어송삼성성남가양'!Y22*0.004 -> 0 | AO26: =AO22*0.004 -> 0 | AP26: =AP22*0.004 -> 0 | AQ26: =AQ22*0.004 -> 0 | AR26: =AR22*0.004 -> 0 | AS26: =AS22*0.004 -> 0 | AT26: =AT22*0.004 -> 0 | AU26: =AU22*0.004 -> 0 | AV26: =AV22*0.004 -> 0 | ... CZ26: =CZ22*0.004 -> 0
B27: 법무 등기비(20) | C27: 20 | D27: 20 | E27: 20 | F27: 20 | G27: 20 | H27: 20 | I27: 20 | J27: 20 | K27: 20 | L27: 20 | M27: 20 | N27: 20 | O27: 20 | P27: 20 | Q27: 20 | R27: 20 | S27: 20 | T27: 20 | U27: 20 | V27: 20 | W27: 20 | X27: 20 | Z27: 20 | AA27: 20 | AB27: 20 | AC27: 20 | AD27: 20 | AE27: 20 | AF27: 20 | AG27: 20 | AH27: 20 | AI27: 20 | AJ27: 20 | AK27: 20 | AL27: 20 | AM27: 20 | AN27: 20 | AO27: 20 | AP27: 20 | AQ27: 20 | AR27: 20 | AS27: 20 | AT27: 20 | AU27: 20 | AV27: 20 | AW27: 20 | AX27: 20 | AY27: 20 | AZ27: 20 | BA27: 20 | BB27: 20 | BC27: 20 | BD27: 20 | BE27: 20 | BF27: 20 | BG27: 20 | BH27: 20 | BI27: 20 | BJ27: 20 | BK27: 20 | BL27: 20 | BM27: 20 | BN27: 20 | BO27: 20 | BP27: 20 | BQ27: 20 | BR27: 20 | BS27: 20 | BT27: 20 | BU27: 20 | BV27: 20 | BW27: 20 | BX27: 20 | BY27: 20 | BZ27: 20 | CA27: 20 | CB27: 20 | CC27: 20 | CD27: 20 | CE27: 20 | CF27: 20 | CG27: 20 | CH27: 20 | CI27: 20 | CJ27: 20 | CK27: 20 | CL27: 20 | CM27: 20 | CN27: 20 | CO27: 20 | CP27: 20 | CQ27: 20 | CR27: 20 | CS27: 20 | CT27: 20 | CU27: 20 | CV27: 20 | CW27: 20 | CX27: 20 | CY27: 20 | CZ27: 20
B28: 취득세(1.1%) | C28: =C22*0.011 -> 407 | D28: =D22*0.011 -> 495 | E28: =E22*0.011 -> 495 | F28: =F22*0.011 -> 544.5 | G28: =G22*0.011 -> 572 | H28: =H22*0.011 -> 550 | I28: =I22*0.011 -> 627 | J28: =J22*0.011 -> 638 | ... X28: =X22*0.011 -> 495 | Z28: =Z22*0.011 -> 451 | AA28: =AA22*0.011 -> 451 | AB28: =AB22*0.011 -> 407 | AC28: =AC22*0.011 -> 429 | AD28: =AD22*0.011 -> 363 | AE28: =AE22*0.011 -> 330 | AF28: =AF22*0.011 -> 374 | AG28: ='동구 은어송삼성성남가양'!R22*0.011 -> 363 | AH28: ='동구 은어송삼성성남가양'!S22*0.011 -> 0 | AI28: ='동구 은어송삼성성남가양'!T22*0.011 -> 0 | AJ28: ='동구 은어송삼성성남가양'!U22*0.011 -> 0 | AK28: ='동구 은어송삼성성남가양'!V22*0.011 -> 0 | AL28: ='동구 은어송삼성성남가양'!W22*0.011 -> 0 | AM28: ='동구 은어송삼성성남가양'!X22*0.011 -> 396 | AN28: ='동구 은어송삼성성남가양'!Y22*0.011 -> 0 | AO28: =AO22*0.011 -> 0 | AP28: =AP22*0.011 -> 0 | AQ28: =AQ22*0.011 -> 0 | AR28: =AR22*0.011 -> 0 | AS28: =AS22*0.011 -> 0 | AT28: =AT22*0.011 -> 0 | AU28: =AU22*0.011 -> 0 | AV28: =AV22*0.011 -> 0 | ... CZ28: =CZ22*0.011 -> 0
B29: 예상 수리비 | C29: =C43 -> 0 | D29: =D43 -> 0 | E29: =E43 -> 0 | F29: =F43 -> 0 | G29: =G43 -> 0 | H29: =H43 -> 0 | I29: =I43 -> 0 | J29: =J43 -> 0 | ... X29: =X43 -> 0 | Z29: =Z43 -> 0 | AA29: =AA43 -> 0 | AB29: =AB43 -> 0 | AC29: =AC43 -> 0 | AD29: =AD43 -> 0 | AE29: =AE43 -> 0 | AF29: =AF43 -> 0 | AG29: =AG43 -> 0 | ... CZ29: =CZ43 -> 0
B30: 실 투자금 | C30: =sum(C24,C26,C27,C28,C29) -> 13575 | D30: =sum(D24,D26,D27,D28,D29) -> 16695 | E30: =sum(E24,E26,E27,E28,E29) -> 12695 | F30: =sum(F24,F26,F27,F28,F29) -> 20262.5 | G30: =sum(G24,G26,G27,G28,G29) -> 14800 | H30: =sum(H24,H26,H27,H28,H29) -> 17770 | I30: =sum(I24,I26,I27,I28,I29) -> 22875 | J30: =sum(J24,J26,J27,J28,J29) -> 23890 | ... X30: =sum(X24,X26,X27,X28,X29) -> 15695 | Z30: =sum(Z24,Z26,Z27,Z28,Z29) -> #VALUE! | AA30: =sum(AA24,AA26,AA27,AA28,AA29) -> 9635 | AB30: =sum(AB24,AB26,AB27,AB28,AB29) -> 11575 | AC30: =sum(AC24,AC26,AC27,AC28,AC29) -> 7605 | AD30: =sum(AD24,AD26,AD27,AD28,AD29) -> 9515 | AE30: =sum(AE24,AE26,AE27,AE28,AE29) -> 8470 | AF30: =sum(AF24,AF26,AF27,AF28,AF29) -> 34530 | AG30: =sum(AG24,AG26,AG27,AG28,AG29) -> 6515 | ... CZ30: =sum(CZ24,CZ26,CZ27,CZ28,CZ29) -> 20
B31: 200% 수익 매도가 | C31: =C22+C30*2 -> 64150 | D31: =D22+D30*2 -> 78390 | E31: =E22+E30*2 -> 70390 | F31: =F22+F30*2 -> 90025 | G31: =G22+G30*2 -> 81600 | H31: =H22+H30*2 -> 85540 | I31: =I22+I30*2 -> 102750 | J31: =J22+J30*2 -> 105780 | ... X31: =X22+X30*2 -> 76390 | Z31: =Z22+Z30*2 -> #VALUE! | AA31: =AA22+AA30*2 -> 60270 | AB31: =AB22+AB30*2 -> 60150 | AC31: =AC22+AC30*2 -> 54210 | AD31: =AD22+AD30*2 -> 52030 | AE31: =AE22+AE30*2 -> 46940 | AF31: =AF22+AF30*2 -> 103060 | AG31: ='동구 은어송삼성성남가양'!R22+AG30*2 -> 46030 | AH31: ='동구 은어송삼성성남가양'!S22+AH30*2 -> 40 | AI31: ='동구 은어송삼성성남가양'!T22+AI30*2 -> 40 | AJ31: ='동구 은어송삼성성남가양'!U22+AJ30*2 -> #REF! | AK31: ='동구 은어송삼성성남가양'!V22+AK30*2 -> 40 | AL31: ='동구 은어송삼성성남가양'!W22+AL30*2 -> -51960 | AM31: ='동구 은어송삼성성남가양'!X22+AM30*2 -> 109120 | AN31: ='동구 은어송삼성성남가양'!Y22+AN30*2 -> 40 | AO31: =AO22+AO30*2 -> 40 | AP31: =AP22+AP30*2 -> 40 | AQ31: =AQ22+AQ30*2 -> 40 | AR31: =AR22+AR30*2 -> 40 | AS31: =AS22+AS30*2 -> 40 | AT31: =AT22+AT30*2 -> 40 | AU31: =AU22+AU30*2 -> 40 | AV31: =AV22+AV30*2 -> 40 | ... CZ31: =CZ22+CZ30*2 -> 40
B32: 특이사항
A33: 수리 | B33: 욕실
B34: UBR욕실
B35: 싱크대
B36: 신발장
B37: 도배,장판
B38: 샷시
B39: 베란다수납장
B40: 조명
B41: 타일
...

Sheet 수리비
B2: 수리 필요 위치 | C2: 수리 예상 가격
C3: 20평대 | D3: 30평대
B4: 욕실 | C4: 300 | D4: 450
B5: UBR욕실 | C5: 450 | D5: 500 | E5: 부분철거불가해서 더비쌈
B6: 싱크대 | C6: 200 | D6: 250
B7: 신발장 | C7: 50 | D7: 50
B8: 도배,장판 | C8: 150 | D8: 200
B9: 샷시 | C9: 650 | D9: 750
B10: 베란다수납장 | C10: 30 | D10: 30
B11: 조명 | C11: 100 | D11: 120
B12: 타일 | C12: 100 | D12: 120

Sheet 매임 스케줄
B3: 매물 임장 스케줄 (데이&그늘)
B4: 순서 | C4: 시간 | D4: 단지 | E4: 부동산 | F4: 전화번호 | G4: 주소 | H4: 예약유무 | I4: 매물정보 (동/호수/타입/방향/특징) | J4: 매매가 | K4: 전세가 | L4: 투자금
B5: 1 | C5: 9:30~10:30 | D5: 이스트시티1단지 | E5: 이스트사랑공인 | I5: 107-고 / | L5: =sum(J5-K5) -> 0
I6: 112-4 / | L6: =sum(J6-K6) -> 0
I7: 102-404 / | L7: =sum(J7-K7) -> 0
B8: 2 | C8: 11:00~12:00 | D8: 신흥SK뷰 | E8: 이스트박사공인 | F8: 010-6371-5951 | L8: =sum(J8-K8) -> 0
L9: =sum(J9-K9) -> 0
L10: =sum(J10-K10) -> 0
C11: 12:10~12:50 | D11: 간단히 식사 시간
B12: 3 | C12: 0.54166667 | D12: 신흥SK뷰 | E12: 이스트박사공인 | F12: 010-6371-5951 | L12: =sum(J12-K12) -> 0
C13: 0.55208333
B14: 4 | C14: 13:30~14:10 | D14: 새들뫼휴먼시아1단지
D15: 이스트시티2단지
B16: 5 | C16: 14:20~14:40 | D16: 이스트시티1단지 | E16: 이스트사랑공인
B17: 6 | C17: 15:00~16:00 | D17: 리더스시티4 | L17: =sum(J17-K17) -> 0
L18: =sum(J18-K18) -> 0
L19: =sum(J19-K19) -> 0
D20: 리더스시티5 | L20: =sum(J20-K20) -> 0
L21: =sum(J21-K21) -> 0
B22: 7 | C22: 16:30~17:30 | D22: e편한세상에코포레 | L22: =sum(J22-K22) -> 0
L23: =sum(J23-K23) -> 0
L24: =sum(J24-K24) -> 0
L25: =sum(J25-K25) -> 0
L26: =sum(J26-K26) -> 0
B27: 8 | C27: 18:00~19:30 | D27: 판암삼정그린코아1단지 | L27: =sum(J27-K27) -> 0
L28: =sum(J28-K28) -> 0
L29: =sum(J29-K29) -> 0
L30: =sum(J30-K30) -> 0
L31: =sum(J31-K31) -> 0
D32: 판암삼정그린코아2단지 | L32: =sum(J32-K32) -> 0
L33: =sum(J33-K33) -> 0

Sheet 지역의 사본
A1: 날짜 | H1: 실
A3: 아파트명
A4: No. | N4: =COLUMN()-2 -> 12 | O4: =COLUMN()-2 -> 13 | P4: =COLUMN()-2 -> 14 | Q4: =COLUMN()-2 -> 15 | R4: =COLUMN()-2 -> 16 | S4: =COLUMN()-2 -> 17 | T4: =COLUMN()-2 -> 18 | U4: =COLUMN()-2 -> 19 | ... CY4: =COLUMN()-2 -> 101
A5: 중개 | B5: 부동산
B6: 연락처
B7: 주소 및 만남장소
A8: 아파트 | B8: 연식
B9: 세대수
B10: 평형
B11: 동호수
B12: 구조
B13: 타입
B14: 방향
A15: 상황 | B15: 거주자
B16: 이사사유
B17: 만기일
B18: 특이사항
A19: 가격 | B19: 매매가
B20: 협의매매가
B21: 전세가
B22: 매전차이 | C22: =C20-C21 -> 0 | D22: =D20-D21 -> 0 | E22: =E20-E21 -> 0 | F22: =F20-F21 -> 0 | G22: =G20-G21 -> 0 | H22: =H20-H21 -> 0 | I22: =I20-I21 -> 0 | J22: =J20-J21 -> 0 | ... CY22: =CY20-CY21 -> 0
B23: 전세가율 | C23: =C21/C19 -> #DIV/0! | D23: =D21/D19 -> #DIV/0! | E23: =E21/E19 -> #DIV/0! | F23: =F21/F19 -> #DIV/0! | G23: =G21/G19 -> #DIV/0! | H23: =H21/H19 -> #DIV/0! | I23: =I21/I19 -> #DIV/0! | J23: =J21/J19 -> #DIV/0! | ... AS23: =AS21/AS19 -> #DIV/0!
B24: 부동산 복비(0.4%) | C24: =C20*0.004 -> 0 | D24: =D20*0.004 -> 0 | E24: =E20*0.004 -> 0 | F24: =F20*0.004 -> 0 | G24: =G20*0.004 -> 0 | H24: =H20*0.004 -> 0 | I24: =I20*0.004 -> 0 | J24: =J20*0.004 -> 0 | ... CY24: =CY20*0.004 -> 0
B25: 법무 등기비(20) | C25: 20 | D25: 20 | E25: 20 | F25: 20 | G25: 20 | H25: 20 | I25: 20 | J25: 20 | K25: 20 | L25: 20 | M25: 20 | N25: 20 | O25: 20 | P25: 20 | Q25: 20 | R25: 20 | S25: 20 | T25: 20 | U25: 20 | V25: 20 | W25: 20 | X25: 20 | Y25: 20 | Z25: 20 | AA25: 20 | AB25: 20 | AC25: 20 | AD25: 20 | AE25: 20 | AF25: 20 | AG25: 20 | AH25: 20 | AI25: 20 | AJ25: 20 | AK25: 20 | AL25: 20 | AM25: 20 | AN25: 20 | AO25: 20 | AP25: 20 | AQ25: 20 | AR25: 20 | AS25: 20 | AT25: 20 | AU25: 20 | AV25: 20 | AW25: 20 | AX25: 20 | AY25: 20 | AZ25: 20 | BA25: 20 | BB25: 20 | BC25: 20 | BD25: 20 | BE25: 20 | BF25: 20 | BG25: 20 | BH25: 20 | BI25: 20 | BJ25: 20 | BK25: 20 | BL25: 20 | BM25: 20 | BN25: 20 | BO25: 20 | BP25: 20 | BQ25: 20 | BR25: 20 | BS25: 20 | BT25: 20 | BU25: 20 | BV25: 20 | BW25: 20 | BX25: 20 | BY25: 20 | BZ25: 20 | CA25: 20 | CB25: 20 | CC25: 20 | CD25: 20 | CE25: 20 | CF25: 20 | CG25: 20 | CH25: 20 | CI25: 20 | CJ25: 20 | CK25: 20 | CL25: 20 | CM25: 20 | CN25: 20 | CO25: 20 | CP25: 20 | CQ25: 20 | CR25: 20 | CS25: 20 | CT25: 20 | CU25: 20 | CV25: 20 | CW25: 20 | CX25: 20 | CY25: 20
B26: 취득세(1.1%) | C26: =C20*0.011 -> 0 | D26: =D20*0.011 -> 0 | E26: =E20*0.011 -> 0 | F26: =F20*0.011 -> 0 | G26: =G20*0.011 -> 0 | H26: =H20*0.011 -> 0 | I26: =I20*0.011 -> 0 | J26: =J20*0.011 -> 0 | ... CY26: =CY20*0.011 -> 0
B27: 예상 수리비 | C27: =C41 -> 0 | D27: =D41 -> 0 | E27: =E41 -> 0 | F27: =F41 -> 0 | G27: =G41 -> 0 | H27: =H41 -> 0 | I27: =I41 -> 0 | J27: =J41 -> 0 | ... CY27: =CY41 -> 0
B28: 실 투자금 | C28: =sum(C22,C24,C25,C26,C27) -> 20 | D28: =sum(D22,D24,D25,D26,D27) -> 20 | E28: =sum(E22,E24,E25,E26,E27) -> 20 | F28: =sum(F22,F24,F25,F26,F27) -> 20 | G28: =sum(G22,G24,G25,G26,G27) -> 20 | H28: =sum(H22,H24,H25,H26,H27) -> 20 | I28: =sum(I22,I24,I25,I26,I27) -> 20 | J28: =sum(J22,J24,J25,J26,J27) -> 20 | ... CY28: =sum(CY22,CY24,CY25,CY26,CY27) -> 20
B29: 200% 수익 매도가 | C29: =C20+C28*2 -> 40 | D29: =D20+D28*2 -> 40 | E29: =E20+E28*2 -> 40 | F29: =F20+F28*2 -> 40 | G29: =G20+G28*2 -> 40 | H29: =H20+H28*2 -> 40 | I29: =I20+I28*2 -> 40 | J29: =J20+J28*2 -> 40 | ... CY29: =CY20+CY28*2 -> 40
B30: 특이사항
A31: 수리 | B31: 욕실
B32: UBR욕실
B33: 싱크대
B34: 신발장
B35: 도배,장판
B36: 샷시
B37: 베란다수납장
B38: 조명
B39: 타일
B40: 확장여부(-)
B41: 합계 | C41: =IF(C10<30,IF(C31="수리필요",'수리비'!$C$4,"0")+IF(C32="수리필요",'수리비'!$C$5,"0")+IF(C33="수리필요",'수리비'!$C$6,"0")+IF(C34="수리필요",'수리비'!$C$7,"0")+IF(C35="수리필요",'수리비'!$C$8,"0")+IF(C36="수리필요",'수리비'!$C$9,"0")+IF(C37="수리필요",'수리비'!$C$10,"0")+IF(C38="수리필요",'수리비'!$C$11,"0")+IF(C39="수리필요",'수리비'!$C$12,"0"),IF(C10>=30,IF(C31="수리필요",'수리비'!$D$4,"0")+IF(C32="수리필요",'수리비'!$D$5,"0")+IF(C33="수리필요",'수리비'!$D$6,"0")+IF(C34="수리필요",'수리비'!$D$7,"0")+IF(C35="수리필요",'수리비'!$D$8,"0")+IF(C36="수리필요",'수리비'!$D$9,"0")+IF(C37="수리필요",'수리비'!$D$10,"0")+IF(C38="수리필요",'수리비'!$D$11,"0")+IF(C39="수리필요",'수리비'!$D$12,"0"))) -> 0 | D41: =IF(D10<30,IF(D31="수리필요",'수리비'!$C$4,"0")+IF(D32="수리필요",'수리비'!$C$5,"0")+IF(D33="수리필요",'수리비'!$C$6,"0")+IF(D34="수리필요",'수리비'!$C$7,"0")+IF(D35="수리필요",'수리비'!$C$8,"0")+IF(D36="수리필요",'수리비'!$C$9,"0")+IF(D37="수리필요",'수리비'!$C$10,"0")+IF(D38="수리필요",'수리비'!$C$11,"0")+IF(D39="수리필요",'수리비'!$C$12,"0"),IF(D10>=30,IF(D31="수리필요",'수리비'!$D$4,"0")+IF(D32="수리필요",'수리비'!$D$5,"0")+IF(D33="수리필요",'수리비'!$D$6,"0")+IF(D34="수리필요",'수리비'!$D$7,"0")+IF(D35="수리필요",'수리비'!$D$8,"0")+IF(D36="수리필요",'수리비'!$D$9,"0")+IF(D37="수리필요",'수리비'!$D$10,"0")+IF(D38="수리필요",'수리비'!$D$11,"0")+IF(D39="수리필요",'수리비'!$D$12,"0"))) -> 0 | E41: =IF(E10<30,IF(E31="수리필요",'수리비'!$C$4,"0")+IF(E32="수리필요",'수리비'!$C$5,"0")+IF(E33="수리필요",'수리비'!$C$6,"0")+IF(E34="수리필요",'수리비'!$C$7,"0")+IF(E35="수리필요",'수리비'!$C$8,"0")+IF(E36="수리필요",'수리비'!$C$9,"0")+IF(E37="수리필요",'수리비'!$C$10,"0")+IF(E38="수리필요",'수리비'!$C$11,"0")+IF(E39="수리필요",'수리비'!$C$12,"0"),IF(E10>=30,IF(E31="수리필요",'수리비'!$D$4,"0")+IF(E32="수리필요",'수리비'!$D$5,"0")+IF(E33="수리필요",'수리비'!$D$6,"0")+IF(E34="수리필요",'수리비'!$D$7,"0")+IF(E35="수리필요",'수리비'!$D$8,"0")+IF(E36="수리필요",'수리비'!$D$9,"0")+IF(E37="수리필요",'수리비'!$D$10,"0")+IF(E38="수리필요",'수리비'!$D$11,"0")+IF(E39="수리필요",'수리비'!$D$12,"0"))) -> 0 | F41: =IF(F10<30,IF(F31="수리필요",'수리비'!$C$4,"0")+IF(F32="수리필요",'수리비'!$C$5,"0")+IF(F33="수리필요",'수리비'!$C$6,"0")+IF(F34="수리필요",'수리비'!$C$7,"0")+IF(F35="수리필요",'수리비'!$C$8,"0")+IF(F36="수리필요",'수리비'!$C$9,"0")+IF(F37="수리필요",'수리비'!$C$10,"0")+IF(F38="수리필요",'수리비'!$C$11,"0")+IF(F39="수리필요",'수리비'!$C$12,"0"),IF(F10>=30,IF(F31="수리필요",'수리비'!$D$4,"0")+IF(F32="수리필요",'수리비'!$D$5,"0")+IF(F33="수리필요",'수리비'!$D$6,"0")+IF(F34="수리필요",'수리비'!$D$7,"0")+IF(F35="수리필요",'수리비'!$D$8,"0")+IF(F36="수리필요",'수리비'!$D$9,"0")+IF(F37="수리필요",'수리비'!$D$10,"0")+IF(F38="수리필요",'수리비'!$D$11,"0")+IF(F39="수리필요",'수리비'!$D$12,"0"))) -> 0 | G41: =IF(G10<30,IF(G31="수리필요",'수리비'!$C$4,"0")+IF(G32="수리필요",'수리비'!$C$5,"0")+IF(G33="수리필요",'수리비'!$C$6,"0")+IF(G34="수리필요",'수리비'!$C$7,"0")+IF(G35="수리필요",'수리비'!$C$8,"0")+IF(G36="수리필요",'수리비'!$C$9,"0")+IF(G37="수리필요",'수리비'!$C$10,"0")+IF(G38="수리필요",'수리비'!$C$11,"0")+IF(G39="수리필요",'수리비'!$C$12,"0"),IF(G10>=30,IF(G31="수리필요",'수리비'!$D$4,"0")+IF(G32="수리필요",'수리비'!$D$5,"0")+IF(G33="수리필요",'수리비'!$D$6,"0")+IF(G34="수리필요",'수리비'!$D$7,"0")+IF(G35="수리필요",'수리비'!$D$8,"0")+IF(G36="수리필요",'수리비'!$D$9,"0")+IF(G37="수리필요",'수리비'!$D$10,"0")+IF(G38="수리필요",'수리비'!$D$11,"0")+IF(G39="수리필요",'수리비'!$D$12,"0"))) -> 0 | H41: =IF(H10<30,IF(H31="수리필요",'수리비'!$C$4,"0")+IF(H32="수리필요",'수리비'!$C$5,"0")+IF(H33="수리필요",'수리비'!$C$6,"0")+IF(H34="수리필요",'수리비'!$C$7,"0")+IF(H35="수리필요",'수리비'!$C$8,"0")+IF(H36="수리필요",'수리비'!$C$9,"0")+IF(H37="수리필요",'수리비'!$C$10,"0")+IF(H38="수리필요",'수리비'!$C$11,"0")+IF(H39="수리필요",'수리비'!$C$12,"0"),IF(H10>=30,IF(H31="수리필요",'수리비'!$D$4,"0")+IF(H32="수리필요",'수리비'!$D$5,"0")+IF(H33="수리필요",'수리비'!$D$6,"0")+IF(H34="수리필요",'수리비'!$D$7,"0")+IF(H35="수리필요",'수리비'!$D$8,"0")+IF(H36="수리필요",'수리비'!$D$9,"0")+IF(H37="수리필요",'수리비'!$D$10,"0")+IF(H38="수리필요",'수리비'!$D$11,"0")+IF(H39="수리필요",'수리비'!$D$12,"0"))) -> 0 | I41: =IF(I10<30,IF(I31="수리필요",'수리비'!$C$4,"0")+IF(I32="수리필요",'수리비'!$C$5,"0")+IF(I33="수리필요",'수리비'!$C$6,"0")+IF(I34="수리필요",'수리비'!$C$7,"0")+IF(I35="수리필요",'수리비'!$C$8,"0")+IF(I36="수리필요",'수리비'!$C$9,"0")+IF(I37="수리필요",'수리비'!$C$10,"0")+IF(I38="수리필요",'수리비'!$C$11,"0")+IF(I39="수리필요",'수리비'!$C$12,"0"),IF(I10>=30,IF(I31="수리필요",'수리비'!$D$4,"0")+IF(I32="수리필요",'수리비'!$D$5,"0")+IF(I33="수리필요",'수리비'!$D$6,"0")+IF(I34="수리필요",'수리비'!$D$7,"0")+IF(I35="수리필요",'수리비'!$D$8,"0")+IF(I36="수리필요",'수리비'!$D$9,"0")+IF(I37="수리필요",'수리비'!$D$10,"0")+IF(I38="수리필요",'수리비'!$D$11,"0")+IF(I39="수리필요",'수리비'!$D$12,"0"))) -> 0 | J41: =IF(J10<30,IF(J31="수리필요",'수리비'!$C$4,"0")+IF(J32="수리필요",'수리비'!$C$5,"0")+IF(J33="수리필요",'수리비'!$C$6,"0")+IF(J34="수리필요",'수리비'!$C$7,"0")+IF(J35="수리필요",'수리비'!$C$8,"0")+IF(J36="수리필요",'수리비'!$C$9,"0")+IF(J37="수리필요",'수리비'!$C$10,"0")+IF(J38="수리필요",'수리비'!$C$11,"0")+IF(J39="수리필요",'수리비'!$C$12,"0"),IF(J10>=30,IF(J31="수리필요",'수리비'!$D$4,"0")+IF(J32="수리필요",'수리비'!$D$5,"0")+IF(J33="수리필요",'수리비'!$D$6,"0")+IF(J34="수리필요",'수리비'!$D$7,"0")+IF(J35="수리필요",'수리비'!$D$8,"0")+IF(J36="수리필요",'수리비'!$D$9,"0")+IF(J37="수리필요",'수리비'!$D$10,"0")+IF(J38="수리필요",'수리비'!$D$11,"0")+IF(J39="수리필요",'수리비'!$D$12,"0"))) -> 0 | ... CY41: =IF(CY10<30,IF(CY31="수리필요",'수리비'!$C$4,"0")+IF(CY32="수리필요",'수리비'!$C$5,"0")+IF(CY33="수리필요",'수리비'!$C$6,"0")+IF(CY34="수리필요",'수리비'!$C$7,"0")+IF(CY35="수리필요",'수리비'!$C$8,"0")+IF(CY36="수리필요",'수리비'!$C$9,"0")+IF(CY37="수리필요",'수리비'!$C$10,"0")+IF(CY38="수리필요",'수리비'!$C$11,"0")+IF(CY39="수리필요",'수리비'!$C$12,"0"),IF(CY10>=30,IF(CY31="수리필요",'수리비'!$D$4,"0")+IF(CY32="수리필요",'수리비'!$D$5,"0")+IF(CY33="수리필요",'수리비'!$D$6,"0")+IF(CY34="수리필요",'수리비'!$D$7,"0")+IF(CY35="수리필요",'수리비'!$D$8,"0")+IF(CY36="수리필요",'수리비'!$D$9,"0")+IF(CY37="수리필요",'수리비'!$D$10,"0")+IF(CY38="수리필요",'수리비'!$D$11,"0")+IF(CY39="수리필요",'수리비'!$D$12,"0"))) -> 0
...
