Workbook

Sheet 우리 기수 전체 일정
A1: ✿ 지투실전 28기 15조 with 뽀오뇨 튜터님 ✿
A2: 첫 "일요일" 날짜 | B2: 46103 | G2: 실전반 가이드 | H2: 실전반 과제시트
A4: 요일 | B4: 일 (SUN) | C4: 월(MON) | D4: 화(TUE) | E4: 수(WED) | F4: 목(THU) | G4: 금(FRI) | H4: 토(SAT)
A5: 날짜 | B5: =B2 -> 46103 | C5: =B5+1 -> 46104 | D5: =C5+1 -> 46105 | E5: =D5+1 -> 46106 | F5: =E5+1 -> 46107 | G5: =F5+1 -> 46108 | H5: =G5+1 -> 46109
A6: 주요 일정 | F6: 1강 오프라인 강의 | G6: 지투실전 전체 OT
A10: 날짜 | B10: =B5+7 -> 46110 | C10: =B10+1 -> 46111 | D10: =C10+1 -> 46112 | E10: =D10+1 -> 46113 | F10: =E10+1 -> 46114 | G10: =F10+1 -> 46115 | H10: =G10+1 -> 46116
A11: 주요 일정 | C11: 개강 / 1강 온라인 업로드 | D11: 조 OT | F11: 2강 오프라인 강의 | H11: 튜터님과 1on1 (20min)
A12: ♥오늘의 주인공♥ | E12: MZ | F12: 로에 | G12: 가히
A13: 전임 당번 | E13: 야자수그늘, 가히 | F13: MZ, 라니 | G13: 학생,로에
A14: 전임 단지 | E14: 신흥SKVIEW, 이스트시티1 | F14: 리더스시티4BL 힐스테이트가양더와이즈 | G14: 리더스시티5BL 은어송하늘채리버뷰
A15: 날짜 | B15: =B10+7 -> 46117 | C15: =B15+1 -> 46118 | D15: =C15+1 -> 46119 | E15: =D15+1 -> 46120 | F15: =E15+1 -> 46121 | G15: =F15+1 -> 46122 | H15: =G15+1 -> 46123
A16: 주요 일정 | B16: 1강 후기 마감 | C16: 2강 온라인 업로드 | F16: 사임 마감 | H16: 튜터링데이 오전9시~
A17: ♥오늘의 주인공♥ | C17: 야자수그늘 | D17: 라니 | E17: 학생 | F17: 굿데이 | G17: 케빈D
A18: 전임 당번 | C18: 케빈D, 굿데이3,MZ | D18: 아르떼,가히,학생 | E18: 로에,야자수그늘,굿데이3 | F18: 라니,MZ | G18: 굿데이3,학생,아르떼
A19: 전임 단지 | C19: e편한세상대전에코포레 새들뫼휴먼시아1단지 아침LH | D19: 한밭자이 고운하이플러스 대주파크빌 | E19: 가오주공 은어송1단지풍림아이원 은어송5단지우미린 | F19: 은어송3단지아이파크 남월제이오투그란데 | G19: 삼익세라믹 은어송6단지풍림아이원 남대전이편한세상
A20: 날짜 | B20: =B15+7 -> 46124 | C20: =B20+1 -> 46125 | D20: =C20+1 -> 46126 | E20: =D20+1 -> 46127 | F20: =E20+1 -> 46128 | G20: =F20+1 -> 46129 | H20: =G20+1 -> 46130
A21: 주요 일정 | B21: 튜데2일차/ 2강 후기 마감 | F21: 4강 오프라인 강의 | G21: 중임 마감 | H21: 튜터님과 1on1 (20min)
A22: ♥오늘의 주인공♥ | C22: 아르떼 | D22: MZ | E22: 가히 | F22: 로에 | G22: 야자수그늘
A23: 전임 당번 | C23: 가히,케빈D,로에 | D23: 야자수그늘,아르떼, 라니 | E23: MZ,로에 | F23: 학생,라니,야자수그늘 | G23: 케빈D,굿데이3
A24: 전임 단지 | C24: 석촌주공, 은어송하늘채2단지 주공삼성타운 | D24: 스마트뷰 효촌마을 신흥마을/어진마을 | E24: 이스트2단지 삼정하이츠타운 | F24: 용방마을 용운주공2단지 한화꿈에그린 | G24: 신동아 한숲
A25: 날짜 | B25: =B20+7 -> 46131 | C25: =B25+1 -> 46132 | D25: =C25+1 -> 46133 | E25: =D25+1 -> 46134 | F25: =E25+1 -> 46135 | G25: =F25+1 -> 46136 | H25: =G25+1 -> 46137
A26: 주요 일정 | B26: 튜터링데이 후기 마감 | C26: 4강 온라인 업로드 | F26: 5강 오프라인 강의 | G26: 5강 온라인 업로드 | H26: 최임 마감
A27: ♥오늘의 주인공♥ | C27: 라니 | D27: 학생 | E27: 굿데이 | F27: 케빈D | G27: 아르떼
A28: 전임 당번 | C28: 아르떼,가히,케빈D | D28: 로에,야자수그늘 | E28: 라니,MZ | F28: 굿데이3,학생,아르떼 | G28: 가히, 케빈D
A29: 전임 단지 | C29: 인동현대/효동현대 자양동아 청룡 | D29: 삼정그린코아1단지 위드힐 | E29: 삼정그린코아2단지 휴먼시아2단지 | F29: 판암주공1,2차 판암주공5,6차 신동파밀리에1 | G29: 홍도갤러리휴리움 홍도서우
A30: 날짜 | B30: =B25+7 -> 46138 | C30: 27 | D30: 28 | E30: 29 | F30: 30 | G30: 46113 | H30: =G30+1 -> 46114
A31: 주요 일정 | B31: 4강 후기 마감 | C31: 최종모임 저녁7시~ | E31: 최종 과제 마감 | F31: 종강
A32: ♥오늘의 주인공♥ | C32: MZ | D32: 가히 | E32: 로에 | F32: 뽀튜터님(?)
A33: 전임 당번
A34: 전임 단지

Sheet 이번 달 원씽 실적 체크
A2: ★규칙★ | J2: 습관화예시
A3: 1. 체크시트는 매주 일요일까지 셀프 체크, 습관 팀장님(님) 최종 시트 확인 후 주간 실적 카톡방 공유 | J3: * 전화임장 주 3회, 회당 부동산 2곳 이상 ([도전]100일 습관만들기 게시판 포스팅)
A4: 2. 미모하시는 분들은 미모시간에 단톡방에 아침인사 해주세요! | J4: * 독서 매일 50p (지금 독서중 글게시) 및 월 3권 독서후기 작성 (독서후기게시판 포스팅)
A5: 3. 독서하시는 분은 '독서중~♡'게시판에, 필사는 칼럼필사 게시판에, 기타 습관 100일습관만들기 게시판에 | J5: * 경제기사 및 생각 정리 주 3회 ([습관] 경제뉴스읽기 게시판 포스팅)
A6: 4. 인증 완료 후 숫자 "1" 기재 | J6: * 월부칼럼 필사 주 3회([흡수] 책/칼럼 필사 게시판 포스팅)
A8: 4월 습관화 과제 체크 시트
A9: 4월 습관화 과제 | D9: 매일시세 30분 | E9: 매일 시세 및 생각 공유 | F9: 시세스캐닝 | G9: 투자칼럼 필사 (이틀에 한 번) | H9: 시세 | I9: 전화임장 | J9: 시세루틴 | K9: 시세루틴 | L9: 시세
A10: 달성기준(일) | D10: 30 | E10: 19 | F10: 20 | G10: 12 | H10: 20 | I10: 15 | J10: 20 | K10: 20 | L10: 20
A11: 달성 횟수 (자동계산됨) | D11: =COUNT(D14:D44) -> 15 | E11: =COUNT(E14:E44) -> 11 | F11: =COUNT(F14:F44) -> 14 | G11: =COUNT(G14:G44) -> 5 | H11: =COUNT(H14:H44) -> 4 | I11: 12 | J11: =COUNT(J14:J44) -> 4 | K11: =COUNT(K14:K44) -> 5 | L11: =COUNT(L14:L44) -> 7
A12: 목표 달성률 (자동계산됨) | D12: =D11/D10 -> 0.5 | E12: =E11/E10 -> 0.57894737 | F12: =F11/F10 -> 0.7 | G12: =G11/G10 -> 0.41666667 | H12: =H11/H10 -> 0.2 | I12: =I11/I10 -> 0.8 | J12: =J11/J10 -> 0.2 | K12: =K11/K10 -> 0.25 | L12: =L11/L10 -> 0.35
A13: 주 | B13: 날짜 | C13: 요일 | D13: 가히 | E13: 케빈 | F13: 데이 | G13: 로에 | H13: 라니 | I13: 그늘 | J13: MZ | K13: 아르떼 | L13: 학생
A14: W-1 | B14: 46111 | C14: 월 | F14: 1
B15: =B14+1 -> 46112 | C15: 화 | D15: 1
B16: =B15+1 -> 46113 | C16: 수 | D16: 1 | F16: 1 | I16: 2
B17: =B16+1 -> 46114 | C17: 목 | F17: 1 | I17: 1
B18: =B17+1 -> 46115 | C18: 금 | D18: 1 | I18: 1
B19: =B18+1 -> 46116 | C19: 토
B20: =B19+1 -> 46117 | C20: 일
A21: W-2 | B21: =B20+1 -> 46118 | C21: 월 | D21: 1 | E21: 1 | F21: 1 | G21: 1 | H21: 1 | J21: 1
B22: =B21+1 -> 46119 | C22: 화 | E22: 1 | F22: 1 | H22: 김해 | I22: 1 | J22: 1 | K22: 1
B23: =B22+1 -> 46120 | C23: 수 | D23: 1 | E23: 1 | G23: 1 | H23: 1 | I23: 1 | J23: 1 | K23: 1
B24: =B23+1 -> 46121 | C24: 목 | D24: 1 | E24: 1 | F24: 1 | K24: 1
B25: =B24+1 -> 46122 | C25: 금 | D25: 1 | E25: 1 | F25: 1 | H25: 1 | K25: 1
B26: =B25+1 -> 46123 | C26: 토 | D26: 1
B27: =B26+1 -> 46124 | C27: 일 | D27: 1
A28: W-3 | B28: =B27+1 -> 46125 | C28: 월 | D28: 1 | E28: 1 | F28: 1 | G28: 1 | H28: 창원마산
B29: =B28+1 -> 46126 | C29: 화 | D29: 1 | E29: 1 | F29: 1 | H29: 1 | I29: 1 | J29: 1 | K29: 1 | L29: 1
B30: =B29+1 -> 46127 | C30: 수 | D30: 1 | E30: 1 | F30: 1 | G30: 1 | H30: 청주 흥덕서원 | I30: 1 | L30: 1
B31: =B30+1 -> 46128 | C31: 목 | D31: 1 | E31: 1 | F31: 1 | L31: 1
B32: =B31+1 -> 46129 | C32: 금 | E32: 1 | H32: 청주 청원 | L32: 1
B33: =B32+1 -> 46130 | C33: 토 | L33: 1
B34: =B33+1 -> 46131 | C34: 일 | F34: 1 | H34: 부산,대구 | L34: 1
A35: W-4 | B35: =B34+1 -> 46132 | C35: 월 | D35: 1 | E35: 1 | F35: 1 | G35: 1 | L35: 1
B36: =B35+1 -> 46133 | C36: 화 | D36: 1 | F36: 1
B37: =B36+1 -> 46134 | C37: 수
B38: =B37+1 -> 46135 | C38: 목
B39: =B38+1 -> 46136 | C39: 금
B40: =B39+1 -> 46137 | C40: 토
B41: =B40+1 -> 46138 | C41: 일
A42: W-5 | B42: =B41+1 -> 46139 | C42: 월
...

Sheet Step1-1. 서로를 알아보아요
A1: 서로에 대해 알아보아요!
B2: 닉네임 | D2: 가히dasikeum | E2: 라니 | F2: 야자수그늘 | G2: 케빈D | H2: 굿데이3 | I2: 아르떼 | J2: MZ | K2: 학생 | L2: 로에
A3: *개인정보는 종강 이후 삭제합니다 | B3: 연락처 | D3: 010-2411-8866 | E3: 010-3554-3966 | F3: 010-4006-0709 | G3: 010-2736-9430 | H3: 010-9876-8701 | I3: 010-9525-3753 | J3: 010-4214-7789 | K3: 010-7191-9684 | L3: 010-5047-7286
B4: 역할 | D4: 조장 | E4: 원씽팀장 | F4: 전임팀장 | G4: 부조장님/과제팀장 | H4: 부조장님/임장팀장 | I4: 감일팀장 | J4: 공유팀장 | K4: 사진/인증팀장 | L4: 총무팀장
A5: *구까지 기재 | B5: 거주지 | D5: 강남구 | E5: 동작구 | F5: 경남거제시 | G5: 동대문구 | H5: 양천구 | I5: 관악구 | J5: 성북구 | K5: 성동구 | L5: 경기도 시흥시
B6: 교통편 (이용 기차역) | D6: 수서역/서울역 | E6: 서울역 | F6: 부산역 | G6: 수서역/서울역 | H6: 서울역 | I6: 수서/서울역 | J6: 서울역 | K6: 용산역 | L6: 광명역
A7: *근무패턴, 개인상황, 보틀넥, 연락가능시간 등 | B7: 특이사항 (연령대 . 근무시간 . 연락가능시간 . 기타 개인상황이나 보틀넥) | D7: 제 2026년 4월은 15조의 것입니다 ♡♡♡ | E7: 4월 업무 이슈 (조장님 개인카톡 드릴게용) | F7: 특이사항없습니다 | G7: 4/12 (일) 가족 일정 4/25 (토) 출근 가능성 | J7: 4/18(토) 가족 결혼식으로 불참 + 4/25일(토) 회사체육대회로 불참 | K7: 특이사항없습니다 | L7: 4월 4일을 제외한 주말은 스케줄 이상 없습니다.
B8: 투자가능여부 | D8: X | E8: X (3월 잔금) | F8: X | G8: X | H8: X | I8: X | J8: X | K8: X | L8: X
B9: 강의수강현황 (금번 제외) | C9: 기초강의 | D9: O | E9: O | F9: O | G9: O | H9: O | I9: O | J9: O | K9: O | L9: O
C10: 실전 | D10: O | E10: O | F10: O | G10: O | H10: O | I10: O | J10: X | K10: O | L10: O
C11: 지투 | D11: O | E11: O | F11: O | G11: O | H11: O | J11: X | K11: O | L11: X
C12: 학교 | D12: X | E12: X | F12: X | G12: O | H12: O | I12: X | J12: X | K12: X | L12: X
C13: 실전투자목표 | D13: 1호기 잔금 (4월 12일) | E13: 지투반 임보 50장 틀 만들기 | F13: 선명한앞마당 | G13: 2호기 방향성 설정 | H13: 3호기 잔금 (4/23) | I13: 2호기찾기 | J13: 2호기 찾기 | K13: 2호기 지방투자 꼭 해보고 싶습니다 | L13: 1호기 계약 (4월 4일)
A14: *꼭 이루고 싶은 딱 한가지만 적어주세요 | B14: 목표 | C14: 실전반 원씽 | D14: 15조 다함께 실전 스케줄 완주하기 | E14: 1호기 매도 플랜 세우기 | F14: 선명한앞마당 | G14: 끈끈한 투자메이트 만들기 | H14: 뾰족한 앞마당 만들기 | J14: 선명한 앞마당 | K14: 대전 동구 앞마당 만들기 | L14: 선명한 앞마당 만들기
A15: *많다고 좋은건 아닙니다 | C15: 루틴 (정량화) | D15: 매일 시세 (닷컴 인증) +전수조사 템플릿 완성 | E15: 중소도시 앞마당 챙기기 (너무 내버려뒀어요) | F15: 시세트레킹 | G15: 매일 시세 | H15: 시세 | I15: 시세 | J15: 시세 | K15: 임보 매일 1장 | L15: 출퇴근길 50p 이상 독서 루틴
C16: 임보 (페이지) | D16: 핵심만 추린 30 | E16: 50 | F16: 30 | G16: 50 | H16: 50 | I16: 30 | J16: 30 | K16: 30 | L16: 30
A17: *10시간 이상 2회 | C17: 임장 (회수) | D17: 14 | E17: 10 | F17: 10 | G17: 10 | H17: 10 | I17: 10 | J17: 8 | K17: 10 | L17: 12
C18: 전화임장 (회수) | D18: 40 | E18: 40 | F18: 1일1전임 | G18: 30 | H18: 50 | I18: 20 | J18: 30 | K18: 10 | L18: 30
C19: 매물 (개수) | D19: 40 | E19: 40 | F19: 30 | G19: 30 | H19: 40 | I19: 30 | J19: 20 | K19: 10 | L19: 25
C20: 부동산 (개수) | D20: 15 | E20: 10 | F20: 7 | G20: 10 | H20: 12 | I20: 10 | J20: 10 | K20: 10 | L20: 10
C21: 나눔글 (개수) | D21: 2 | E21: 1 | F21: 0 | G21: 3 | H21: 1 | J21: 1 | K21: 0 | L21: 0
A22: *앞마당 확인 *임장보고서 완성 기준으로 기재 | B22: 수도권 | D22: [서울] 성동, 구로 (반의반의 반의반마당) [수도권] 수원 권선 | E22: 서울 : 구로,송파,동대문,성북 경기 : 고양시 덕양구, 부천 (평촌,광명) 인천 : 부평구 | F22: 강서구 성동구 수지구 동안구 | G22: 서울 관악구, 도봉구 성남 수정구, 중원구, 안양 동안구, 구리, 군포, 수원 영통구, 남양주 | H22: [서울] 강남구, 서초구, 양천구, 동작구, 영등포구, 강서구, 동대문구, 서대문구, 성북구, 관악구, 은평구, 구로구 [경기도] 용인시 수지구, 안양 동안구, 일산 서구, 동구 , 구리시, 수원 영통구, 군포시 | I22: [서울] 서대문구, 강동구, 동작구 [경기도] 수지구, 권선구 | J22: 구리, 성북구 | K22: 구리시, 군포시, 덕양구, 수지구, 강동구, 노원구, 동대문구, 서대문구, 성동구, 성북구, 영등포구, 구성남, 부평구 | L22: 서대문구/ 부천원미구/ 군포
B23: 지방 | D23: 부산 (동래, 연제, 진) 울산 (남) 창원 (성산, 의창, 마산회원, 합포), 김해 | E23: 대구 :수중북동 부산 :연제동래 광주 :남 대전: 중 울산: 남중북 중소도시: 청주,창원마산,김해,천안서북 | F23: 부산남구 수영구 천안동남구, 창원 성산구 의창구 | G23: 부산 연제구 / 대구 중구, 북구, 동구, 남구 / 광주 남구 / 울산 남구, 중구, 북구, 동구 천안 서북구, 동남구 / 전주 덕진구 / 포항 남구 | H23: [광역시] 부산 해운대구, 동래구, 진구 / 대구 수성구, 중구 / 대전 서구, 유성구 / 울산 남구, 중구, 북구, 동구 / 광주 북구 [중소도시] 창원 성산구, 의창구,마산회원구,합포구 / 천안시 서북구/ 청주시 흥덕구, 서원구, 청원구, 상당구 / 김해시 / 구미시 | I23: 부산 동래구/연제구/진구 울산 남구/중구/동구/북구 광주 남구 [중소] 성산구 / 의창구/ 마산회원 / 합포구 흥덕구 | J23: 부산 해운대구, 진구, 연제구, 울산 남구, 중구, 북구, 동구 | K23: 광주 서구, 대구 북구, 울산 남구, 울산 북구, 전주 완산구 | L23: 울산 북구/동구/ 창원 성산구/마산합포/마산회원/ 천안 서북구
B25: 가히dasikeum | C25: 조장 | D25: 튜터와 소통하여 조의 전체사항 조율/진행 공지사항 및 스케쥴 안내, 과제취합 및 운영 전반
B26: 굿데이3 | C26: 부조장 (임장) | D26: 임장 스케줄/루트 취합, 최종루트 배포, 임장 리딩, 매임 조 편성
B27: 케빈D | C27: 부조장 (과제) | D27: 과제 및 과제수행 독려, 주요 데드라인 체크 (매주 월요일 일정 체크하여 안내)
B28: 라니 | C28: 원씽 팀장 | D28: 매일 원씽 독려하며 조원들 원씽 챙기기 (오전 6-8시)
B29: 아르떼 | C29: 감일 팀장 | D29: 감사일기 매일(주중 오전) 취합
B30: 학생 | C30: 사진 팀장 | D30: 온오프라인 모임 시 인증 사진 & 제목, 주중 올뺌 관리,
B31: 야자수그늘 | C31: 전임 팀장 | D31: 전화임장 리딩(전임 두려운 분 적극 권장), 매일 전임 담당 안내 및 독려
B32: MZ | C32: 공유 팀장 | D32: 부동산 기사/임장지 지역 정보 등 기사 공유, 조원 나눔글/수강후기/발도장 공유(수시)
B33: 로에 | C33: 총무 팀장 | D33: 임장 및 튜터링데이 스카, 식당, 숙박, 각종 모임장소 예약 및 총무역할

Sheet Step1-2. 질문있어요!
B1: 질문으로 성장한다 | E1: *질문을 위한 질문은 No! *질문은 읽는 사람을 배려하여 핵심을 간결하게!
B2: 순번 | C2: 질문자 | D2: 질문 | E2: 질문에 대한 내 생각 | F2: 질문에 대한 조원들 생각 | G2: 튜터님 말씀
B3: 1 | C3: 학생 | D3: 대전 동구 분임과 단임을 하면서 기존에 앞마당이었던 대구 북구의 느낌이 들었습니다. 대전 안에서도 중심이 아니기에, 위치 역시 중심일수록 좋고, 학군보다는 연식과 그 주변 환경이 중요하다는 것을 알았습니다. 예전에 대구 북구 임장시 택시에서 들었던 임장지에 대한 기사님의 평가와 대구 북구와 대전 동구와 굉장히 비슷하다고 느꼈습니다. 궁금한 것은 만약 대구 북구안에서의 중심부의 단지와 대전 동구 안에서의 중심부의 한 단지를 비교할 때 같은 연식과 같은 평형이라 가정했을 때, 우선순위 혹은 선호도를 가르기 위해서는 매임을 양쪽으로 넘나들어야 되는 것이겠죠? 혹시 다른 방법이 있다면 어떤 것이 있을까요? 다른 지역에 있는 단지들끼리 아무리 중요한 핵심 포인트가 같다 하더라도, 대구 북구 사람들과 대전 동구 사람들이 다른데, 이 단지가 더 낫겠다의 생각은 어떻게 하는 걸까요?! | E3: 우선 대구 북구와 대전 동구의 단지 비교 단지의 전세가를 확인해보고, 선호도를 나눌 수 있겠다는 생각과 각 물건마다의 상황 파악을 위한 전임을 통해 내가 감당 가능한 물건인지 확인! 그리고 하루는 대구 북구 가서 매물털고, 하루는 대전 동구가서 매물 털기! | F3: 케빈 － 지방 다른 도시끼리 비교할 때는 흔히 도생단(도시, 생활권, 단지)으로 비교를 많이 하는 편입니다. 도시로 비교했을 때는 대구(235만) >대전(144만) / 생활권은 북구 침산은 대구 내에서 어느 정도 위상을 가진 생활권일까, 동구 신흥은 대전 내에서 어느 정도 위상을 가진 생활권일까 / 단지는 그 생활권에서 선호도가 어느 정도 되는 단지일까를 서로 정리한 후 비교를 해보는 편입니다. ex) 대전 동구 신흥sk뷰는 대전 내 중하위생활권의 최선호단지 vs 대구 북구 오페라삼정그린코아는 대구 중위 생활권의 최선호단지 =>> 오페라삼정그린코아가 좀 더 가치가 높다 이런식으로 판단 후 그래프를 붙여보는 편입니다 학생님 좋은 질문 감사합니다 ~~! 가히 - 저도 케빈님 방식대로 봅니다! 지역간 비교를 많이 해본 적은 없지만, 1) 인구수를 기준으로 한 도시 체급 비교, 2) 생활권 순위 (상중하 정도), 3) 생활권 내 선호도 순위 (상중하 정도), 4) 기타 입지요소 비교 ... 그 다음에 아실 그래프로 확인! 그래프마저 비슷하다면 거래량도 같이 볼 것 같고.. (지방이니까) 그래도 정말 비슷하다? 하면 진짜 매임 통해서 매물 vs 매물로 가격 협상, 조건 더 좋은 것으로 투자 고려할 것 같습니다 :) MZ － 체급이 다른 지역을 비교하는 것은 정말 어려운 일이라고 생각해요! 대구 북구의 위상을 대구 안에서 전체적으로 보고 그 후에 단지는 그 지역내 상, 중상, 중중, 중하, 하 중에 어디에 속하는지 선호도를 볼 것 같고요, 그 다음에 대전동구의 하나의 단지는 대전 동구에서의 전체에서 어떤 생활권 위상을 가지고 선호도는 얼마나 되는지 볼 것 같습니다. (케부님의 도,생,단 전법이라고 볼 수 있겠어요) 대전 북구와 대전 동구 두 개의 앞마당만으로는 비교하기가 쉽지 않을 것 같습니다. 대전과 대구에서 최소의 두 개의 구씩 더 돌아보고 판단해볼 것 같습니다. | G3: 지방에서 다른지역간의 비교를 질문주셨네요 우선 대구 북구와 대전 동구의 단지 비교 단지의 전세가를 확인해보고, 선호도를 나눌 수 있겠다는 생각과 각 물건마다의 상황 파악을 위한 전임을 통해 내가 감당 가능한 물건인지 확인! 그리고 하루는 대구 북구 가서 매물털고, 하루는 대전 동구가서 매물 털기! 라고 생각남겨주셨는데 일다 지방에서 지역간 비교하는것 자체가 어려워요 . 그걸 인정하고 시작하셔야합니다 지방은 각각의 사이클이 다르고, 인구 체급이 달라서 그래요 그래서 체급을 먼저 비교하면 대구 > 대전 이죠 (체급 (=인구 수!) 각 말씀주신 단지의 가치가 지역내에서 구내에서 생활권내에서의 가치를 잘 알고있어야해요 사실 엄청어렵잖아요 일단 질문에는 단지의 가치나 특정 투자금도 없어서 제가 방법적으로 먼저 설명드리면 투자후보 단지라면 물건을 매물털러 지역2개다 가지말고 가성비로 전화임장으로 매물털기를 추천드립니다 전화임장으로 모든물건지, 부동산 다 전화드려서 같은물건에대한 정보를 다 쌓으세요. 그러고 상황과 상태, 일잘러 부사님 몇분 핀을 꽂아두고 정말 좋은 물건이 나오면 그때 매물보러 가시고, 간김에 털고오는걸 추천드려요
B4: 2 | C4: 학생 | D4: 이편한세상대전에코포레 뒤편에 스타벅스가 위치되어 있던데, 심지어 외곽이었지만 DT가 아니었습니다. 현재 대전 동구의 DT가 아닌 스벅은 대전터미널점, 가오동 생활권, 그리고 에코포레 단지 뒤편 뿐입니다. 그렇다면 스타벅스에서 에코포레가 입지적으로 대전동구에서 괜찮다고 생각했기에 여기다 지은게 아닐까 하는 생각이 들었습니다. 이런 생각과 동시에 에코포레 단임시 정말 신혼부부 수요가 엄청나다는 것을 알수 있었습니다. 그렇다면! 생각보다 에코포레가 굉장히 괜찮은 단지가 아닐까 하는 생각이 들었습니다 제 생각이 맞을까요? | E4: 대전 동구의 킥은 위치, 연식, 환경으로 대전 에코포레는 대전 동구에서 연식만으로 승부를 건다고 생각했으나, 스벅에서 이 땅을 선택했다면 위치역시 애매하지 않다는 것일까? 생각이 들었습니다. | F4: 케빈 - e편한 단지 저도 너무 좋았습니다 ㅎㅎ 스타벅스가 들어오는 것도 학생님 생각에 어느 정도 동의합니다 ㅎㅎ 다만 스타벅스는 우리가 입지 가치를 따지는 데에 우선적으로 검토하진 않는 것으로 알고 있어요 :) 그리고 그쪽 스타벅스는 DT이름은 없지만 DT느낌 같아요.. 따라서 스타벅스는 우선 머리속에 지워두고 학생님이 말씀하신 킥(선호요소)을 중점으로 단지 가치를 먼저 따져볼 것 같습니다 ㅎㅎ 가히 - 저도 에코포레 되게 좋게 봤습니다!! 신혼부부/영유아 자녀 부모들이 가성비 있게 거주할 수 있는 [외곽 신축 대단지]로 봤어요. 연식 괜찮고 브랜드까지 좋아서 젊은 분들 선호도도 높을 것이라 생각했는데, 학생님 말씀처럼 실제로 단임할 때 사람들 엄청 많아서 더 좋아보였습니다! 학생님의 결론은 동의하지만, 결론으로 향하는 과정에서 스벅의 의사결정(?)을 그렇게까지 높이 평가할 것 같진 않아요! ㅋㅋ (그리고 오늘 학생님이 전임으로 확인도 해주셨고!~ㅎㅎ) 다만 스벅과 별개로 용운동의 위치가 (예를 들어 가오동보다) 좋냐 나쁘냐는 좀 더 살펴봐야할 것 같습니다! (대전 중심 서구 혹은 대전역과의 거리 등) MZ - 저도 입지를 판단할 때에 스벅을 참고하는 것을 참 좋아합니다. 그런데 에코포레 뒷편의 스벅의 경우 저희가 실제 스타벅스를 가보지 않았고, (막상 가봤는데 엄청 작은 스벅일 수도 있고요) 주변에 아무것도 없다고 한다면 저는 주변 호재가 있는지 한 번 살펴볼 것 같습니다. 전임해주신 대로 의료원이 들어오기로 했다고 하여 DT점이 아닌 스벅이 있다는 게 이해가 되었는데 의료원이 만약 못들어온다고 하면 조금 아쉬운 입지의 스벅이 될 것 같습니다. 그런데 지방에서는 신축이 곧 입지다!! 라는 말을 어느정도 믿고 있기 때문에 에코포레의 위상과 어느정도 대단지인지를 살펴볼 것 같은데 그 자체만으로 입지를 만드는 건 4000세대 정도 되었을 때의 이야기라고 생각했습니다. 에코포레의 경우 2267세대로, 이 단지 하나만으로 스벅이 들어오기는 조금 아쉽다고 생각했었습니다. 그럼에도 나홀로 언덕 대단지에 속하기 때문에 투자하기에는 괜찮은 단지라고 생각했습니다. | G4: 아무래도 스타벅스때문에 혼란이 오신거같아요 저도 공감하는데요 스타벅스랑 맥도날드는 부동산사업하는곳이라던데 ㅎㅎ 아니면 초록마을이 있으면 학군지고 아이들이많다! 등등의 생각들이 저도 있었어요 일단 크게 대전동구에서의 입지가 무엇이 있는지 생각해보면 좋겠어요 대전동구 사임도 이제 다 제출하셨으니, 입지요소는 다들 파악하셨죠 어떤 입지가 가격을 경정하나요? 여러분들이 말하시는 연식이 환경이에요. 환경이 택지, 상권,연식이 들어갑니다 대전동구에 학군이 있나요?직장이 있나요? 지방에서 교통의 의미도 크지는 않아요. 그럼 남는건 환경이죠(=연식) 환경 : 택지 (쾌적성+안전성), 상권 (편의성), 연식 (쾌적성+하차감♡) 스타벅스는 없구요! 이제 연식이 좋은 이편한이 어느정도 선호도를 갖고있는지 파악해보면 되겠네요
B5: 3 | C5: 케빈 | D5: 동구 내에서 E편한에코포레와 은어송하늘채리버뷰에 대한 가치 비교가 헷갈립니다 ! | E5: 생활권은 하늘채가 확실히 낫지만, 가오동은 동구 내에서도 외곽이라는 인식이 강한 듯 해요 (택시기사님, 부사님, 실거주민 등) 환금성을 고려하면 투자하기엔 그래도 중심쪽이고 단지가 좋은 E편한이 비슷하거나 아주 조금 더 나은 것 같은데요. 튜터님의 생각은 어떠실지요 :) | F5: 가히 - 케부님 의견처럼 대전 거주민들이 가오동을 완전 외곽으로 보는 것 같다고 느꼈지만, 그래도 연식이 4년 더좋고 (내가 매도할 때도 연식이 꽤 괜찮을) 리버뷰 주변 균질성이 더 좋아서 저는 리버뷰의 손을 들어주고 싶습니다 ㅎㅎ. 로에 - 연식은 리버뷰가 더 좋지만, 눈으로 보았을 때 연식 차이가 크게 느껴지진 않았던 것 같아요. 그리고 e편한이 2000세대가 넘는 대단지로 상품성이 좋고, 브랜드 아파트라 사람들의 선호도로 조금 더 가져가지 않을까 싶습니다ㅎㅎ 위치의 장점이 둘 다 없다면 거주만족도가 어디가 더 좋을까? 생각해봤을 때 단지 분위기, 시설 등이 더 좋았던 e편한이 조오금 더 가치가 있을 것 같습니다. MZ - 지방에서는 연식이 곧 입지다!! 그리고 둘 다 입지가 조금 애매한 곳이기 때문에 연식으로 따지면 에코포레'20/2267^, 하늘채리버뷰'24/937^ 로, 둘 다 충분히 투자가치가 높은 곳이지만 하늘채리버뷰를 좀 더 앞단으로 생각할 것 같습니다. | G5: 대전동구의 입지요소로는 환경은 연식이죠 ㅎㅎ 두 단지의 연식이 모두 좋아요 그럼 여기서부터는 그럼 연식외에 다른 선호요인이 무엇을 갖고있는지 레이어를 쌓아보면 좋아요 일단 아직 여러분이 단지분석과 매물임장전이라 단지의 장단점을 자세히 파악하지 못하셨을거에요 그러니 전임, 매임하시면서 요부분 집중해서 파악해보시면 좋을거같구요 저는 생활권에 사는 사람을 볼거같아요 이편한은 신혼부부, 가오동은 가족이 주로 거주하고있죠 이부분은 현장에서 임장하면서 생활권에 사는 사람들, 그 분위기를 보고 오셔야합니다 더 자세한건 저랑 튜터링데이에 임장하면서 어떻게 봐야하는지 알려드릴게요 위치는 은어송생활권 반경에있고 연식도 4년더 신축인 하늘채를 우선으로 볼거같으나 제가드리는 말씀에는 가격이 다 빠져있어요 이렇게 생각하고 말씀드리지만, 나의 상황과 투자금에는 그 순위가 바뀔수있다는점도 같이 말씀드리고싶어요 또 투자로 봤을때 가치가 더 좋은걸 우선으로 보되, 질문에 나온거처럼 외곽이니까 대전역 인근에 같은투자금으로 할수있는 더좋은게 있는지 살펴봐야합니다
B6: 4 | C6: MZ | D6: 대전역이 가지는 의미 (지하철역, ktx) | E6: 지방에서는 자차를 많이 이용 하니 지하철역이 크게 의미 있지 않고, 또 대전이 부산만큼 지하철이 활성화 되어 있지도 않다 보니 크게 의미 있다고 생각하지 않았었고, ktx 의 경우에도 지방의 경우 원도심에 많이 있다 보니 크게 의미있지 않을 거라고 생각했는데, 대전역과 가까운 단지들에서 서울과의 출퇴근, 대전역을 많이 언급하는 걸 보니 대전역은 좀 의미가 다른 거 같다고 생각했습니다. | F6: 케빈- 지하철역을 기준으로 하면 도시교통량이 중요한 것 같아요 ㅎㅎ 대구도 교통체증이 심한 곳은 지하철이 의미가 있듯이 대전도 서구 주요 지역에서 교통체증이 심한 편이라면 중심부 노선 정도는 의미가 있겠지만 저희가 가는 동구에는 택시기사님 모두가 대전은 차 안밀려요 ~ 라는 것을 말씀하신 것을 보아 유의미하지 않다고 생각합니다 :) 대전역은 시외로 이동하는 수요가 있기 떄문에 엠지님이 말씀하셨던 것처럼 어느 정도는 의미가 있을 것이라 생각합니다 (남편 동탄 출근, 아내 구미 출근 등) 이는 동구 신흥생활권 내에서 역과의 거리에 대한 매매가 및 전세가 비교로 알 수 있을 듯 합니다 :) 그리고 임보써보니 코레일 본사 직원수가 굉장히 많으네요 ㅎㅎ 가히 - 과거 대장이었던 이스트시티를 왜 좋아하냐는 질문에 부사님이 1초의 망설임도 없이 "대전역 가까워서"라고 했던 걸 보면 대전역이 그래도 꽤 유의미하다고 생각했습니다! ㅎㅎ 다만 대전역의 교통 가치가 뛰어나서라기보다 코레일 본사가 거기 있다보니 직주근접의 가치도 있지 않을까~ 생각했어요. 신인동 단지들을 조금 파보면 더 자세히 알 수 있을 것 같고.. 특히 [어진마을 vs 신흥마을]은 왜 3-4천씩 차이가 나는지 궁금했습니다 :) 정리하자면, 대전역이 서구/유성구를 뛰어넘을 (혹은 견줄만한) 가치를 지녔다고 보긴 어렵지만 동구 내에서 대전역 접근성은 유의미하다 정도로 봤습니다 :) 그늘 : 저도 이부분이 계속 고민됩니다. 내가 코레일 본사직원이면 동구 살까? 출퇴근이 힘든 서울도 아닌데 직주근접을 이유로 환경을 버리는 게 지방에서 제대로 보는 게 맞나 계속 의심되는데 이스트 사장님은 거기가 철도아파트랍니다. 어떻게봐야할지 저도 궁금합니다. 코레일 직원도 가족단위라면 서구/유성구 살면서 교통도 편한데 자차출퇴근 할 것 같고, 아니면 서울 살면서 공짜기차 이용하거나, 솔로나 자녀 없는 부부는 동구 거주가능하지 않나 생각해봤습니다. | G6: 제가 튜터링데이에서도 대전에대해 말씀드릴텐데 지방에서는 타지인이 이해할수없는 부분들이있어요 ㅎㅎ 일단 대전역이 가깝다는건 교통+직장의 의미입니다 실제로 직장이 서울과 지방인분은 신혼집을 대전역 인근에 구할수도있어요 그 대전역이라는 수요가 직장이 될수도있는데, 그게 꼭 대전에 있을필요는 없다는걸 말씀드리고 싶은겁니다 대전역으로 출퇴근하거나 꼭 주변에 살아야하는 수요가 있어요 요부분은 한번 여러분이 단지분석혹은 매물임장하면서 어디까지가 그들의 마지노선인지 파악해보면 좋겠습니다 이런거야말로 진짜 임장을 통해서 알수있어요 사실 다들 아실거같지만, 전임과 매임을 통해 파악합니다 여기 사는분들 회사출퇴근 어디로 주로하시는지 여쭤보거나 직접가서 어떤직업 갖고게신지, 이사 왜가시는지 어디로가시는지 이 단지에 사람들이 사는이유를 직간접적으로 물어봅니다
B7: 5 | C7: 가히 | D7: 가오동에서 투자범위를 어디까지 볼 것인가? | E7: 하늘채리버뷰까지! 코오롱하늘채2차는 16년으로 이미 10년.. 어쩔 수 없이 연식 아쉬운 단지를 해야한다면 동구보다는 수요층이 더 탄탄할 (거라고 예상되는) 서구/유성구를 우선할 듯 | F7: MZ : 하늘채리버뷰까지만 볼듯. 하늘채2차부터 16년식이지만 조금 애매. 로에 : 하늘채리버뷰까지만 볼 듯. 코오롱이 여기중에서는 연식이 괜찮은 편이지만 동구 전체로는 연식이 이미 상품성이 떨어지기 시작. 케빈 : 저는 신흥 생활권까지만 볼 듯 합니다 :) 리버뷰도 투자못할 건 아니지만 너무 하급지의 중간생활권이라 좀 더 좋은 선택지가 있지 않을까 생각합니다. 차라리 대전 내 중급지 중위생활권이 좀 더 수요가 많다고 생각합니다 라니: 저는 중구에 조금더 연식이 떨어지더라도 중심부에 있는 단지를 할거 같습니다. 그래프가 누워있는것을 보고(?) 식겁했습니다 ㅎㅎ 이부분은 튜데때 만나서 이야기 해봐도 좋을것같습니다! | G7: 투자마지노선에 대한 질문들이 몇개더 있었는데요. 일단 투자하지못할 단지는 없습니다. 우리는 선호도와 투자금에따라 우선순위를 정할뿐입니다. 가오동 투자우선순위가 쉽게 오지않을뿐이에요... 앞단에 항상 더 좋은것들이 있어서요. 여기서 조심해야할 사항은 우리가 앞마당으로만들고 무시?하던 단지가 2년후 소액으로와서 투자기회를 줄 단지가 될수도있어요. 실제로 제가 학생때 실전반에서 앞마당만들면서 무시하던 단지를 1년후에 어렵게 모셔서 투자했습니다 ^^ 그러니 이렇게 만들때 제일중요한건 임보에 단지의 가치와 선호도를 반드시 기록하고 남겨놓아야해요. 1년후에 대전동구에서 변하는게 크게 어떤게 있을까요. 변하는건 가격입니다. 가치는 안변해요. 공급말씀주시는것도 사실 가격을 말하시는거라고 이해되어요. 그러니 지금 우리는 임보에 가치와 선호도를 잘 남겨야해요.
B8: 6 | C8: 가히 | D8: 판암동 삼코1단지 vs. 은어송 하늘채리버뷰 | E8: 하늘채리버뷰 ((가격 확인 전. 분임 & 단임 만으로 판단)) - 삼코가 단지 느낌과 상권접근성이 훨씬 더 좋았지만 연식 (24vs18), 받아줄 수요층이 더 많을 것 같다 생각해서 리버뷰 - 삼코1단지가 판암에서 독보적이라 실제 가치보다 판암 거주민들의 자부심?으로 가격이 높게 형성되어 있을듯 | F8: MZ : 연식으로 접근. 하늘채리버뷰 (삼코1 은 실거주면 고민해볼듯) 로에 : 환경 좀 더 우세. 삼코1단지. 연식(상품성)은 떨어지지만 현장에서 더 살고싶은 마음이 들었음 아르떼 : 삼코(주변환경과 상품성이 좋은것 같다) 연식좋을때 사서 팔고 나오면 괜찮을것 같은데 투자 마지노선 느낌인듯 하지만 가격이 싸다면 고려하겠음. | G8: (이제 막 사임을 제출, 단지분석과 매물임장 전임을 감안하고) 다른분들 의견도 반반으로 나뉘는것같아요. 반반으로 나뉘죠? 그럼 진짜 비슷한거에요, 장단점이 상쇄되면서 수요도 똑같이 분산되겠죠. 그럼우리는 거기서 더 높은 수익률을 위해 이렇게 노력하는 투자자들이니, 매물까지 들어가서 비교하면서 볼거같아요. 중요한건 실거주인지 투자인지에 따라 내가 가능한 매매가, 혹은 투자금에따라 순서가 바뀌겠죠. 가치가 이렇게 비슷하다면, 더 딮하게 물건대 물건으로 비교해야하는 거에요. [추가 질문] 우리는 결국 전세 레버리지 투자자니 개별 단지 매물대 매물로 보되 전세 수요가 더 큰곳 (사람들이 더 많이 찾는곳)을 매물임장으로 파악하고 결론내리면될지? 에 대한 질문이었습니다! → 네 물건대 물건이라는건 결국 물건 가격, 상태, 동층향이 다 포함된 이야기에요. 조건에서 전세의 조건에따라 우선순위가 중요해지는거죠. 말씀처럼 전세수요가더 큰= 가격이더 높은 으로 이해됩니다. 그럼 투자금이 더 적으니 우선순위가 맞아요.
B9: 7 | C9: 가히 | D9: 한화꿈그 투자할 수 있나? | E9: 연식도 아쉬운데 동구, 그것도 용운동이라 입지 가치가 거의 없다고 생각.. 대전이 오르고 올라 투자할 곳이 여기밖에 없다해도 차라리 다른 지방 지역을 가겠다. (=투자안한다.) | F9: MZ : 외곽이라는 택시기사님 의견, 동구도 외곽인데 거기서 더 외곽느낌 나면 투자로 고려하지 않을 듯 로에 : 연식이 경쟁력이 없는 연식인데 그만큼 강점도 없다. 수요를 끌어오지 못할듯 아르떼 : 주변에 좋아할만한게 없는것 같다 그럼에도 불구하고 투자를 한다하면 앞단에 대전역 더 가까운곳이나 신흥쪽 더 좋는 단지를 먼저 찾아볼것 같습니다. | G9: 투자에는 우선순위만 있을뿐, 투자 못할 단지는 없다. (다만 한화꿈그가) 그 순위가 너어무 후순위로 까마득한거죠. 내가만약에 정말 이투자금밖에 없고, 그때 한화꿈이 제일 우선순위면 투자하는거에요. 자칫 이단지는 투자안해라는 생각으로 투자기회를 놓칠수있어요. 이게정말 한끗차이라서 그냥 우선순위가 아니다라고 생각하고 바라보시면 좋겠습니다.
B10: 8 | C10: 가히 | D10: 삼코1 vs. E편한 에코포레 | E10: E편한에코포레 - 상품성 : E편한 > 삼코 ⇒ 연식, 브랜드, (+세대수) - 환경 : E편한 =< 삼코 ⇒ 삼코 앞 신축 상권, 주공이긴 하지만 아파트 택지,, 다만 그렇다고 해서 E편한 주변 환경이 유해한 것은 아니었기 때문에 비슷한 수준으로 평가. - 교통 : E편한 < 삼코 대전 동구의 최우선 선호요소를 상품성으로 봤기 때문에 E편한 선택 | F10: 로에 : 에코포레, 더 대단지, 내부 쾌적, 아이들 위한 시설 많고 아이들도 많고 젊은 어머니들 많고 살고 싶은느낌 . 그런데 따로떨어진 두동(117,118) 보다는 삼코1 선호. MZ : 언덕이긴 막상 가보면 아이들 많고 활발한 분위기. 에코포레 더 좋음. 라니 : 전세수요가 어느곳이 더 붙는지는 확인해봐야 알겠지만 삼코1은 위치적인 이점이 있고 e편한은 연식 그 자체+초품아 이점이 있음. E편한이 신축이긴 하지만 신혼부부,애키우는 유딩초딩으로 수요가 한정되진 않을까 라는 생각을 해봄. E편한이 김해 주촌 두산위브같다는 생각을 해봄 (외곽인데 단지 그 자체만으로도 사람들이 좋아하는 아파트) 아르떼 : 밖에서 볼땐 안쪽이라 그랬는데 단지 내부가 너무 쾌적했고 애들도 많아 활기찬 느낌 . e편한 에코포레 선택할듯 | G10: Q6과 비슷 → 전임/매임/단분으로 숨참고 딥다이브하기! ㅋㅋㅋㅋㅋㅋㅋㅋㅋㅋㅋㅋ누가 "숨참고" 써주셨나욬ㅋㅋㅋㅋㅋㅋ
B11: 9 | C11: 가히 | D11: 케빈님 질문 답을 쓰다가 문득 궁금해진 게, 일반인(?)들이 이사 or 집 구할 때 지역을 넓게 보기보다 본인이 살던 곳 주변 신축을 가는 경우도 꽤 있는데.. 가오동 신축의 이사 수요와 용운동 신축의 이사 수요가 각각 어디 살던 어떤 사람들일지 궁금합니다. → 대전 동구 애매한 생활권 신축의 수요층 | E11: 동구에 살다가 동구 안에서만 이사하는 분들이 꽤 많을 것 같고, 신혼부부가 아닌 이상 생활권을 바꾸면서까지 거주지를 바꿀지는 의문입니다. 특히 가장 좋아하는 신인동/천동 쪽이 아니라 가오동/용운동으로는.. "굳이?" 싶습니다. (그나마 e편한이 브랜드라 쪼끔은 다른 생활권 수요를 끌어들일지도) 전임으로 해결하는 수 밖에 없을 것 같은데 부사님께 어떤 식으로 질문을 드리면 좋을까요? → "새 아파트 생기면 보통 어떤 분들이 이사오세요?" | F11: 케빈 : 저도 원주민들 수요가 제일 클거 같고 대전역 출퇴근 가성비 수요, 또는 그 주변 금산이나 옥천에 조그만 산단 일자리가 있던데 그 정도 수요가 있지 않을까 생각합니다 ! 가히 : (제가 질문했지만 아까 전임하면서 살짝 들은 얘기가 있어서) 가오/용운은 아니지만, 리더스 입주 때 서구/유성구 살던 젊은 분들이 엄청 많이 오셨었다고 해요! 분양가가 워낙 쌌기도 해서 인기 많았다고, 그런데 동구를 "거쳐가는 아파트"라고 인식하신다 하고, 그래서 59도 선호도가 상당히 높은 점 확인했습니다. 지방은 무조건 84 선호도가 높을 줄 알았는데 대전은 (혹은 대전 동구는) 그렇지 않다는 점이 특이했어요. (+리더스 전세하려다 매매하셨던 분들 지금 가격 많이 올라가지구 요즘 매우 기뻐하고 계신다는 얘기도 살짝 전합니다.. ^^) 라니 : 저 이거 전임하면서 물어봤었어요! 여기는 주로 어떤 사람들이 이사오냐구요.(실거주로 전화함) 확실한건 신혼부부나 애있는 엄마들은 이 단지를 찍어서 온다고 했습니다. (아마도 신축살고싶은데 돈이 안되는 사람들이겠죠) 반면 이 사람들이 또 돈모아서 서구 유성구 단지로 이사도 갑니다.. 명암이 있는것 같습니다! | G11: 요거는 뭔가 정답은 없는 질문인데요. 일단 매임가셔서 자세히 보시면 좋겠구요. 그럼에도 답변을 드리려고 노력해본다면... 제생각에는 일단 주변에 입지가없는곳에 건물연식만 보고오면 몸이 가벼운사람이 올 확률이 높겠죠. 아이가없는 신혼부부, 자녀가 성인인 가족처럼요. 그러고 전임과 매임으로 한번더 확인해볼거같아요. Q) 부사님께 어떤 식으로 질문을 드려야 이 정보를 캐낼 수 있을지 보통 매도이유를 물어봅니다. 세입자 연령대나 누가주로 보러오는지 물어봅니다. 매임가서 사는사람을 관찰하고옵니다. 그래서 가능하면 공실은 잘 안잡아요. 계속 누가사는지 어떤사람이사는지를 물어보고 파악하셔야해요. 그분들의 소득수준과 수요가 얼마나 두터운지가 투자랑 연결되니까요 + [라니님 꿀팁] 사장님~ 여기 신혼부부가 집 많이보러 오나요? 주로 누가 오나요? ((전세수요파악)) + [MZ님 추가 질문] 갑자기 궁금해진 건데, 신혼부부 많이 사는 단지와 가족단위(부모+초중딩자녀) 로 사는 단지는 어떤 게 더 좋다, 라는 게 있는지 궁금합니다. → 정말 솔직하게 답변드리면, 그분들의 소득수준을 생각해보시면 좋겠어요. 예를들면 가족단위(부모+초중딩자녀) 세입자에게 전세금 2천 요구와 신혼부부에게 전세금 2천만원을 요구했을때 내가 세입자라면 어떨까요 (전세상승금이요) 실제로 거주하는 지역사람들의 입장에서 생각해보면 투자에도 도움이됩니다. 제가 가족형태로 말씀드렸지만 부유한 신혼부부가 거주하는 동네도 있어요 ㅎㅎ 예를들면 성동구가 그런곳이죠. 그래서 지방에서는 직장이 중요합니다. (가족단위 수요 혹은) 신혼부부가 아니라 사람들의 수요로 생각을 확장하면 더 도움되실거에요. 단지분석, 매물임장까지 결론쭉 써보면서 지역사람들의 입장과 수요 집중해보면 좋을거같아요. + [케부님 정리] 우리집에 전세금을 잘 받쳐줄 수 있는 세입자를 찾아봅시다!~
B12: 10 | C12: 가히 | D12: 대전 동구 생활권을 어떻게 분류하셨나요? 그리고 생활권의 순위는 어떻게 나누셨는지 궁금합니다!~ | E12: 1) 신인/천동 2) 가오/대성 3) 용운 3) 판암 4) 삼성/성남 순위 : 신인/천동 > 가오/대성 > 용운 = 판암 > 삼성/성남 (*삼성/성남 : 홍도/가양동까지 포함) 그런데 Top10을 보아하니.. [삼성/성남/홍도/가양]의 단지들이 상위권에 훨씬 많이 포진해 있었습니다.ㅠ 생활권 순위는 주거 환경이 좋은 순대로 놓되, 개별 단지 가치가 높다 (연식, 브랜드 신축 등) 라고 봐도 무방할까요? 혹은 대전역/서구 둔산동 접근성 고려해서 삼성/성남의 땅의 (물리적 위치) 가치가 높다고 판단해야 할까요? | F12: 케빈 : 저도 신흥 > 가오 >= 판암 > 성남 정도로 생활권 순위는 이렇게 생각했지만 땅의 위치로만 따졌을 때는 삼성성남이 1등이라 생각합니다. 관악구에서도 남현동이 땅의 위치는 제일 좋지만 상위생활권은 아니듯이, 대전역 위쪽도 땅의 가치는 제일 좋지만 아파트가 많이 없어 상위 생활권은 아니지만 단지가 딴딴하고 주변이 나쁘지 않으면 충분히 선호되는 단지라고 생각합니다 ! 따라서 삼성4구역이나 성남3구역 등 위쪽 개발이 이루어지면 삼성성남이 상위생활권이 될 수 있지 않을까 생각합니다 :) 그늘: 저도 지금 상황에선 삼성/성남이 균질성 환경 면에서 아쉬움이 크지만, 재건축된다면 의미있는 위치라고 생각했습니다. 그리고 비균질하거나, 외곽도 많은 동구에선 더욱 더 단지 바이 단지로 보는 게 맞겠다고 저도 생각했습니다. | G12: 대전동구의 가격결정 요소는 환경이었는데요. 이제 여러분이 제출하신 생활권 순위에서 어려워하시는 부분이 무엇인지 파악해보니 수도권과 지방에서 환경이 좋다는 정의가 달라요. 더 자세히 말씀드리면 지방에서도 지역마다, 생활권마다 환경이라는 입지요소가 다릅니다. 그지역에서 사람들이 좋아하는 환경이 상권일수도 있구요. 아파트 연식일수도있어요. 아니면 역세권일수도있어요 ㅎㅎ +[아까 정리 복붙] ★ 환경 : 택지 (쾌적성+안전성), 상권 (편의성), 연식 (쾌적성+하차감♡) 그게 수도권은 큰판으로 비슷한데 지방은 그게 참 너무다양하고 달라서 파악하는게 어려울수있어요. 그걸 여러분이 한달동안 파악하는거에요. 그걸 강의에서는 선호도, 가격결정요소라고 하는거에요. 그래서 순위는 (두구두구) 튜터링데이에 공개하겠습니다 ㅎㅎㅎ
B13: 11 | C13: 케빈 | D13: 새들뫼휴먼시아1단지 가격흐름을 봤을 때, 2012-2013년도에는 공급이 그리 많지 않음에도 전세가는 오르지만 가격이 소폭하락하는 모습을 보이는데 왜 그럴까요 ? | E13: 입주가 많지는 않은데다, 세종시 정부청사 이전으로 인한 거주수요까지 늘어나 전세가가 오르긴 했지만, 금리 상승기로 인해 매매수요로 올겨붙지 않았고, 잇따른 세종 내 대규모 입주를 위해 전세를 살며 기다리며 관망하는 분위기였을 것 같습니다. (지금과 비슷한 분위기) | F13: 학생- 오 찾아보니 세종시 대규모 입주로 매매가 잠잠해졌다고 합니다. 그래서 매매수요가 전세수요로 전환되어 그런 상황이 벌어진 것 같스비다 라니- 저는 조금 다르게 이해했습니다. 10-11년때 유성구에 공급이 많았고 이게 소화가 되지 않아서 12,13년에도 물량이 적어도 대전 내에서 해소되지 않은 것 같아요. 근데 또 세종 공급도 11년부터 스멀스멀 올라오기 시작했습니다.. 14년에는 불기둥이네요. 챗GPT에 검색해보니 당시 정책 불확실성으로 인한 전세난이 있었고(사람들이 집을 안살려고 함) 매수심리는 위축되어서 저가 급매위주로 소진됬다고 합니당. | G13: 요건 다양한 요인이 있을수있는데, 이 단지만 그런건지 아니면 생활권 내에 어느정도 선호도를 갖고있는 단지만 그런건지 파악해보면 좋겠습니다 사실 데이터는 확인용으로 보고, 전임을 열심히하시는게 더 도움이됩니다 이걸 답변을 드리기보단 이 질문을갖고 결론까지 가져가보는게 좋을거같아요 그래야 내투자시 리스크까지 헷지될거같습니다
B14: 12 | C14: 케빈 | D14: 저희 조에 저를 포함해 대전이 첫 임장지이신 분들이 많은데요. 한 지역을 처음갈 때, 또 심지어 동구처럼 그 지역의 하급지일 때, 지역과 친해지기 위한 튜터님만의 팁이 있을까요 ~? | E14: 대전을 전체 판으로 놓고 알아보는 과정이 필요할 듯 한데, 아직 앞마당이 많이 없다면 어떻게 알아가야할 지가 궁금합니다 ㅎㅎ | F14: 로에 - 전체적으로 그 지역의 중요한 요소(ex.학군, 직등)가 무엇인지 파악하고 접근하는 것 같아요! 예를 들어서 마산을 먼저 임장간다 하면 창원에서는 국가산업단지(직장)가 중요하니까 마산에서 이 부분에 영향을 끼치는 요소는 뭘까? 하고 접근하면 그 지역을 이해하기 더 쉬워지지 않을까 싶습니다! 라니- 저도 로에님이랑 비슷한 생각인데 임보 쓰기 전까지는 연식 좋은것만 보자! 라는 생각을 배제하는 편이에요. 완전 썩구축 말고 애매한 3억짜리 애들도 매임을 못하면 전임이라도 합니다. | G14: 일단요건 앞마당 갯수에따라 다른데요 10개이하면 1개구를 자세히 파요 10개이하면 1개구를 자세히 파요 10개이상, 어느정도 임보가 익숙하거나 속도가 붙으면 지방에서 입지작성할때 광역시면 크게 한판으로 보고 임장지를 들어갑니다 그리고 여러분은 이미 지방투자 실전반 강의를 들으셧잖아요 1강에서 다 알려주셔서 사실 다 아셔요 ㅎㅎ 네 강의자료 레버리지하세요 그런식으로 간단하게! 파악하고 임장지를 깊게 들어갑니다 1개구를 제대로 이해하면 다른지역이해도 빨라요 결국 그 지역사람들을 이해하는게 중요해서그렇습니다 (같은광역시 기준입니다)
B15: 13 | C15: 학생 | D15: 대전 동구에서 이편한세상대전센텀비스타 같은 주복의 영향력은 어느정도 일지 궁금합니다. 대구처럼 주복을 대전도 좋아하나요? | E15: 우선 35평 현재 호가가 4억대 중반으로 형성되어있습니다. 26년 6월에 입주하는 신축임에도 불구하고 은어송하늘채리버뷰 가격가 비슷한 것을 보니, 연식이 뛰어나도 그리고 위치상으로 나쁘지 않음에도 대전 동구에서 주복은 그리 선호하지 않는 것으로 보입니다 | F15: 케빈 : 대구 사람들이 주복을 왜 좋아할지 생각해봤을 때, '주복이라서' 좋아한다기 보다는 대구에 중심지 땅 자체가 너무 좁기 때문에 어쩔 수 없이 주상복합이 많이 들어오고, 대구 사람들은 '주복 정도만 되어도' 만족하는 것이 아닐까 생각이 듭니다. 그러니 대구에선 주복을 최대한 짱짱히 짓기도 하는 것 같고요. 이 점에서 대전 동구는 빈 땅이 있는 것은 아니지만 대단지들도 있고 재개발되어 들어올 수도 있기 떄문에 주복에 대한 선호도는 크지 않을 것이라 생각합니다. 실제로 이편한이 들어오는 땅은 저희가 분임을 처음 했을 때 매우 별로였던 생활권이기도 했고 그런 점이 가격에 녹아있지 않나~ 생각합니다 라니 : 대구사람들 주복 환장합니다(원주민이 이야기 하는거니 들어주세요 ㅎ). 특히 달구벌대로에 붙어있고 으시대는거 좋아하면 더 좋아하죠. 하지만 대전은 대구만큼 주복보다는 국평을 선호한다는 생각이 더 강하게 들었습니다. 특히 시세따면서 은어송 생활권에 59가 없다는 것을 보고 아 여기는 진짜 처음부터 지을떄 84를 타겟팅으로 하고 짓구나 하는 생각이 들었습니다.!! MZ : 대전 동구는 연식이 중요한데, 생각보다 동구에 연식 좋은 아파트가 많지 않아서 연식이 좋다면 주복도 의미있게 볼 수 있겠다고 생각헀습니다.
B16: 14 | C16: 그늘 | D16: 동구에서 학원상권의 의미 | E16: 가오동에 학원가가 좋지만, 택시기사님께 거긴 맞벌이 부부가 학원만 보내놓고 케어가 안된다고 하셨습니다. 그러고 보니, 중학교 성취도도 형편없는 수준이더라고요. 학원가상권이 그렇게 좋아도 애들 수준이 그렇게 떨어지면, 학원가가 의미가 없다고 생각합니다. | F16: MZ : 생각보다 학업성취도도 높지 않고 매력적인 아파트가 많지 않았습니다. 엄청 의미 있는 학원가로 생각하지 않을 것 같습니다. 케빈 : 그늘님 말씀처럼 손품으로나 발품으로나 학업성취도, 학원가 면에서 학군으로의 의미는 없을거라 생각합니다 ~ | G16: 대전 동구가 학군지인가요?외부에서 동구로 아이를 교육시키러 이사오나요?그럼 동구에서 학원은 환경, 상권으로 생각하시면 될거같아요
B17: 15 | C17: 그늘 | D17: 이편한에코포레 위치를 유의미하게 봐도 좋을까요? 외곽은 외곽일까요. | E17: 코레일 직원이 동구에 산다는 가정 하에, 운전을 못하지 않는 한, 굳이 이스트에 살까? 신축2000세대인 에코포레에 살까 생각해보았습니다. 에코포레가 차로 대전역까지 8분이더라고요. 저희야 분임으로 뺑뺑 돌았지만, 실제로는 매우 가까워보이더라고요. 택시기사님도 여긴 아침에 대전역까지 안막힌다하시고, 막상 에코포레 가보니 거주민들 수준이 좋아보였습니다. 이런 외곽 신축이라면 의미있지 않을까(학군, 환경 포기하고 동구 살기로 마음먹었다면) 생각합니다. | F17: 라니 : 전임시트에도 적었는데, 여기는 사람들이 가격 때문에 찍어서 오는 단지이지만 신혼부부나 3인가정 수요를 확실히 끌어들일 수 있는 단지라고 생각합니다. 하지만 위치가 가지는 의미는 약하다고 생각합니다. 우리가 보통 '중심부에 가까이 붙어있다' 라고 설명하는 곳은 전부 대전을 전체로 놓고 봤을 때 그나마 서구 중구에 붙어있는 단지들이었습니다. 제가 생각했을 때는 여기는 위치보다도 연식이 가지는 힘이 더 크다고 생각합니다 하지만 섣부른 판단일 수 있으니 매임하면서 한번 더 생각을 입혀보겠습니다 :) MZ : 연식이 곧 환경이다! 이 정도의 연식에 대단지 아파트라면 그 자체로 의미있는 환경이 될 것이라고 생각합니다. 의미 있는 곳이라고 생각했습니다. | G17: 거주민 수준이 좋아보이셨다고 적어주셨는데요에코포레 거주민 수준을 매물임장 다녀오셔서 확인해보시면 좋겟어요 매물임장까지 다녀오셔서 안에사는 사람들이 누군지 어떤사람들이 사는지 보시면 좋겠어요
B18: 16 | C18: 라니 | D18: (튜터님 다음번에 답 주셔도 됩니다) 공급파트를 쓰다 보니 앞으로 세종 공급이 없습니다. 강의에서 배웠듯이 대전 공급은 세종 공급까지 같이 봐야 한다 라는 말이 있었는데요, 과거 시장에는 어느정도 이해가 되었습니다. 하지만 앞으로의 세종 공급은 거의 없는 시점에서, 세종 공급을 같이 보는게 유의미할까 라는 생각이 드는데 튜터님+조원분들의 생각이 궁금합니다. | E18: 인구이동에서 앞으로 세종에 공급이 터지고 더 중심부에 매력적인 공급이 나오면 움직일 수도 있기 때문에 아직도 유의미한지가 궁금했습니다 ㅎㅎ | F18: MZ : 세종이 앞마당은 아니라서 공급에 대해 잘 모르긴 하지만 공급이 없더라도 주변 영향을 받는 지역의 공급을 트래킹하는 것은 루틴화에 도움이 될 거라고 생각합니다! 케빈 : 저도 엠지님처럼 안하는 것보다 하는 것이 좋다고 생각합니다~ 다만 동구보다는 유성구에서 주효할 듯 합니다 :) | G18: [튜터님 팁] 요거는 공급분석을 한번 해보면 좋을거같아요. 과거에 세종공급의 영향이 얼마나있었는지 보시면 좋을거같아요. 과거 세종공급이 있을때 어느동네에 영향이 가장컸고, 얼마나 컸는지 보시면 좋을거같아요. 튜데 이후-> 구별로 뜯어보기
B19: 17 | C19: 라니 | D19: 튜터님 주말은 잘 보내셨나요! 튜데 끝나고 집 가는길에 튜터님이 비교분임 해주신 유성구의 '이 생활권에 없는 것' 을 열심히 생각했는데요 (새로운 시도였고 매우 재밌었습니다) 3,4주차 매물임장 할 때 저희가 부사님께 '매도사유가 어떻게 되냐' 라고 물어보는데요 이 부분을 '이 생활권에 없는것' 으로 확장해서 생각해도 되겠죠?!!! | E19: 도안신도시 생활권에 없는것 = 학군-> 이건 둔산에 있다! 라는 생각을 하게 되니 왜 도안베르디움이 연식이 빠지는데도 가격을 지키고 있는지가 이해되었습니다 | F19: 케빈 : 저도 동의합니다 ~ 없는 것을 찾아서 갈 테니 ~ 로에 - '매도사유=해당 단지, 생활권에 없는 것' 확실하게 이해됐어요! 저도 이부분에 있어 동의합니다ㅎㅎ | G19: 너무 좋은 질문입니다 💛 사람들이 매도하거나 이사나가는 수요가 바로 그단지의 약점이나 부족한 점으로 볼수있어요! 이렇게 현장에서 매물임장가셔서 내가 생각한 수요가 맞는지 확인하고 오시면 좋겠습니다~ 또 반대로 사람들이 정말좋아하는 수요에대한 선호도의 크기도 느껴보고 오시면 좋겠습니다! 대전역 접근성을 도대체 얼마나 좋아하는건지! 생생한 후기 기다리고있겠습니다 *내가 생각한 강점/약점과 진짜 거주민들의 이유 매칭시켜보기 *도대체 얼마나 왜 !
B20: 18 | C20: 학생 | D20: 단지분석 4분할 하면서 놀란것은 은어송1단지풍림아이원이 6개월간 20퍼센트 반등했다는 사실입니다 아니 가오동 외곽에서 왜 여기를 샀을까? 하는 의문이 들었습니다 대전 동구의 킥은 위치와 연식인데 여기는 두개 다 빠지는 거 아닌가? 오히려 위드힐은 위치상으로 은어송1단지 풍림아이원보다 괜찮은데 3개월 동안 4퍼센트 하락했습니다 가오동 정말 헷갈리는 동네네요 | E20: 우선 대전 동구의 킥은 위치와 연식이 중요합니다. 그럼에도 가오동은 가오동 안에 그 중심상권과 가까우면 선호를 좀 더 받는 것 같다고 생각이들었습니다 은어송1단지풍림아이원이 정말 가까이에 상권이 있다보니 아무래도 선택을 받았지 않았을까 싶습니다. 그럼에도 대전 동구는 위치와 연식이 중요하다는 제 생각에는 변함이 없습니다 | F20: 가히 : 오.. 질문을 보자마자 아실에서 풍림을 확인했는데 진짜로 최근에 거래가 쭉! 상승했더라고요!! 그런데 그래프에서 같이 눈에 띄는 부분이.. 전세가 완전 딱 붙어서 상승해있더라 이말입니다 ㅋㅋ (전세가가 치고 올라와서 매매가를 끌어올리는 것처럼 보였어요.) 그와 달리 위드힐은 전세가가 최근에 치고 올라와서 진짜 소액 투자 기회를 주고 있네~ 라는 생각이 들었습니다. 정리하자면, 위드힐이 최근 3개월간 살짝 내리막을 보여준것은 사실이지만 2013년식이라 매물 컨디션에 따른 차이일수도 있고, 오히려 22년 12월 저점 대비 상승한걸로 봐서 저는 그래프상으로도 위드힐이 앞서있다고 읽혀집니다!! 물론 아실그래프가 정답은 아니지만, 두 단지 그래프를 비교해보면 (평형이 다양하긴하지만) 위드힐이 더 먼저 & 더 크게 상승하는 것도 확인이 되어요!~ 가오동도 사람들이 사는 곳이고 일반인들은 원래 거주하던 동네를 잘 떠나지 않는데다 요즘 워낙 전세가 귀해지다보니 이럴거면 차라리 매수해~로 많이 넘어간게 아닐까 짐작해봅니다 :) 케빈 : 6개월 전은 특히나 낮게찍히고 최근거래는 특히나 높게 찍혀 20%라는 상승률을 만들어냈네요 ㅎㅎ 이건 물건 단위로 좀 더 상세하게 들어가 볼 필요가 있겠고요 상승률은 언제까지나 숫자이고 참고용으로 생각해주시고, 학생님의 킥으로 가치 비교를 하는 데에 더 우선을 두셨으면 좋겠습니다 ㅎㅎ | G20: 요건 단지의 상승를 보시고 질문주신것같아요 수익률을 볼때 조심해야하는건, 그 단지에대한 가치로만 생각하는것이 아니라 당시에 그단지의 연식, 주변의 상황까지 같이 보시면 더 입체적으로 이해되실거같습니다 과거시점의 단지가치를 지금시점으로 가져오면 다른단지가 나오게될수도있어요
B21: 19 | C21: 그늘 | D21: 단지분석의 반등여부 칸을 정리하면서, 동구에는 아무래도 경제적 능력이 아직 부족한 신혼과 영유아가정이 많이 살다보니, 20평대를 선호한다는 이야기를 전임에서 많이 들었습니다. 그래서 주요단지는 반등여부에 20평대와30평대를 같이 넣어보았는데요. 신흥SK의 경우, 20평대는 +32%, 30평대는 +52%반등했더라고요. 역시 20평대를 선호해도, 오름 폭은 30평대가 좋다고 이해해야 할까요? 같은 의미로 지방에서는 가능하다면 투자금을 더 들여 30평대를 투자하는게 낫다는 결론으로 가는 게 맞을까요? | E21: SK 20평대와30평대인데요. 평수로 등락률 비교로도 해석이 가능할까요? 전 SK 20평대선호도도 꽤좋다고 생각했는데, 역시 오르는 건 30평대인가...라는 생각을 했습니다/ (튜터님 말씀)그늘님~~ 이런 고민들 너무 좋아요! 💛 더 깊게들어가서 결국 고민하는 본질을 더 생각해보면 좋을거같아요. 투자하는 경우라면 같은 투자금인가요. 실거주인가요. 사람들의 선호도를 보기위함인가요. 그런 관점으로 고민해보면서 단지분석 혹은 질문시트 남겨주세요~ | F21: 가히 : 저 또한 "지방은 84지"라는 편견을 가지고 전임했다보니 부사님들 말씀에 59에 혹했어서 넘 공감되는 질문이었습니다ㅎㅎ. 저는 20평대가 낫냐 30평대가 낫냐보다 내 투자금에 뭘 할 수 있는지를 더 우선으로 볼 것 같고, 20평대도 30평대도 각각 다른 장단점을 가지고 있다고 생각했습니다. 다만 같은 투자금이라는 전제라면 20평대가 신혼/영유아 수요가 있더라도 저는 30평대를 우선적으로 볼 것 같습니다. 동구만의 특징보다 30평대 아파트가 가진 본질적인 가치가 더 높다고 생각합니다! 케빈 : 우선은 가격대가 둘 다 저렴한 구간이니 디딤돌(신혼 6억 이하) 같은 정책 대출 쓰기도 좋을 것이고, 그러니 인기가 좋은 30평대가 더 많은 반등을 했다고 생각합니다, 그리고 대전역을 이용하는 특성 상 부부이며 맞벌이가 많을 것이라 생각되기도 하네요 ㅎㅎ | G21: 사실 평형보다 앞단에 있는건 단지의 선호도입니다 그리고 투자적으로 생각하면 투자금까지 넣어서 볼수있어요~ 59와 84의 투자금이 어떻게 되나요~? 저는 만약에 같은 투자금으로 84를 할수있다면 할거같아요~ 그렇지만, 투자금의 차이가 굉장히 크죠? 만약에 sk뷰 84에 2억을 넣는다고 가정해보시면 훨씬 우선순위의 단지들이 앞단에 있을거에요 sk뷰 59에 대략 8천으로 투자한다고 생각하면, 어떨까요 요렇게 생각해보면 엄청 심플해집니다 그럼 8천으로 할수있는 가장좋은 투자처는 어디지~? 그것도 대장을~? 요렇게 가치를 먼저보고 그다음 투자금을보면 우선순위가 올라갈거같아요 (59가 가격 왜곡이 많더라고요!!) 하락장의 특징입니다 ㅎㅎ 좋은가치의 저평가를 쏙쏙 골라살수있는 기회겠네요! ㅎㅎ
B22: 20 | C22: MZ | D22: 진담님 단지분석 4분할 장표 키워드에 대한 질문입니다. 세대수나 학업성취도 등 데이터를 정확히 적지 않고, 키워드처럼 뭉뚱그려서 적는 게 어떤 의미를 가지나요? (예를 들면 1328세대 인데 1,000세대 라고 적는다던지, 학업성취도 83%인데 80%라고 적는다던지 하는 것들이요) | E22: 뭉뚱그려 보면 오히려 4분할해서 비교할 때 더 직관적으로 나눌 수 있겠다고 생각했는데요, 신흥Sk뷰와 이스트, 리더스시티를 만드는 장표에서는 거의 다 비슷한 키워드로 나와서 이럴 때에는 어떻게 비교하는 게 좋을까 하는 고민이 들었습니다. 1,300세대정도의 대단지와 4,000세대 정도의 대단지도 키워드로는 같은 키워드로 나오게 될 것 같아서요! 이런 부분이 궁금했습니다. | F22: 가히 : 앗 MZ님.. 저는 개인적으로 제 업무 특성상 데이터 정확도가 넘나 중요해서 완전 똑같은 걸로 고민했던 적이 있었는데ㅋㅋ 근데 언젠가부터 단지 비교 시, 대충 1000세대 이상 규모의 대단지냐 500세대 규모냐의 등으로 좀 더 큼지막하게 비교를 하다보니, 세세한 숫자에는 크게 연연해하지 않아도 된다는 걸 오히려 배우게 됐던 것 같아요! 여러 카테고리 (세대수, 연식 + 각 입지요소등)에서 비교하며 총체적인 판단을 내리다보니 비교하기 용이하도록 단위를 맞추신 것 같습니다! 그리고 저는 강사님들의 교안이나 방식을 따라하되, 필요하다면 좀 더 추가하기도 합니다. 결국 제 임보는 저를 위한거라 생각해서... / 신흥SK뷰 vs 이스트 vs 리더스는 딱 놓고 봤을 때 연식과 위치가 가장 도드라지게 다를 것 같은데 엠지님은 어떤 키워드 쓰셨을지도 궁금하네용!! 로에 - 저는 각 단지에 선호하는 요소가 얼마나 들어가있을까? 로 크게 생각했습니다! 생활권 전체적으로 선호하는 요소를 더 많이 가진 것을 우선으로 보되 세세한건 그 안에서 추려내서 더 깊게 분석해보면 되지않을까 싶어요! 근데 저도 단지이름 옆에 (연식, 세대수)를 추가로 적긴했습니다ㅎㅎ 케빈 : 엠지님 디테일한 분석 넘 좋네요 ㅎㅎ 하지만 83%인지 80%인지 구분 하는 것은 우리가 경제적 자유를 위해 가는 길에서는 쓸모가 그리 크지 않은 고민일 수 있을것이라 생각합니다 ㅎㅎ 엠지님말씀처럼 뭉뚱그려서 더 편하게 비교해보시죠 ㅎㅎ:) | G22: 요건 기준을 정하고 나눈다고 생각해주시면 좋아요 예를들어 우리가 단지임장하고나면 사실 가치가 정말 천차만별로 정리하기 힘들잖아요~ 그럼에도 상, 중, 하 크게 3가지로 나눕니다 더 비슷하게 생각해주면 , 사람들이 1000세대를 넘으면 좋아한다는 개념으로 기준을 만족하는지를 보고 키워드로만 적어두신거에요. 사람들의 선호 카드를 많이 갖고있는 단지가 사람들이 제일 좋아할 가능성이 커지는거에요
B23: 21 | C23: 그늘 | D23: 진담튜터님 단지분석에서 거래량 아실에서 딸 때, 매매,전세,월세 구분없이 하라고 하시는데, 월세를 빼지 않는 이유가 궁금합니다. | E23: 진담튜터님은 매매전세월세 중 어느선호도로 거주하는지 보는 거라고하시는데, 사실 이해가 안됩니다. 이게 투자에서 어떤 의미를 가지는지 명료하게 정리되지가 않습니다. | F23: 가히 : 저도 그늘님과 비슷한 생각으로 실거래 차트에서 월세를 자주 빼곤 했었는데, 지난달부터 전수조사할 때 월세 매물수를 같이 보기 시작했습니다! 가장 첫번째로 월세 또한 그 단지에 거주하고 싶어하는 [수요]이기 때문이고, 두번째로는 전세보다 월세가 많은 단지들이 공통된 특징이 있는 것도 같았고, 마지막으로 전세가 워낙 없다보니 월세도 같이 챙겨보게 되었어용! 케빈 : 요즘처럼 전세가 없는 시장에서는 특히나 의미가 있다고 생각합니다 ~ 월세도 어쨌든 그 아파트에 거주하고 싶은 수요니까요 :) | G23: 요부분도 많이 어려워하시는거같아요~ 저는 전세월세는 결국 실거주자들의 실제선호도라 생각이 들었어요~ 요즘 전세가 귀해서 거래도 많이 안되어서 월세까지 더블체크하면서 보라는 의미로 이해됩니다 . 결국 중요한건 사람들이 좋아하는 선호도, 단지를 그럼에도 들어와서 거주하고싶은지! 본질을 생각해보면 좋을거같아요~ (근데 좀 구축에 비선호단지 소형 이런게 월세가많긴하더라고요) 맞아요, 그런곳일수록 소득수준이 낮은사람이 많이 살아서 그럴수있어요~
B24: 22 | C24: 그늘 | D24: 지방투자할 때 조심하라는 이야기하면서 항상 저가치 물건이 있다는 말을 강의에서 들었는데요. 임장하고 이야기하면서 계속 투자 못할 물건은 없다는 말과 상충되는 것 같아 튜터님과 함께 생각을 정리하고 넘어가고 싶습니다. 예를 들어 외곽 구축이나 준구축들은 저는 저가치라고 판단하고 있거든요. 이게 투자 뒷단에라도 있는걸까요? 투자하면 잃을 수 있는 저가치라고 보시나요? | E24: 저는 지방에서는 저가치 물건을 투자하면 위험하니까 보수적으로 보는 게 맞다고 생각합니다. 물론 뭐든 이건 투자할 건 아니니까 하는 마인드는 옳지 않지만요. | F24: 가히 : 예전에 인턴 튜터님이 지방에서 연식이 너무 빠지는 건 배제한다고 하셨던 말씀이 기억나는데, 지방에서는 그게 저가치가 아닌가 싶습니다. (정확한 숫자는 찾아봐야하겠지만, 예를 들어 광역시는 25년 이상, 중소도시는 15년 이상 넘은 단지는 투자 범위에서 제외 등으로) 실제로 입지가 정말 탄탄하다면 연식을 뛰어넘기도 하지만 (e.g. 크로바), 지방에서는 그런 곳이 매우 한정적이다보니 그렇게 말씀해주셨다고 생각했어요. 잔쟈니님 교안에서처럼 지방에서는 아파트의 가치에 입지보다 상품성 비중이 높은 경우가 많다보니, 입지도 별론데 상품성(=연식)마저 너무 빠지면 저가치로 보고 저는 투자범위에서 아예 배제할 것 같습니다. (주공2단지, 삼정하이츠 등) 케빈 : 전에 빈쓰튜터님 강의에서 저가치 아파트라고 해서 무조건 가격이 떨어지는 것은 아니라고 하더라고요. 물론 저가치 아파트로도 돈을 벌 수 있지만(투자할 수 있지만) 우리는 동일한 기회비용으로 최선의 선택을 해야하기에 가치비교를 하는 것이라 생각합니다 ~ | G24: 저는 일단 내가 경험이 적고, 아직 실력을 쌓아가는 단계라면 모든단지에 투자할수있고 우선순위의 개념으로 갖고 단지를 바라봐주셨으면 좋겠어요 이유는, 편견혹은 습관적으로 정말 투자할수있는 기회를 스스로 놓칠수있기 때문입니다 그러고 이제 경험이나 실력이 어느정도 쌓여서 나만의 생각이 생긴다면, 말씀처럼 저가치를 바라보고 이정도 투자단지는 하지않는다는 투자마지노선을 정할거같아요 강의에서는 혹여 기초반 수강생분들이 코칭도없이 덜컥 사실까봐, 어느정도의 가이드를 드리면서 저가치를 말씀드렸다고 생각됩니다 우리는 배운 투자자이니까, 우선순위만 있을뿐 투자못할 단지는 없다고 모든단지를 바라보고 실력을 쌓으면 좋겠습니다 💛 우리 뽀버즈는 배운대로 행동하면 가치를 잘 아는 투자자가 되실거에요 💛
B25: 23 | C25: 그늘 | D25: 진담튜터님 단지분석중인데요. 단지중 20평대나 30평초반이 주력인 단지들이 꽤 있어서요. 84가 없거나, 몇 세대 안되거나 그런 경우가 있었어요. 처음엔 84기준으로 잡고 해야지 생각했는데, 계속 그런 단지들이 나오니까 고민스럽더라고요. 그래서 단지에서 세대수가 가장 많은 대표 평형으로 해보고 있는데요. 그러니까 또 비교가 어려우려나 싶어 고민스럽습니다. 튜터님의 의견이 궁금합니다. | F25: 가히 : 저도 그런 단지는 세대수가 가장 많은 평형을 대표로 보는데, 삼코 같은 특수한 경우를 제외하고는 같은 평형끼리 비교해볼 것 같아요!! (59는 59끼리, 74는 74끼리) 대신 입지 가치가 달라서 가격대가 같다면 **어렵겠지만** 함께 비교해볼 것 같습니다. (e.g. 4억대 59 vs 4억대 84) 케빈 : 저도 그늘님처럼 비교하고 있습니다 ㅎㅎ | G25: 평형이 섞이면 아무래도 비교평가할때 어려우실거같아요 저는 84, 59, 낀평형 3가지로 나눠서 분류해서 보았어요 물건대 물건을 비교할때는 요렇게 평형을 맞춰서 골라보시면 좋을거같아요 단 생활권 단지분석을 하시면서 생활권별 가격결정요소, 단지의 선호도 상중하를 체크하고 계시죠~ 그 장표에서 평형을 지우고 어떤단지가 가격결정요소와 선호요소를 많이 갖고있는지 우선으로 생각해보시고 그 다음에 평형대 평형을 붙이면서 비교해보시면 우선순위가 더 쉽게 정리될거같아요 평형을 지우고 가치대 가치로보는게 어려운 비교평가가 맞아요 ㅜㅜ 최대한 맞출수있게 비교하고, 앞단에 생활권우선순위와 생활권내에서 단지 선호도가 정리되어있으면 조금더 수월하실거같습니다
B26: 24 | C26: 학생 | D26: 진담님의 4분할 단지분석을 진행하면서 눈에 띄게 이 단지가 이 단지보다 좋은 것을 많이 가졌구나를 알 수 있었습니다. 이 4분할 단지분석을 수도권에 적용하려면 기존에 위치/연식, 학군, 환경, 단지 부분을 교통, 학군, 환경, 연식? 정도로 나눠서 적용해도 될까요? | E26: 수도권 임보에 적용할 때는 상품성보다는 입지가 중요하니 교통, 학군, 환경 정도가 제일 중요하고 연식은 제일 후순위일것 같습니다 | F26: 가히 : 저는 수도권에서도 연식은 중요하다고 생각합니다!! ㅋㅋ 대신 강남 접근성이라는 위치 가치가 워낙 압도적으로 중요하다보니 교통의 비중을 더 높이되, 연식을 굳이 후순위로 둘 것 같진 않아용.. 강남구보다 서초구 평단가가 높은 이유는 온전히 연식 덕분인 것처럼요..? 케빈 : 교통, 학군, 환경, 강남직선거리(한강 직선거리) 요 정도이지 않을까요 ㅎㅎ | G26: 입지요소에 대한 질문이네요! 수도권과 지방에서는 어떻게 다르게봐야하는지 질문주셨어요~ 너무 좋은 질문입니다 현재는 위치,연식/ 학군/ 환경/ 단지 인데 여기서 위치,연식을 수도권은 교통으로 보면좋을지 질문주셨는데요~ 저는 같은 내용이라고 이해됩니다. 그래서 위치가 곧 강남까지의 거리를 볼거같아요 튜터링데이에서도 말씀드렸듯이 단지나 생활권은 단 한가지 입지요소로 선호도가 결정되지는 않아요 수도권에서도 연식이 선호요소로 작용하는 단지들이 있습니다 그래서 크게, 수도권은 교통이더 중요하고 지방은 연식이더 중요하다는 개념은 맞지만 단지분석시에 단지마다의 입지요소를 볼때는 동일하게 보셔도 됩니다! 단지분석전에 사전임장보고서에서 입지요소 결론을 내고 넘어간 상황이라 단지는 개별적으로 파악한다고 이해해주시면 더 쉽게 와닿으실거같아요~
B27: 25 | C27: 그늘 | D27: 전임이 왜 이렇게 어려운가 생각해보면, 제 생각보다 늘 시간을 훨씬 많이 잡아먹는 느낌입니다. 어느 단지를 할지 보고, 또 찾고, 전화하고, 정리하는데 시간을 너무 많이 쓰는데요. 튜터님만의 전임 방식, 가볍게 접근할 수 있는 방법 같은 게 있으실까요? | F27: 로에 - 그늘님 질문에 너무 공감합니다. 막상 전화하면 떨리지는 않는데 내가 이 단지를 잘 알고 있어야 사장님과 말을 이어갈 수 있다고 생각해서 사전 준비 시간이 오래걸리는 것 같아요ㅜㅜ(+마음의 준비 시간 포함) 저도 튜터님만의 전임 방법이 궁금합니다 ㅎㅎ 케빈 - 저는 전임을 '갯수 채우려고 하다보면' 하기가 싫더라고요. 이걸 또 공유하고 시트만들어야하고.. 저는 이런 벽이 있어서 그냥 길 걷다가, 임장하다가 사장님한테 편하게 물어보고 기록 안 하고 끊어보자 라는 마음으로 하기도 합니다. 개수에 연연하지 않고요 ㅎㅎ 그럼 더 전임다운 전임을 할 수 있더라고요 그렇게 좌르르 하고 지도위에 올려봅니다 ~ | G27: 여러분 전화임장에대한 벽 아직 조금씩은 있으시죠~? 전임 준비 다들 얼마나 걸리세요~? 전임준비 너무 힘드셨을거같아요 ㅜㅜ 여러분 그럼 준비가 오래걸리시는데 전임의 목적은 어떤걸까요~? 왜 하는걸까요~? 전화임장을 잘하게되는 비법이있어요 여러분이 오래걸리고 부대끼는 이유를 생각해보면한번의 통화에 많은걸 얻으려고 노력하셔서 그렇다고 생각되어요 그럴려면내가 시세도 알아야하고 가격도 잘알아야하고 부사님이 질문주시면 대답도 해야할거같은데 임장온거 들키면 곤란한데 준비를 엄청하시다가 에너지를다 써버리는경험 저도 많이했었어요 저는 어떻게 하는지 알려드릴게요 일단 전화임장의 목적은 한번의 통화로 많은걸 알아내는게아니라 일잘러 부사님, 친절한 부사님을 찾으려고 전화합니다 저는 틈새시간에 전임을해요 예를들면 저녁주문하고 음식나오기전에 나가서 한통하고옵니다 5~10분정도요 먼저 부동산에서 전화걸 매물이랑 부사님 캡쳐를해요 그럼 이미지 2장이죠? 요거 나에게 카톡보내기하고 전화겁니다 사장님 00동 00호 보고 전화드려요 요거 물건 있나요~ 나갔나요~ 상태는, 날짜는, 매도사유는 등등 물건에대한거만 물어보면서 우리가 사장님을 면접본다고 생각해보세요 그러고 네 사장님~ 제가 더 알아보고 다시전화드릴게요~ 하고 짧게 메모합니다 특징을 그다음보내놓고 나중에 그 단지 매물임장갈때 제일 친절하고 일잘하는분에게 예약을잡아요 저는그러고 현장에가서 물건에대한걸 많이 여쭤봐요 단지대단지 질문이나 가치질문은 직접얼굴뵙고 물건보면서 선호도,가치를 파악합니다 이렇게하면 기록 이랑 목적까지 달성했죠? 여러분 전임기록 길게주시는거 잘보고있어요. 아마 하시면서 스스로 정리도 많이되고 다른분들에게도 나눠주실거에요 실제 톡방에서 캡쳐2장- 짧은코멘트로 릴레이남기시고 전임시트에 기록잘 챙겨주셔도됩니다 그 벽을 낮추고 빈도를 높이시는게 훨씬 도움될거에요 (질문은 보통 한 전화에 몇개정도 하시나요?） 저는 몇개를 정하지는않고, 물건 상태나 날짜 조건위주로 여쭤보고 파악이되면 통화를 끝냅니다 또 여기서팁은 일부러 전화로 질문하려고 붙잡고 늘어지지않아요! （가히 : 주인분 거주하시나요? 부사님 : 글쎄 나야 모르지???? 가히 : 아.. 네!~~ 감사합니다~~~）이렇게 말씀하시면 면접탈락이잖아요? 네 사장님~ 감사합니다~ 하고 통화 빠르 게 끊으세요 그리고 공유해주세요 여러분 임장보고서에 시세 그룹핑 하셨죠 예를들어 실거주자들이 내가 매물임장간 단지랑 같이보는단지가 있다면 혹은 투자자입장에서 비슷한투자금 단지가 있죠 저는 매물임장가서 시세그룹핑 보고 질문 많이드려요 사장님 a단지랑 b단지랑 같은조건이면 어디가 전세 더 먼저 나가요 사장님 사실 b단지도 투자금 비슷해서 같이보고있는데, 어디가 먼저 전세빠져요? 그렇다면 전임으로 친절한 부사님찾기를 먼저 해서 친절한 부사님께 매물잡으면 됩니다! 킥은 실제 투자자들 혹은 실거주자들이 많이 비교하는 비슷한 선호도의 단지를 같이 물어보는거에요 그럼 a단지가서는 b단지의 단점을, b단지에서는 a단지의 단점을 말해주실거에요 ㅎㅎㅎ 전누잘!전누잘!전누잘! 전화임장 장표 최상단에 투자자비선호 부사님 칸 만들고 취합하고 피하시면 좋을거같아요~
B28: 26 | C28: 가히 | D28: 튜터님 MBTI가 궁금합니다!!!!!! | E28: E.. S..TP?!! ESTJ ??! | F28: 학생) ENTJ 라니) 그렇게 생각하는 이유는?!ㅋㅋㅋ
B29: 27 | C29: MZ | D29: 매임할때 선호도 파악은 30평대 위주로 맞춰서 하는게 좋을 거 같은데 실제로 투자로 접근하고 싶은 단지들은 20평대도 많아서 어떻게 자연스럽게 30평대도 보고 20평대도 볼 수 있을지 궁금합니다! | E29: a. 이번 부동산에서는 30평대만 잡고 다른 부동산에서 20평대를 잡아서 보기 b. 30평대 잡으면서 좀 소액으로 할만한것도 보고있는데 20평대도 보여달라고 해서 보기 이렇게 두 가지 방법을 생각해보았는데 어떤 식으로 보고 계신지 궁금합니다. | F29: 학생) 사장님 제가 30평대 투자하고 나서 돈 남으면 20평대도 하려고 하는데 같이 보여주세요 가히 : 기왕이면 84 하고 싶은데 59가 가격이 너무 좋은 것 같아요. 사장님 생각은 어떠세요? (사장님 의견 줄줄줄) 그러면 사장님, 59도 같이 볼 수 있을까요? 봐야 알 것 같아요.
B30: 28 | C30: 학생 | D30: 전세가 낮게 깔린 기존 계약에서 세입자에게 n천만원 높인 금액으로 신규계약하되, 2년치 이자를 선지급한다는 조건으로 계약을 진행한다면 만약 2천만원 올린금액일 때 2천만원에 대해 2년동안 현재 금리로 나눈 금액을 바로 제공하는 걸까요? | E30: 2천만원에 2년치 4% 금리로 했을때 대략 160만원이고, 이걸 기존 세입자에게 지급하면 된다고 생각하는데 이게 아니라면 세입자가 전세대출 받은 총액의 2년치 이자일지 잘 모르겠습니다 | F30: 케빈 : 학생님 정확하십니다 라니 : 학생님 세입자가 전세대출 받은 총액의 2년치 이사를 줄 필요는 없어요~ 우리가 왜 이렇게 하는지 생각해 보면 답이 나올거 같아요. 보통 세입자가 가져오는 전세 대출의 이자는 투자자가 받는 신용대출보다 금리가 더 낮아요. 그러면 투자자 입장에서는 세입자가 더 높은 전세금을 은행으로 레버리지 받아서 가져오는게 더 좋은거죠~ 이 플랜은 현재 전세가 없는 시장에서 통할수 있는 전략인 것 같아요 (울산,부산) 대전같은 경우 곧있음 공급이 많고 대체할 수 있는 전세가 대전 동구보다 더 상급지에 있기 때문에 이 전략보다는 당장 투자금이 더 들더라도 전세를 빨리 빼는 플랜이 더 나아보입니다 :)
B31: 29 | C31: 라니 | D31: 튜터님 1주차 매임이 끝났습니다. 학생님이랑도 매임을 하면서 이야기 했는데 이미 좋은 생활권과 단지는 정해져 있는듯한 느낌이 자꾸 듭니다 ㅎㅎ(같은 돈이면 신흥sk뷰로 결론이 감) 튜터님은 이럴 때 어떻게 생각하실지 궁금합니다. | E31: 제대로 보고있는건 맞는것 같은데 자꾸 신흥sk로 결론이 맺어집니다 (이러다 우리 다 똑같은 단지 뽑아오는거 아닐까요 ㅎㅎ)
B32: 30
B33: 31
B34: 32
B35: 33
B36: 34
B37: 35
B38: 36
B39: 37
B40: 38
...

Sheet Step2. 우리의 임장 계획
I1: 사임제출 | K1: 튜터링데이 | Q1: 중임제출 | Y1: 최임제출 | AA1: 최종 모임
B2: 닉네임 | C2: 구분 | D2: 토(SAT) | E2: 일(SUN) | F2: 월(MON) | G2: 화(TUE) | H2: 수(WEN) | I2: 목(THU) | J2: 금(FRI) | K2: 토(SAT) | L2: 일(SUN) | M2: 월(MON) | N2: 화(TUE) | O2: 수(WEN) | P2: 목(THU) | Q2: 금(FRI) | R2: 토(SAT) | S2: 일(SUN) | T2: 월(MON) | U2: 화(TUE) | V2: 수(WEN) | W2: 목(THU) | X2: 금(FRI) | Y2: 토(SAT) | Z2: 일(SUN) | AA2: 월(MON) | AB2: 화(TUE) | AC2: 수(WEN) | AD2: 목(THU) | AE2: 금(FRI) | AF2: 토(SAT) | AG2: 일(SUN) | AH2: 월(MON) | AI2: 화(TUE) | AJ2: 수(WEN) | AK2: 목(THU) | AL2: 금(FRI)
D3: 46116 | E3: 46117 | F3: 46118 | G3: 46119 | H3: 46120 | I3: 46121 | J3: 46122 | K3: 46123 | L3: 46124 | M3: 46125 | N3: 46126 | O3: 46127 | P3: 46128 | Q3: 46129 | R3: 46130 | S3: 46131 | T3: 46132 | U3: 46133 | V3: 46134 | W3: 46135 | X3: 46136 | Y3: 46137 | Z3: 46138 | AA3: 46139 | AB3: 46140 | AC3: 46141 | AD3: 46142 | AE3: 46143 | AF3: 46144 | AG3: 46145 | AH3: 46146 | AI3: 46147 | AJ3: 46148 | AK3: 46149 | AL3: 46150
B4: ='Step1-1. 서로를 알아보아요'!D2 -> 가히dasikeum | C4: 계획 | D4: 분임 | E4: 단임1 | K4: 튜데 | L4: X | R4: 매임1 | S4: 단임2 | X4: 매임2 | Y4: 매임3
C5: 도착/출발시간 | D5: 08:03 서대전 | E5: 미정 | K5: 08:03 서대전 19:37 대전역 | R5: 09:34 대전역 도착 | S5: 출발시간 미정 | X5: 대전역 09:02 | Y5: 08:07 대전역
C6: 숙박여부 | D6: O | E6: X | K6: X | R6: O | S6: X | Y6: X
B7: ='Step1-1. 서로를 알아보아요'!E2 -> 라니 | C7: 계획 | D7: 분임 | E7: 단임 | K7: 튜데 | L7: 필요시 | R7: 매임 | Y7: 매임
C8: 도착/출발시간 | D8: 08:03 서대전 | K8: 08:00 대전역 | R8: 9시 대전역 | Y8: 9시 대전역
C9: 숙박여부 | D9: X | K9: X | R9: X | Y9: X
B10: ='Step1-1. 서로를 알아보아요'!F2 -> 야자수그늘 | C10: 계획 | D10: 분임 | E10: 단임 | K10: 튜데 | L10: O | R10: 매임 | S10: X | Y10: 매임
C11: 도착/출발시간 | R11: 대전역9시22분
C12: 숙박여부 | D12: O | K12: O | R12: O | Y12: X
B13: ='Step1-1. 서로를 알아보아요'!G2 -> 케빈D | C13: 계획 | D13: 분임 | E13: 단임 | K13: 튜데 | L13: X | R13: 매임 | Y13: 매임
C14: 도착/출발시간
C15: 숙박여부 | D15: O
B16: ='Step1-1. 서로를 알아보아요'!H2 -> 굿데이3 | C16: 계획 | D16: 분임 | E16: 단임 | K16: 튜데 | L16: 단임 | R16: 매임 | Y16: 매임
C17: 도착/출발시간 | D17: 08:03 서대전 | K17: 08:03 서대전
C18: 숙박여부 | D18: X | K18: O
B19: ='Step1-1. 서로를 알아보아요'!I2 -> 아르떼 | C19: 계획
C20: 도착/출발시간
C21: 숙박여부
B22: ='Step1-1. 서로를 알아보아요'!J2 -> MZ | C22: 계획 | D22: 분임 | E22: 단임 | K22: 튜데 | L22: o | R22: 매임0.5 | S22: X | X22: 매임 1.5 | Y22: x | Z22: X
C23: 도착/출발시간 | R23: 대전역 15:03 | X23: 대전역 09:02
C24: 숙박여부 | D24: ? | R24: X | Y24: X
B25: ='Step1-1. 서로를 알아보아요'!K2 -> 학생 | C25: 계획 | D25: 분임 | E25: 단임 | R25: 매임
C26: 도착/출발시간 | K26: 튜데 | L26: O | R26: 8시 서대전
C27: 숙박여부 | D27: O
B28: ='Step1-1. 서로를 알아보아요'!L2 -> 로에 | C28: 계획 | D28: 분임 | E28: 단임 | K28: 튜데 | L28: O | R28: 매임 | Y28: 매임
C29: 도착/출발시간 | D29: 15:48 도착 | K29: 08:03 서대전 | R29: 08:47 대전
C30: 숙박여부 | D30: O | K30: O | R30: X | Y30: X
C31: 강의
B32: 분임 | C32: 튜터링데이
B33: 단임 | C33: 사임제출
B34: 매임 | C34: 최임제출

Sheet 매임예약
B2: 날짜 | C2: 4/18 (토) | I2: 날짜 | J2: 4/18 (토) | P2: 날짜 | Q2: 4/18 (토) | W2: 날짜 | X2: 4/18 (토) | AD2: 날짜 | AE2: 4/18 (토)
B3: 팀 | C3: 가히/르떼 | I3: 팀 | J3: 케빈/로에 | P3: 팀 | Q3: 데이/그늘 | W3: 팀 | X3: 라니/학생 | AD3: 팀 | AE3: MZ
B4: 구분 | D4: 단지명 | E4: 상세 예약 정보 | F4: 노트 | G4: 예약 확정 | I4: 구분 | K4: 단지명 | L4: 상세 예약 정보 | M4: 가서 사장님께 여쭤볼것 | N4: 예약 확정 | P4: 구분 | R4: 단지명 | S4: 상세 예약 정보 | T4: 가서 사장님께 여쭤볼것 | U4: 예약 확정 | W4: 구분 | Y4: 단지명 | Z4: 상세 예약 정보 | AA4: 가서 사장님께 여쭤볼것 | AB4: 예약 확정 | AD4: 구분 | AF4: 단지명 | AG4: 상세 예약 정보 | AH4: 가서 사장님께 여쭤볼것 | AI4: 예약 확정
B5: 시간 | C5: 10:00~11:30 | D5: SK뷰 리더스시티 | E5: [SK뷰] 112-304 (59b) 3.8/2.7 110-2504 (59b) 4.1/3.0 (조합원/뷰굿) 111-3101 (59a) 4.15 106-701 (59a) 4.1 111-903 (59a) 4.02 [리더스] 401-601(74b) 4.75 405-704(74a) 4.70 407-18층 (74b) 4.65 (무옵션, 에어컨값 협의 가능) | F5: SK뷰 112-304 지하주차장에서 만나용 SK뷰 a/b 선호 비슷, 리더스 A 선호 | G5: O | I5: 시간 | J5: 10:00~11:00 | K5: 한밭자이 | L5: 104-2503 3.5억 (~27.2 주전가능) 107-1402 3.6억 112-1901 3.6억 | N5: O | P5: 시간 | Q5: 08:30~ | R5: 이스트1단지 | S5: 24평 107동 고층 3억7천(27/2월 만기) | U5: O | W5: 시간 | X5: 10:00~11:00 | Y5: 삼정그린코아1 | AB5: O | AD5: 시간 | AE5: 16:00-17:00 | AF5: 신흥SK뷰 | AG5: [1] 104동-5층 전세입자 거주 4.1(4.0) / 3.0 전세만기 올해 6월 -> 지금 내면 전세 맞출 수 있을듯 [2] 111동-31층 4.15 / 전세입자 거주 전세만기 올해 5월 -> 잔금 3개월로 하고 2달은 매도인부담? | AH5: 30평대와 20평대의 수요 차이 가족단위 많이 살 거 같은데 내부 20평>30평으로 이동 수요? | AI5: O
B6: 예약자 | C6: 가히 | I6: 예약자 | J6: 로에 | P6: 예약자 | Q6: 그늘 | S6: 30평 112동 4층 4억7천(27년 3월 만기) | W6: 예약자 | X6: 라니 | AD6: 예약자 | AE6: MZ
B7: 부동산명 | C7: 리더스시티대표 | I7: 부동산명 | J7: 엘지공인 | P7: 부동산명 | Q7: 이스트사랑 | S7: 34평 102동 404호 4억9,500(27년 7월 만기),104동 14층 5억5천(27월 2월 이후 아무때나) | W7: 부동산명 | X7: 010-5388-8266 | AD7: 부동산명 | AE7: 대동이스트OK
B8: 부동산연락처 | C8: 010-4488-2820 | I8: 부동산연락처 | J8: 010-5450-3301 | P8: 부동산연락처 | S8: 110동 30평 4.5억 (2시 20분) | W8: 부동산연락처 | X8: 삼정코아행복공인중개 | AD8: 부동산연락처 | AE8: 010-7547-3636
B9: 시간 | G9: O | I9: 시간 | J9: 11:00~12:30 | K9: 효촌마을 스마트뷰 | L9: 효촌마을 스마트뷰 106동 고층 3.3억(27.11만기(2.75억)) - 세입자 연락가디리는 중 | N9: O | P9: 시간 | Q9: 11:00~ | R9: 신흥SK 뷰 | S9: 108-23층 74 5.0억 협의입주 103-12층 84 5.7억 103-19층 84 5.8(공실) 111고층 74 전세승계 5.05억(*계속거주원함)(1시) 107-25층 84 5.9억(1시15분) | U9: O | W9: 시간 | X9: 11:30~12:30 | Y9: e편한에코포레 | Z9: 학생,라니 각각 금요일 확인후 피드백 | AB9: O | AD9: 시간 | AF9: 이스트시티1단지 | AG9: 3.7 / 2.4 [1.5] 27.01 만기라 잘 안보여줌 최근 4억 실거래라 이거 진짜 싼거임. 다른 나갈 물건임. 같은동 같은라인 공실로 | AH9: 신흥Sk뷰와 비교해서는 여기는 어떰? 그냥 가성비 단지임? 아니면 여기 고수하는 분이 계심? | AI9: O
B10: 예약자 | I10: 예약자 | J10: 로에 | P10: 예약자 | Q10: 그늘 | W10: 예약자 | X10: 학생 | AD10: 예약자
B11: 부동산명 | I11: 부동산명 | J11: 둥지공인 | P11: 부동산명 | Q11: 이스트박사 | W11: 부동산명 | AD11: 부동산명
B12: 부동산연락처 | I12: 부동산연락처 | J12: 010-8321-6833 | P12: 부동산연락처 | Q12: 010-6371-5951 | W12: 부동산연락처 | AD12: 부동산연락처
B13: 시간 | C13: 12:15~13:00 | D13: 이스트시티 | E13: 5개 | F13: 협조적이심. | I13: 시간 | J13: 13:00~14:30 | K13: 힐스테이트 가양더와이즈 | L13: 102동 41층 4.9억 외 투자매물 추려서 준비해주신다함 굿굿 | N13: O | P13: 시간 | Q13: 13:30~ | R13: 휴먼시아1단지+ 이스트2단지 | S13: 새들뫼 110 중층 4.3억 이스트 201/고층 4.3억 | U13: O | W13: 시간 | X13: 0.5625 | Y13: 새들뫼,펜타뷰 | AB13: 일단 오세요 | AD13: 시간 | AE13: 18:00-19:00 | AF13: 리더스시티4BL / 5BL | AG13: [1] 4BL 30A형 - 7층 주인거주 - 2년채워야 해서 26.08까지 기달 3.2 [2] 4BL 30B형 - 18층 18층이어도 B보다 A가 구조가 더 좋고 조망이 좋아서 (18층은 뭔가 막혀있어서) [1]번 매물 더 추천. B형이 500 더 싸게 감 | AH13: 4BL A타입이 구조 더 좋고 7층이어도 18층B형보다 조망 좋다는데 확인해볼 것. | AI13: O
B14: 예약자 | C14: 라떼 | I14: 예약자 | J14: 로에 | P14: 예약자 | Q14: 그늘 | W14: 예약자 | X14: 라니 (투넘버) | AD14: 예약자 | AE14: MZ
B15: 부동산명 | C15: 이스트시티공인 | I15: 부동산명 | J15: 착한공인 | P15: 부동산명 | Q15: 새들뫼공인중개 | W15: 부동산명 | X15: 펜타뷰114 | AD15: 부동산명
B16: 부동산연락처 | C16: 010-7477-0355 | I16: 부동산연락처 | J16: 010-5421-6101 | P16: 부동산연락처 | Q16: 010-3270-6200 | W16: 부동산연락처 | X16: 010-5345-3160 | AD16: 부동산연락처
B17: 시간 | C17: 13:00~14:00 | D17: 새들뫼 | E17: 집주인새들뫼휴먼시아1단지 102동 매매4억 3,000 아파트112C-/84m², 26/26층, 남동향 다들 집만 보고 가서 안사니깐 안보여줄려고 하심. ㅠㅠ | F17: 중간? 좀 껄끄러워하심. | I17: 시간 | J17: 15:30~17:00 | K17: 꿈에그린 용방마을 | L17: 꿈그 106동 5층 2.6억 (기본, 깔끔) 용방 303동 8층 2.35억 (수리 x) 용방 2.5억 (수리O, 도배는 필요할 수도) | M17: 어디로 이사 많이 가나요 | N17: O | P17: 시간 | Q17: 15:00~16:00 | R17: 리더스시티4단지 & 5단지 | S17: 1. 2, 3. 4. 5. | U17: O | W17: 시간 | X17: 0.625 | Y17: 이스트1 | Z17: *이스트시티84타입 정리* 1.104-1404호 2.103 동 고층 주인전세 가능한 매물 3.102-404호 매:4.95억 기전세금3억 27년7월초 아침 9시30분 볼수 있음 그래서 볼수는 없음 30평:111동1401호 26평:108동26층 방문약속했어요 이스트는 이렇게 보여준다고 | AB17: O | AD17: 시간
B18: 예약자 | C18: 라떼 | I18: 예약자 | J18: 케빈 | P18: 예약자 | Q18: 데이 | W18: 예약자 | X18: 학생 | AD18: 예약자
B19: 부동산명 | C19: 새들뫼사랑공인 | I19: 부동산명 | J19: 열린 | P19: 부동산명 | Q19: 리더스시티공인 | W19: 부동산명 | AD19: 부동산명
B20: 부동산연락처 | C20: 010-3063-3670 | I20: 부동산연락처 | J20: 010-7275-1941 | P20: 부동산연락처 | Q20: 010-6759-9050 | W20: 부동산연락처 | AD20: 부동산연락처
B21: 시간 | C21: 14:00~15:00 | D21: 어진마을 신흥마을 | E21: 정리타임 및 식사 >>> 누구 맘대로요????????? ♡^.^♡ >>> 정리는 이동 중에 ~~~ *^.^* 어진 vs 신흥 비교 | F21: 부사님 사무실 2시 | G21: O | I21: 시간 | J21: 17:00~18:30 | K21: E편한에코포레 | L21: 117동 저층(4층) 4.2억 / 3억 안고 세만기 (갱신권 완료) 103동 30층 59 / 세 안고 물건 보기 어려움 | M21: 사장님 자꾸 동시진행 안 된다고 입주물건 안 보여줌 | N21: o | P21: 시간 | Q21: 16:30~17:30 | R21: e편한세상에코포레 | S21: 1. 2, 3. 4. 5. | U21: O | W21: 시간 | X21: 0.66666667 | Y21: 위드힐 | AB21: O | AD21: 시간
B22: 예약자 | C22: 가히 | I22: 예약자 | J22: 케빈 | P22: 예약자 | Q22: 데이 | W22: 예약자 | X22: 라니 | AD22: 예약자
B23: 부동산명 | C23: 어진마을공인 | I23: 부동산명 | J23: 용운E편한 | P23: 부동산명 | Q23: 에코포레합동 (부부)에코포레공인 | W23: 부동산명 | X23: 천동공인중개사 | AD23: 부동산명
B24: 부동산연락처 | C24: 010-9784-3360 | I24: 부동산연락처 | J24: 010-3462-1291 | P24: 부동산연락처 | Q24: 010-3466-9100 | W24: 부동산연락처 | X24: 010-9429-9177 | AD24: 부동산연락처
B25: 시간 | C25: 15:00~16:00 | D25: e편한세상 에코포레 | E25: 104동 1303호 4.25 / 6월12,13일 만기 더 살길 원함 113동 2502호 4.45 / 12월 만기, 학군 땜에 | F25: 3시 104동 앞에서 | G25: O | I25: 시간 | J25: 18:30~19:30 | K25: 삼정그린코아 | L25: 105동 1403호 4.2억 31평 9층도 있는데 뷰 간섭 같은 가격이지만 덜 좋음 (이건 안 봄) 202동 905 3.6억 29평 203동 16층 3.47억 29평 둘다 팔아야 함 | M25: 사장님 꼬치꼬치 캐물어보셔서 여자친구랑 간다함 | N25: o | P25: 시간 | Q25: 18:00~19:00 | R25: 판암삼정그린코아 1,2단지 | S25: 1. 2, 3. 4. 5. 6. 7. | U25: O | W25: 시간 | X25: 0.70833333 | Y25: 리더스45 74 SK뷰 59 | Z25: 리더스4 59 최근거래되서 전세놓을수있는물건이 없다 | AB25: O | AD25: 시간
B26: 예약자 | C26: 가히 | I26: 예약자 | J26: 케빈 | P26: 예약자 | Q26: 데이 | W26: 예약자 | X26: 라니 | AD26: 예약자
B27: 부동산명 | C27: 대청부동산 | I27: 부동산명 | J27: 삼정코아행복 | P27: 부동산명 | Q27: 삼정코아행복공인 | W27: 부동산명 | X27: 부동산이즈리더스 | AD27: 부동산명
B28: 부동산연락처 | C28: 010-7444-1130 | I28: 부동산연락처 | J28: 010-5388-8266 | P28: 부동산연락처 | Q28: 010-5388-8266 | W28: 부동산연락처 | X28: 010-4488-2820 | AD28: 부동산연락처
B29: 시간 | C29: 16:00~17:00 | D29: 삼정그린코아 1단지 | E29: 29평/ 104-1903 (RR) - 4.0 28평/ 113-1403 - 3.7 (조정 가능) 24평/ 113-301 - 3.4/2.5 (27.10 만기) | F29: 부동산 사무실 4시 | G29: O | I29: 시간 | P29: 시간 | W29: 시간 | X29: 0.75 | Y29: 은어송코로오하늘채12 은어송하늘채리버뷰 | Z29: 학생님 리더스 시간 확인하고 예약 할게요 | AD29: 시간
B30: 예약자 | C30: 가히 | I30: 예약자 | P30: 예약자 | W30: 예약자 | AD30: 예약자
B31: 부동산명 | C31: 복돼지부동산 | I31: 부동산명 | P31: 부동산명 | W31: 부동산명 | AD31: 부동산명
B32: 부동산연락처 | C32: 010-6330-3993 | I32: 부동산연락처 | P32: 부동산연락처 | W32: 부동산연락처 | AD32: 부동산연락처
B33: 시간 | C33: 17:30~18:30 | D33: 은어송 하늘채리버뷰 (24년식) | E33: 102동 4.85 천변뷰 + 물건 2개 더 | F33: 리버뷰공인중개사사무소 | G33: O | I33: 시간 | P33: 시간 | W33: 시간 | AD33: 시간
B34: 예약자 | C34: 라떼 | I34: 예약자 | P34: 예약자 | W34: 예약자 | AD34: 예약자
B35: 부동산명 | C35: 리버뷰공인 | I35: 부동산명 | P35: 부동산명 | W35: 부동산명 | AD35: 부동산명
B36: 부동산연락처 | C36: 010-3460-6176 | I36: 부동산연락처 | P36: 부동산연락처 | W36: 부동산연락처 | AD36: 부동산연락처
B37: 시간 | C37: 18:30~19:30 | D37: 은어송2단지 코오롱하늘채07 | E37: 기존 예약 취소 → 당일예약 | G37: O | I37: 시간 | P37: 시간 | W37: 시간 | AD37: 시간
B38: 예약자 | C38: 가히 | I38: 예약자 | P38: 예약자 | W38: 예약자 | AD38: 예약자
B39: 부동산명 | I39: 부동산명 | P39: 부동산명 | W39: 부동산명 | AD39: 부동산명
B40: 부동산연락처 | C40: 9731-4500 | I40: 부동산연락처 | P40: 부동산연락처 | W40: 부동산연락처 | AD40: 부동산연락처
B41: 시간 | I41: 시간 | P41: 시간 | W41: 시간 | AD41: 시간
...

Sheet Step3-1. 아맞다 전화임장!
B1: 목표 | C1: 100 | D1: 달성률
B2: 실적 | C2: =COUNTA(C7:C1006) -> 104 | D2: =C2/C1 -> 1.04
F3: 부동산 정보 | J3: 아파트 정보 | N3: 매물 정보
B4: 순번 | C4: 닉네임 | D4: 일자 | E4: 요일 | F4: 부동산명 | G4: 전화번호 | H4: 매매 매물수 | I4: 전세 매물수 | J4: 단지명 | K4: 입주시기 | L4: 세대수 | M4: 연식 | N4: 동/층/향 | O4: 공급평형 | P4: 매매가 | Q4: 전세가 | R4: 매전차 | S4: 평단가 | T4: 전세가율 | U4: 특이사항/전임내용 | V4: 부동산 평가 | W4: 얻은 정보/내생각 | X4: 공유용 양식 (자동 완성) | AA4: 우리 조 총 실적 | AB4: =sum(AB6:AB14) -> 104 | AC4: =IF(AB4=C2,"","check")
B5: 예시 | C5: OOO | D5: 2024.01.01. | E5: 일 | F5: 금나무공인중개사사무소 | G5: 02-592-5600,010-2858-1475 | H5: 17 | I5: 32 | J5: 래미안원베일리 | K5: 2023.08 | L5: 2990 | M5: =year(today())-K5+1 -> 3.92 | N5: 116동 14층 남향 | O5: 24 | P5: 270000 | Q5: 120000 | R5: =P5-Q5 -> 150000 | S5: =P5/O5 -> 11250 | T5: =Q5/P5 -> 0.44444444 | U5: 첫입주, 풀옵션. 24년 2월 28일 협의. | V5: 친절하고 투자물건에 대해 잘 앎. | Z5: 닉네임 | AA5: 이번달 목표 | AB5: 실적 | AC5: 달성률
B6: 1 | C6: 루시퍼홍#1 | D6: 2026.02.02 | E6: 월 | F6: 왜이제왔어공인 | G6: 02-1234-5678 | H6: 70 | I6: 14 | J6: 🐕편한세상 | K6: 2021.12 | L6: 1000 | M6: =year(today())-K6+1 -> 5.88 | N6: 1동 7층 남향 | O6: 24 | P6: 70000 | Q6: 50000 | R6: =if(and(P6 <> "", Q6 <> ""), P6-Q6, "") -> 20000 | S6: =if(and(P6 <> "", O6 <> ""), P6/O6, "") -> 2916.6667 | T6: =if(and(Q6 <> "", P6 <> ""), Q6/P6, "") -> 0.71428571 | U6: 집주인거주. 입주일 협의. 특올수리 | V6: 엄청 친절하신 일잘러 사장님 | W6: 1단지는 지주연결이 되어 있는데 2단지는 안되어 있음. 최근 2단지가 6.9억에 거래됐고 아직 실거래는 안올라옴 | X6: =if(OR(U6 <>"", V6<>"", W6 <> ""), TEXTJOIN("", TRUE, J6, " ", K6, " ", L6, "^", char(10), F6, " ", G6, char(10), O6, "p ",N6, " ", P6, " / ", Q6 , " ", CHAR(10),CHAR(10), U6, CHAR(10),CHAR(10), "<부동산 평가>",CHAR(10),CHAR(10), V6, CHAR(10),CHAR(10), "<얻은 정보>", CHAR(10),CHAR(10),W6), "") -> 🐕편한세상 2021.12 1000^ 왜이제왔어공인 02-1234-5678 24p 1동 7층 남향 70,000 / 50,000 집주인거주. 입주일 협의. 특올수리 <부동산 평가> 엄청 친절하신 일잘러 사장님 <얻은 정보> 1단지는 지주연결이 되어 있는데 2단지는 안되어 있음. 최근 2단지가 6.9억에 거래됐고 아직 실거래는 안올라옴 | Z6: 가히 | AA6: 40 | AB6: =COUNTIF($C:$C,$Z6) -> 18 | AC6: =AB6/AA6 -> 0.45
B7: =B6+1 -> 2 | C7: 라니 | D7: 2026.04.01 | E7: 수 | F7: 태양공인중개사 | G7: 010-8631-0785 | H7: - | I7: - | J7: 이스트시티 | K7: 2018 | M7: =year(today())-K7+1 -> 9 | O7: 34 | P7: 52000 | Q7: 38000 | R7: =if(and(P7 <> "", Q7 <> ""), P7-Q7, "") -> 14000 | S7: =if(and(P7 <> "", O7 <> ""), P7/O7, "") -> 1529.4118 | T7: =if(and(Q7 <> "", P7 <> ""), Q7/P7, "") -> 0.73076923 | U7: 단지 특정하지 않고 전세 시세와 전세 매물 추천 요청 현재 전세 시세 3.8-4.0. SK 전세 3.7짜리 2개가 있는데 하나는 에어컨 있고 하나는 에어컨 없는거다. 둘다 천변 보이는쪽이 RR이고 이스트시티는 철길쪽이랑 철길 아닌쪽이랑 전세가도 차이 난다(천만원정도) 현재 전세가 많지 않다. 두개 보고 자녀있으면 이스트시티 선택하는데 SK도 104.105.106 쪽은 학교랑 가깝다 SK가 비싼 이유는 연식 때문이다. 단지가 대전역에서 걸어서 얼마걸리나? 15분 정도 걸린다. 보통 여기는 둘중에 한명이 KTX 타고 다른곳 (김천구미.동대구,서울) 이용해야 하는 사람들이 중간 합의점으로 찾는 곳이다. | V7: 친절 일잘러 | W7: 두개 선호요소가 명확하다. 이스트-초품아, SK-연식 매임으로 SK들어왔을때 주변 분위기도 물어 봐야겠다. 이스트는 철길쪽과 철길아닌쪽 전세 최근실거래좀 찾아봐야겠다. | X7: =if(OR(U7 <>"", V7<>"", W7 <> ""), TEXTJOIN("", TRUE, J7, " ", K7, " ", L7, "^", char(10), F7, " ", G7, char(10), O7, "p ",N7, " ", P7, " / ", Q7 , " ", CHAR(10),CHAR(10), U7, CHAR(10),CHAR(10), "<부동산 평가>",CHAR(10),CHAR(10), V7, CHAR(10),CHAR(10), "<얻은 정보>", CHAR(10),CHAR(10),W7), "") -> 이스트시티 2018 ^ 태양공인중개사 010-8631-0785 34p 52,000 / 38,000 단지 특정하지 않고 전세 시세와 전세 매물 추천 요청 현재 전세 시세 3.8-4.0. SK 전세 3.7짜리 2개가 있는데 하나는 에어컨 있고 하나는 에어컨 없는거다. 둘다 천변 보이는쪽이 RR이고 이스트시티는 철길쪽이랑 철길 아닌쪽이랑 전세가도 차이 난다(천만원정도) 현재 전세가 많지 않다. 두개 보고 자녀있으면 이스트시티 선택하는데 SK도 104.105.106 쪽은 학교랑 가깝다 SK가 비싼 이유는 연식 때문이다. 단지가 대전역에서 걸어서 얼마걸리나? 15분 정도 걸린다. 보통 여기는 둘중에 한명이 KTX 타고 다른곳 (김천구미.동대구,서울) 이용해야 하는 사람들이 중간 합의점으로 찾는 곳이다. <부동산 평가> 친절 일잘러 <얻은 정보> 두개 선호요소가 명확하다. 이스트-초품아, SK-연식 매임으로 SK들어왔을때 주변 분위기도 물어 봐야겠다. 이스트는 철길쪽과 철길아닌쪽 전세 최근실거래좀 찾아봐야겠다. | Z7: 그늘 | AA7: 32 | AB7: =COUNTIF($C:$C,$Z7) -> 12 | AC7: =AB7/AA7 -> 0.375
B8: =B7+1 -> 3 | C8: 그늘 | D8: 2026.4.1. | E8: 수 | F8: sk진공인중개 | G8: 010-9677-0709 | H8: 26 | I8: 0 | J8: 신흥SKVIEW | K8: 2022.04 | L8: 1588 | M8: =year(today())-K8+1 -> 4.96 | N8: 103동/고(탑층아님)/남동향 | O8: 34 | P8: 56000 | Q8: 35000 | R8: =if(and(P8 <> "", Q8 <> ""), P8-Q8, "") -> 21000 | S8: =if(and(P8 <> "", O8 <> ""), P8/O8, "") -> 1647.0588 | T8: =if(and(Q8 <> "", P8 <> ""), Q8/P8, "") -> 0.625 | U8: 투자자컨셉 현재 저층 탑층 제외 가장 저렴한 물건. 월세입자 5000/100만, 월세입자가 관리 잘했고 따로 인테리어 하신 건 없으심. 26.12.하순 월세 계약 만료(갱신X) 더 산다고 하시면 협의 해볼 물건임. 그래도 집을 보여주신다고 함. 그외 101동 15층 59000원 말씀하시는 데 더 저렴하게 할 수 있을 물건 있음. 분양받아서 주인이 가야하는 물건임. 101동은 뻥뷰. 주인거주중 조합원 세대 물건(선호) | V8: 사장님 친절 일잘러느낌 | W8: 현재 단지들에 전세가 잘 안나가고 있는 상황임. 3.5억은 생각해야 함. 3.6억 이상으로 나와있으나, 그전에도 3.3-3.5까지 나갔는데, 요즘 전세가 없다보니 살짝 높여 나왔으나 전세 찾는 손님이 없음. 주변 단지 중에서는 재개발 지역의 대장 아파트라, 가격이 빠지지 않았고 주변 LH, 여기만 브랜드라 관심이 높다. 20평대에 신혼부부들이 좋아하고, 20평대가 더 선호도가 좋다. 대동역 10분 내 도보 등으로 대전역이 가까워 젊은 사람들의 선호가 높다. 조합원 세대와 일반분양 세대가 있는데 조합원 선호가 있고, 109동이 제일 로얄동, 다음 109동이 좋고, 108, 109동은 남서향, 101동도 조합원동으로 남동향. | X8: =if(OR(U8 <>"", V8<>"", W8 <> ""), TEXTJOIN("", TRUE, J8, " ", K8, " ", L8, "^", char(10), F8, " ", G8, char(10), O8, "p ",N8, " ", P8, " / ", Q8 , " ", CHAR(10),CHAR(10), U8, CHAR(10),CHAR(10), "<부동산 평가>",CHAR(10),CHAR(10), V8, CHAR(10),CHAR(10), "<얻은 정보>", CHAR(10),CHAR(10),W8), "") -> 신흥SKVIEW 2022.04 1588^ sk진공인중개 010-9677-0709 34p 103동/고(탑층아님)/남동향 56,000 / 35,000 투자자컨셉 현재 저층 탑층 제외 가장 저렴한 물건. 월세입자 5000/100만, 월세입자가 관리 잘했고 따로 인테리어 하신 건 없으심. 26.12.하순 월세 계약 만료(갱신X) 더 산다고 하시면 협의 해볼 물건임. 그래도 집을 보여주신다고 함. 그외 101동 15층 59000원 말씀하시는 데 더 저렴하게 할 수 있을 물건 있음. 분양받아서 주인이 가야하는 물건임. 101동은 뻥뷰. 주인거주중 조합원 세대 물건(선호) <부동산 평가> 사장님 친절 일잘러느낌 <얻은 정보> 현재 단지들에 전세가 잘 안나가고 있는 상황임. 3.5억은 생각해야 함. 3.6억 이상으로 나와있으나, 그전에도 3.3-3.5까지 나갔는데, 요즘 전세가 없다보니 살짝 높여 나왔으나 전세 찾는 손님이 없음. 주변 단지 중에서는 재개발 지역의 대장 아파트라, 가격이 빠지지 않았고 주변 LH, 여기만 브랜드라 관심이 높다. 20평대에 신혼부부들이 좋아하고, 20평대가 더 선호도가 좋다. 대동역 10분 내 도보 등으로 대전역이 가까워 젊은 사람들의 선호가 높다. 조합원 세대와 일반분양 세대가 있는데 조합원 선호가 있고, 109동이 제일 로얄동, 다음 109동이 좋고, 108, 109동은 남서향, 101동도 조합원동으로 남동향. | Z8: 라니 | AA8: 40 | AB8: =COUNTIF($C:$C,$Z8) -> 19 | AC8: =AB8/AA8 -> 0.475
B9: =B8+1 -> 4 | C9: 그늘 | D9: 2026.4.1.. | E9: 수. | F9: 위드힐탑 | G9: 042-282-3349 | H9: 122 | I9: 4 | J9: 리더스시티5BL | K9: 2024.12 | L9: 2135 | M9: =year(today())-K9+1 -> 2.88 | N9: 505동/중/남동 | O9: 34 | P9: 50000 | Q9: 28000 | R9: =if(and(P9 <> "", Q9 <> ""), P9-Q9, "") -> 22000 | S9: =if(and(P9 <> "", O9 <> ""), P9/O9, "") -> 1470.5882 | T9: =if(and(Q9 <> "", P9 <> ""), Q9/P9, "") -> 0.56 | U9: 전세낀 물건, 28000에 들어있고, 내년 27년 1월 30일 만기. 집은 보여주실 수 있다고 함. 에어컨 4대 501동 로얄동 로얄층 전세 28000 물건 있으나 보여주지는 않는다고 하심. 에어컨 3대, 중문, 주방 수납 등 현재 지금 전세 받는다면 3.2억 정도에서 거래될 수 있으나, 손님이 많지는 않음. 현재 실거래가 잘 이뤄지지 않아, 거래가가 제대로 나와있지 않고, 주인분들이 원하시는 희망 호가가 올라가있는 경향이 있음. | V9: 전반적으로 묻는 질문에 답은 하시나, 적극적이진 않으심 | W9: 죄송합니다. 제대로 못물어봤네요~^^ | X9: =if(OR(U9 <>"", V9<>"", W9 <> ""), TEXTJOIN("", TRUE, J9, " ", K9, " ", L9, "^", char(10), F9, " ", G9, char(10), O9, "p ",N9, " ", P9, " / ", Q9 , " ", CHAR(10),CHAR(10), U9, CHAR(10),CHAR(10), "<부동산 평가>",CHAR(10),CHAR(10), V9, CHAR(10),CHAR(10), "<얻은 정보>", CHAR(10),CHAR(10),W9), "") -> 리더스시티5BL 2024.12 2135^ 위드힐탑 042-282-3349 34p 505동/중/남동 50,000 / 28,000 전세낀 물건, 28000에 들어있고, 내년 27년 1월 30일 만기. 집은 보여주실 수 있다고 함. 에어컨 4대 501동 로얄동 로얄층 전세 28000 물건 있으나 보여주지는 않는다고 하심. 에어컨 3대, 중문, 주방 수납 등 현재 지금 전세 받는다면 3.2억 정도에서 거래될 수 있으나, 손님이 많지는 않음. 현재 실거래가 잘 이뤄지지 않아, 거래가가 제대로 나와있지 않고, 주인분들이 원하시는 희망 호가가 올라가있는 경향이 있음. <부동산 평가> 전반적으로 묻는 질문에 답은 하시나, 적극적이진 않으심 <얻은 정보> 죄송합니다. 제대로 못물어봤네요~^^ | Z9: 케빈 | AA9: 30 | AB9: =COUNTIF($C:$C,$Z9) -> 14 | AC9: =AB9/AA9 -> 0.46666667
B10: =B9+1 -> 5 | C10: 가히 | D10: 46113 | E10: 수 | F10: SK진공인 | G10: 010-9677-0709 | H10: 26 | I10: 0 | J10: 신흥SK뷰 | K10: 2022.04 | L10: 1588 | M10: =year(today())-K10+1 -> 4.96 | N10: 103동 고/24층 남동향 | O10: 34 | P10: 56000 | Q10: 37000 | R10: =if(and(P10 <> "", Q10 <> ""), P10-Q10, "") -> 19000 | S10: =if(and(P10 <> "", O10 <> ""), P10/O10, "") -> 1647.0588 | T10: =if(and(Q10 <> "", P10 <> ""), Q10/P10, "") -> 0.66071429 | U10: [매물 정보] - 103동 고/24층 남동향 : 5.6억 - 102, 103동은 조망이 살짝 막힘 (특히 남동), 101동이 앞동에 남서향이 전망 좋은 편인데 5.9억부터 - 다른 매물 추천 : 101동 7층인데 5.9 -> 5.8 가능 | V10: 친절, 일잘러는 아니시지만 손님과 유대감 쌓기 좋을 스타일 | W10: [시세/분위기] - 현재 전세 고층 3.6 (3/24에 1천 내림) & 저층 3.7 - 부사님 처음에 전세 3.8~3.9 말씀하시다가 3.5가 안전선이라고 말바꾸심 - 전세 문의가 활발하고 빠르게 나가는 편은 아닐 것으로 예상 | X10: =if(OR(U10 <>"", V10<>"", W10 <> ""), TEXTJOIN("", TRUE, J10, " ", K10, " ", L10, "^", char(10), F10, " ", G10, char(10), O10, "p ",N10, " ", P10, " / ", Q10 , " ", CHAR(10),CHAR(10), U10, CHAR(10),CHAR(10), "<부동산 평가>",CHAR(10),CHAR(10), V10, CHAR(10),CHAR(10), "<얻은 정보>", CHAR(10),CHAR(10),W10), "") -> 신흥SK뷰 2022.04 1588^ SK진공인 010-9677-0709 34p 103동 고/24층 남동향 56,000 / 37,000 [매물 정보] - 103동 고/24층 남동향 : 5.6억 - 102, 103동은 조망이 살짝 막힘 (특히 남동), 101동이 앞동에 남서향이 전망 좋은 편인데 5.9억부터 - 다른 매물 추천 : 101동 7층인데 5.9 -> 5.8 가능 <부동산 평가> 친절, 일잘러는 아니시지만 손님과 유대감 쌓기 좋을 스타일 <얻은 정보> [시세/분위기] - 현재 전세 고층 3.6 (3/24에 1천 내림) & 저층 3.7 - 부사님 처음에 전세 3.8~3.9 말씀하시다가 3.5가 안전선이라고 말바꾸심 - 전세 문의가 활발하고 빠르게 나가는 편은 아닐 것으로 예상 | Z10: 굿데이 | AA10: 50 | AB10: =COUNTIF($C:$C,$Z10) -> 14 | AC10: =AB10/AA10 -> 0.28
