Workbook

Sheet 임장지
B1: 상 | C1: 중
B2: 하
A3: 84 | B3: 선호도 | D3: 단지정보 (30평) | L3: 투자결과
B4: 생활권 | C4: 생활권 내 | D4: 단지명 | E4: 시기(년) | F4: 전세가율 80%이상인 기간 | G4: 평형 | H4: 매매가 | I4: 전세가 | J4: 전세가율 | K4: 투자금 | L4: 시기(년) | M4: 매매가 | N4: 수익금 | O4: 상승율 | P4: 수익율
A5: 생활권 | J5: =I5/H5 | K5: =H5-I5 | N5: =M5-H5 | O5: =1+(M5-H5)/H5 | P5: =N5/K5 | R5: 나만의 인싸이트 | Z5: 감사합니다 튜터님 ㅎㅎㅎ 정리하자면
A6: 생활권 | J6: =I6/H6 | K6: =H6-I6 | N6: =M6-H6 | O6: =1+(M6-H6)/H6 | P6: =N6/K6 | Z6: 1. 생활권 별 / 선호도 별 단지 추출 (상중하)
A7: 생활권 | J7: =I7/H7 | K7: =H7-I7 | N7: =M7-H7 | O7: =1+(M7-H7)/H7 | P7: =N7/K7 | Z7: 2. 각 단지들 투자하기 좋았던 시기 기록 (전세가율 80% 이상인 시기, 투자기회를 얼마나 주었는가?)
A8: 생활권 | J8: =I8/H8 | K8: =H8-I8 | N8: =M8-H8 | O8: =1+(M8-H8)/H8 | P8: =N8/K8 | Z8: 3. 그 단지들 전고점 시기 기록
A9: 생활권 | J9: =I9/H9 | K9: =H9-I9 | N9: =M9-H9 | O9: =1+(M9-H9)/H9 | P9: =N9/K9 | Z9: 4. [2번 시기]에 투자했을 때 [3번 시기] 기준 수익률 분석
A10: 생활권 | J10: =I10/H10 | K10: =H10-I10 | N10: =M10-H10 | O10: =1+(M10-H10)/H10 | P10: =N10/K10
A11: 생활권 | J11: =I11/H11 | K11: =H11-I11 | N11: =M11-H11 | O11: =1+(M11-H11)/H11 | P11: =N11/K11 | Z11: 선명한 앞마당을 만들어 줄 '찐' 수익률분석 [나알이]
A12: 생활권 | J12: =I12/H12 | K12: =H12-I12 | N12: =M12-H12 | O12: =1+(M12-H12)/H12 | P12: =N12/K12 | R12: 결론 | Z12: https://weolbu.com/s/MhxRTz9ZpG
A13: 생활권 | J13: =I13/H13 | K13: =H13-I13 | N13: =M13-H13 | O13: =1+(M13-H13)/H13 | P13: =N13/K13
A14: 생활권 | J14: =I14/H14 | K14: =H14-I14 | N14: =M14-H14 | O14: =1+(M14-H14)/H14 | P14: =N14/K14
A15: 생활권 | J15: =I15/H15 | K15: =H15-I15 | N15: =M15-H15 | O15: =1+(M15-H15)/H15 | P15: =N15/K15
A16: 생활권 | J16: =I16/H16 | K16: =H16-I16 | N16: =M16-H16 | O16: =1+(M16-H16)/H16 | P16: =N16/K16
A17: 생활권 | J17: =I17/H17 | K17: =H17-I17 | N17: =M17-H17 | O17: =1+(M17-H17)/H17 | P17: =N17/K17
A18: 생활권 | J18: =I18/H18 | K18: =H18-I18 | N18: =M18-H18 | O18: =1+(M18-H18)/H18 | P18: =N18/K18
A19: 생활권 | J19: =I19/H19 | K19: =H19-I19 | N19: =M19-H19 | O19: =1+(M19-H19)/H19 | P19: =N19/K19 | R19: 투자적용 및 질문
A20: 생활권 | J20: =I20/H20 | K20: =H20-I20 | N20: =M20-H20 | O20: =1+(M20-H20)/H20 | P20: =N20/K20
A21: 생활권 | J21: =I21/H21 | K21: =H21-I21 | N21: =M21-H21 | O21: =1+(M21-H21)/H21 | P21: =N21/K21
A22: 생활권 | J22: =I22/H22 | K22: =H22-I22 | N22: =M22-H22 | O22: =1+(M22-H22)/H22 | P22: =N22/K22
A23: 생활권 | J23: =I23/H23 | K23: =H23-I23 | N23: =M23-H23 | O23: =1+(M23-H23)/H23 | P23: =N23/K23
A24: 59 | B24: 선호도 | D24: 단지정보 (20평) | L24: 투자결과
B25: 생활권 | C25: 생활권 내 | D25: 단지명 | E25: 시기(년) | F25: 전세가율 80%이상인 기간 | G25: 평형 | H25: 매매가 | I25: 전세가 | J25: 전세가율 | K25: 투자금 | L25: 시기(년) | M25: 매매가 | N25: 수익금 | O25: 상승율 | P25: 수익율
A26: 생활권 | J26: =I26/H26 | K26: =H26-I26 | N26: =M26-H26 | O26: =1+(M26-H26)/H26 | P26: =N26/K26
A27: 생활권 | J27: =I27/H27 | K27: =H27-I27 | N27: =M27-H27 | O27: =1+(M27-H27)/H27 | P27: =N27/K27
A28: 생활권 | J28: =I28/H28 | K28: =H28-I28 | N28: =M28-H28 | O28: =1+(M28-H28)/H28 | P28: =N28/K28
A29: 생활권 | J29: =I29/H29 | K29: =H29-I29 | N29: =M29-H29 | O29: =1+(M29-H29)/H29 | P29: =N29/K29
A30: 생활권 | J30: =I30/H30 | K30: =H30-I30 | N30: =M30-H30 | O30: =1+(M30-H30)/H30 | P30: =N30/K30
A31: 생활권 | J31: =I31/H31 | K31: =H31-I31 | N31: =M31-H31 | O31: =1+(M31-H31)/H31 | P31: =N31/K31
A32: 생활권 | J32: =I32/H32 | K32: =H32-I32 | N32: =M32-H32 | O32: =1+(M32-H32)/H32 | P32: =N32/K32
A33: 생활권 | J33: =I33/H33 | K33: =H33-I33 | N33: =M33-H33 | O33: =1+(M33-H33)/H33 | P33: =N33/K33
A34: 생활권 | J34: =I34/H34 | K34: =H34-I34 | N34: =M34-H34 | O34: =1+(M34-H34)/H34 | P34: =N34/K34
A35: 생활권 | J35: =I35/H35 | K35: =H35-I35 | N35: =M35-H35 | O35: =1+(M35-H35)/H35 | P35: =N35/K35
A36: 생활권 | J36: =I36/H36 | K36: =H36-I36 | N36: =M36-H36 | O36: =1+(M36-H36)/H36 | P36: =N36/K36
A37: 생활권 | J37: =I37/H37 | K37: =H37-I37 | N37: =M37-H37 | O37: =1+(M37-H37)/H37 | P37: =N37/K37
... A45: 생활권 | J45: =I45/H45 | K45: =H45-I45 | N45: =M45-H45 | O45: =1+(M45-H45)/H45 | P45: =N45/K45
Z58: [공급 영향 심화 버전]
Z60: {=- 호갱노노 그래프}
...

Sheet 대전동구
B1: 상 | C1: 중
B2: 하
A3: 84 | B3: 선호도 | D3: 단지정보 (30평) | AE3: 투자결과
B4: 생활권 | C4: 생활권 내 | D4: 단지명 | E4: 평형 | F4: 매 | G4: 전 | H4: 연식 | I4: 세대수 | J4: 나이 | K4: 공급면적 | L4: 전용면적 | M4: 평형 | N4: 매 | O4: 전 | P4: 차 | Q4: 전세가율 | R4: 전고 | S4: 전저 | T4: 계/복 | U4: 방 | V4: 화 | W4: 면적세대수 | X4: 시기(년) | Y4: (전세가율80%이상인)기간 | Z4: 평형 | AA4: 매매가 | AB4: 전세가 | AC4: 전세가율 | AD4: 투자금 | AE4: 시기(년) | AF4: 매매가 | AG4: 수익금 | AH4: 상승율 | AI4: 수익율
A5: 가양동 | B5: 하 | C5: 상 | D5: 힐스테가양더와이즈(주복) | E5: 34 | F5: 4.9 | G5: 3.5 | H5: 2024.09 | I5: 358 | J5: 2.91 | K5: 113A, 113B | L5: 84 | M5: 34 | N5: 50000 | O5: 35000 | P5: 14000 | Q5: 0.71428571 | R5: 57600 | S5: 52000 | T5: 계단식 | U5: 3 | V5: 2 | W5: 156 | Z5: 34 | AC5: #DIV/0! | AD5: 0 | AG5: 0 | AH5: #DIV/0! | AI5: #DIV/0!
A6: 가양동 | B6: 하 | C6: 상 | D6: 힐스테가양더와이즈(주복) | E6: 43 | F6: 0 | G6: 0 | H6: 2024.09 | I6: 358 | J6: 2.91 | K6: 141A, 142B | L6: 105 | M6: 43 | N6: 0 | O6: 0 | P6: 0 | Q6: #DIV/0! | R6: 0 | S6: 0 | T6: 계단식 | U6: 3 | V6: 2 | W6: 115 | Z6: 43 | AC6: #DIV/0! | AD6: 0 | AG6: 0 | AH6: #DIV/0! | AI6: #DIV/0!
A7: 가양동 | B7: 하 | C7: 상 | D7: 힐스테가양더와이즈(주복) | E7: 44 | F7: 0 | G7: 0 | H7: 2024.09 | I7: 358 | J7: 2.91 | K7: 146 | L7: 108 | M7: 44 | N7: 0 | O7: 0 | P7: 0 | Q7: #DIV/0! | R7: 0 | S7: 0 | T7: 계단식 | U7: 4 | V7: 2 | W7: 85 | Z7: 44 | AC7: #DIV/0! | AD7: 0 | AG7: 0 | AH7: #DIV/0! | AI7: #DIV/0!
A8: 가양동 | B8: 하 | C8: 상 | D8: 힐스테가양더와이즈(주복) | E8: 64 | F8: 0 | G8: 0 | H8: 2024.09 | I8: 358 | J8: 2.91 | K8: 210 | L8: 155 | M8: 64 | N8: 0 | O8: 0 | P8: 0 | Q8: #DIV/0! | R8: 0 | S8: 0 | T8: 계단식 | U8: 3 | V8: 3 | W8: 2 | Z8: 64 | AC8: #DIV/0! | AD8: 0 | AG8: 0 | AH8: #DIV/0! | AI8: #DIV/0! | AK8: 투자적용 및 질문
A9: 천동 | B9: 상 | C9: 하 | D9: 휴먼시아2단지 | E9: 34 | F9: 2.5 | G9: 2.3 | H9: 2008.11 | I9: 763 | J9: 18.89 | K9: 111C, 111B, 111A | L9: 84 | M9: 34 | N9: 25000 | O9: 23000 | P9: 2000 | Q9: 0.92 | R9: 39000 | S9: 25300 | T9: 계단식 | U9: 3 | V9: 2 | W9: 597 | X9: 2020.01 | Y9: 0.02 | Z9: 34 | AA9: 24175 | AB9: 20167 | AC9: #DIV/0! | AD9: 0
A10: 천동 | B10: 상 | C10: 하 | D10: 휴먼시아2단지 | E10: 30 | F10: 2.4 | G10: 2 | H10: 2008.11 | I10: 763 | J10: 18.89 | K10: 99 | L10: 75 | M10: 30 | N10: 24000 | O10: 20000 | P10: 4000 | Q10: 0.83333333 | R10: 31000 | S10: 23000 | T10: 계단식 | U10: 3 | V10: 2 | W10: 72 | X10: 2025.09 | Y10: 0.03 | Z10: 30 | AA10: 23250 | AB10: 20000 | AC10: #DIV/0! | AD10: 0
A11: 천동 | B11: 상 | C11: 하 | D11: 휴먼시아2단지 | E11: 43 | F11: 0 | G11: 0 | H11: 2008.11 | I11: 763 | J11: 18.89 | K11: 142 | L11: 108 | M11: 43 | N11: 0 | O11: 0 | P11: 0 | Q11: #DIV/0! | R11: 0 | S11: 0 | T11: 계단식 | U11: 4 | V11: 2 | W11: 94 | Z11: 43 | AC11: #DIV/0! | AD11: 0
A12: 성남동 | B12: 상 | C12: 하 | D12: 효촌마을 | E12: 33 | F12: 3.15 | G12: 2.5 | H12: 2003.04 | I12: 818 | J12: 23.96 | K12: 108A | L12: 84 | M12: 33 | N12: 31500 | O12: 25000 | P12: 6500 | Q12: 0.79365079 | R12: 40500 | S12: 29000 | T12: 계단식 | U12: 3 | V12: 2 | W12: 272 | Z12: 33 | AC12: #DIV/0! | AD12: 0
A13: 성남동 | B13: 상 | C13: 하 | D13: 효촌마을 | E13: 33 | F13: 2.8 | G13: 2.6 | H13: 2003.04 | I13: 818 | J13: 23.96 | K13: 109B | L13: 84 | M13: 33 | N13: 28000 | O13: 26000 | P13: 2000 | Q13: 0.92857143 | R13: 40500 | S13: 30000 | T13: 계단식 | U13: 4 | V13: 2 | W13: 100 | Z13: 33 | AC13: #DIV/0! | AD13: 0
A14: 성남동 | B14: 상 | C14: 하 | D14: 효촌마을 | E14: 24 | F14: 2.3 | G14: 2 | H14: 2003.04 | I14: 818 | J14: 23.96 | K14: 79A, 80B | L14: 59 | M14: 24 | N14: 23000 | O14: 20000 | P14: 3000 | Q14: 0.86956522 | R14: 31000 | S14: 22000 | T14: 계단식 | U14: 3 | V14: 1 | W14: 327 | Z14: 24 | AC14: #DIV/0! | AD14: 0
A15: 성남동 | B15: 상 | C15: 하 | D15: 효촌마을 | E15: 21 | F15: 1.9 | G15: 1.5 | H15: 2003.04 | I15: 818 | J15: 23.96 | K15: 69 | L15: 46 | M15: 21 | N15: 19000 | O15: 15000 | P15: 4000 | Q15: 0.78947368 | R15: 25000 | S15: 18000 | T15: 복도식 | U15: 2 | V15: 1 | W15: 119 | X15: 2020.06 | Y15: 0.01 | Z15: 21 | AA15: 17220 | AB15: 14000 | AC15: #DIV/0! | AD15: 0
A16: 효동 | B16: 상 | C16: 하 | D16: 효동현대 | E16: 49 | F16: 4 | G16: 1.8 | H16: 1998.09 | I16: 1056 | J16: 28.91 | K16: 161 | L16: 134 | M16: 49 | N16: 40000 | O16: 18000 | P16: 22000 | Q16: 0.45 | R16: 40000 | S16: 35000 | T16: 계단식 | U16: 4 | V16: 2 | W16: 30 | Z16: 49 | AC16: #DIV/0! | AD16: 0
A17: 효동 | B17: 상 | C17: 하 | D17: 효동현대 | E17: 37 | F17: 3.35 | G17: 2 | H17: 1998.09 | I17: 1056 | J17: 28.91 | K17: 123A, 125B, 128 | L17: 99 | M17: 37 | N17: 33500 | O17: 20000 | P17: 13500 | Q17: 0.59701493 | R17: 35000 | S17: 28000 | T17: 계단식 | U17: 3 | V17: 2 | W17: 126 | X17: 2020.11 | Y17: 0.06 | Z17: 37 | AA17: 25000 | AB17: 22000 | AC17: #DIV/0! | AD17: 0
A18: 효동 | B18: 상 | C18: 하 | D18: 효동현대 | E18: 32 | F18: 2.7 | G18: 2 | H18: 1998.09 | I18: 1056 | J18: 28.91 | K18: 107B, 112 | L18: 86 | M18: 32 | N18: 27000 | O18: 20000 | P18: 7000 | Q18: 0.74074074 | R18: 34000 | S18: 23000 | T18: 계단식 | U18: 3 | V18: 2 | W18: 6 | X18: 2020.01 | Y18: 0.01 | Z18: 32 | AA18: 17500 | AB18: 15500 | AC18: #DIV/0! | AD18: 0
A19: 효동 | B19: 상 | C19: 하 | D19: 효동현대 | E19: 31 | F19: 2.6 | G19: 2 | H19: 1998.09 | I19: 1056 | J19: 28.91 | K19: 103, 106A, 106B, 109A | L19: 84 | M19: 31 | N19: 26000 | O19: 20000 | P19: 6000 | Q19: 0.76923077 | R19: 32500 | S19: 23500 | T19: 계단식 | U19: 3 | V19: 2 | W19: 561 | X19: 2020.01 | Y19: 0.01 | Z19: 31 | AA19: 17500 | AB19: 15500 | AC19: #DIV/0! | AD19: 0
A20: 효동 | B20: 상 | C20: 하 | D20: 효동현대 | E20: 30 | F20: 2.35 | G20: 1.8 | H20: 1998.09 | I20: 1056 | J20: 28.91 | K20: 99 | L20: 76 | M20: 30 | N20: 23500 | O20: 18000 | P20: 5500 | Q20: 0.76595745 | R20: 28500 | S20: 22000 | T20: 계단식 | U20: 3 | V20: 2 | W20: 102 | X20: 2020.02 | Y20: 0.03 | Z20: 30 | AA20: 19250 | AB20: 16000 | AC20: #DIV/0! | AD20: 0
A21: 효동 | B21: 상 | C21: 하 | D21: 효동현대 | E21: 23 | F21: 2.2 | G21: 1.3 | H21: 1998.09 | I21: 1056 | J21: 28.91 | K21: 77A, 78B | L21: 59 | M21: 23 | N21: 22000 | O21: 13000 | P21: 9000 | Q21: 0.59090909 | R21: 25500 | S21: 18500 | T21: 계단식 | U21: 3 | V21: 1 | W21: 231 | Z21: 23 | AC21: #DIV/0! | AD21: 0
A22: 홍도동 | B22: 중 | C22: 하 | D22: 홍도서우 | E22: 35 | F22: 2.4 | G22: 1.2 | H22: 1996.1 | I22: 571 | J22: 30.9 | K22: 114 | L22: 84 | M22: 35 | N22: 24000 | O22: 12000 | P22: 12000 | Q22: 0.5 | R22: 18000 | S22: 19000 | T22: 복도식 | U22: 3 | V22: 2 | W22: 33 | Z22: 35 | AC22: #DIV/0! | AD22: 0
A23: 홍도동 | B23: 중 | C23: 하 | D23: 홍도서우 | E23: 24 | F23: 1.49 | G23: 1.3 | H23: 1996.1 | I23: 571 | J23: 30.9 | K23: 80 | L23: 59 | M23: 24 | N23: 14900 | O23: 13000 | P23: 1900 | Q23: 0.87248322 | R23: 16500 | S23: 13800 | T23: 복도식 | U23: 3 | V23: 1 | W23: 139 | X23: 2020.06 | Y23: 0.01 | Z23: 24 | AA23: 13300 | AB23: 11000 | AC23: #DIV/0! | AD23: 0
A24: 홍도동 | B24: 중 | C24: 하 | D24: 홍도서우 | E24: 17 | F24: 0.92 | G24: 0.72 | H24: 1996.1 | I24: 571 | J24: 30.9 | K24: 56 | L24: 42 | M24: 17 | N24: 9200 | O24: 7200 | P24: 2000 | Q24: 0.7826087 | R24: 12300 | S24: 9000 | T24: 복도식 | U24: 2 | V24: 1 | W24: 275 | X24: 2020.01 | Y24: 0.02 | Z24: 17 | AA24: 8400 | AB24: 7200 | AC24: #DIV/0! | AD24: 0
A25: 홍도동 | B25: 중 | C25: 하 | D25: 홍도서우 | E25: 18 | F25: 0.9 | G25: 0.85 | H25: 1996.1 | I25: 571 | J25: 30.9 | K25: 61 | L25: 45 | M25: 18 | N25: 9000 | O25: 8500 | P25: 500 | Q25: 0.94444444 | R25: 13500 | S25: 12000 | T25: 복도식 | U25: 2 | V25: 1 | W25: 124 | X25: 2020.05 | Y25: 0.05 | Z25: 18 | AA25: 9260 | AB25: 8125 | AC25: #DIV/0! | AD25: 0
A26: 홍도동 | B26: 중 | C26: 상 | D26: 홍도갤러리휴리움 | E26: 30 | F26: 3.5 | G26: 2.4 | H26: 2023.02 | I26: 419 | J26: 3.98 | K26: 98 | L26: 74 | M26: 30 | N26: 35000 | O26: 24000 | P26: 11000 | Q26: 0.68571429 | R26: 36000 | S26: 32500 | T26: 계단식 | U26: 3 | V26: 2 | W26: 85 | Z26: 30 | AC26: #DIV/0! | AD26: 0
A27: 홍도동 | B27: 중 | C27: 상 | D27: 홍도갤러리휴리움 | E27: 24 | F27: 2.9 | G27: 2.35 | H27: 2023.02 | I27: 419 | J27: 3.98 | K27: 80B, 82A, 87C | L27: 59 | M27: 24 | N27: 29000 | O27: 23500 | P27: 5500 | Q27: 0.81034483 | R27: 30000 | S27: 26500 | T27: 계단식 | U27: 3 | V27: 2 | W27: 206 | X27: 2024.06 | Y27: 0.02 | Z27: 24 | AA27: 27700 | AB27: 23000 | AC27: #DIV/0! | AD27: 0
A28: 홍도동 | B28: 중 | C28: 상 | D28: 홍도갤러리휴리움 | E28: 22 | F28: 2.5 | G28: 2 | H28: 2023.02 | I28: 419 | J28: 3.98 | K28: 71A, 72C, 74B | L28: 49 | M28: 22 | N28: 25000 | O28: 20000 | P28: 5000 | Q28: 0.8 | R28: 26800 | S28: 24500 | T28: 계단식 | U28: 2 | V28: 2 | W28: 128 | X28: 2025.12 | Y28: 0.01 | Z28: 22 | AA28: 25183 | AB28: 20300 | AC28: #DIV/0! | AD28: 0
A29: 인동 | B29: 중 | C29: 하 | D29: 현대 | E29: 29 | F29: 2.2 | G29: 1.3 | H29: 1987.06 | I29: 728 | J29: 39.94 | K29: 97 | L29: 79 | M29: 29 | N29: 22000 | O29: 13000 | P29: 9000 | Q29: 0.59090909 | R29: 25500 | S29: 19000 | T29: 계단식 | U29: 3 | V29: 1 | W29: 52 | X29: 2020.01 | Y29: 0.01 | Z29: 29 | AA29: 15000 | AB29: 12000 | AC29: #DIV/0! | AD29: 0
A30: 인동 | B30: 중 | C30: 하 | D30: 현대 | E30: 32 | F30: 2.2 | G30: 1.8 | H30: 1987.06 | I30: 728 | J30: 39.94 | K30: 104 | L30: 84 | M30: 32 | N30: 22000 | O30: 18000 | P30: 4000 | Q30: 0.81818182 | R30: 27800 | S30: 19000 | T30: 계단식 | U30: 3 | V30: 1 | W30: 312 | X30: 2022.1 | Y30: 0.01 | Z30: 32 | AA30: 21633 | AB30: 17333 | AC30: #DIV/0! | AD30: 0
A31: 인동 | B31: 중 | C31: 하 | D31: 현대 | E31: 26 | F31: 2.1 | G31: 1.6 | H31: 1987.06 | I31: 728 | J31: 39.94 | K31: 86 | L31: 70 | M31: 26 | N31: 21000 | O31: 16000 | P31: 5000 | Q31: 0.76190476 | R31: 25000 | S31: 17000 | T31: 계단식 | U31: 3 | V31: 1 | W31: 182 | X31: 2020.09 | Y31: 0.02 | Z31: 26 | AA31: 16838 | AB31: 14000 | AC31: #DIV/0! | AD31: 0
A32: 인동 | B32: 중 | C32: 하 | D32: 현대 | E32: 25 | F32: 1.8 | G32: 1.5 | H32: 1987.06 | I32: 728 | J32: 39.94 | K32: 81 | L32: 63 | M32: 25 | N32: 18000 | O32: 15000 | P32: 3000 | Q32: 0.83333333 | R32: 23900 | S32: 16500 | T32: 계단식 | U32: 3 | V32: 1 | W32: 130 | Z32: 25 | AC32: #DIV/0! | AD32: 0
A33: 인동 | B33: 중 | C33: 하 | D33: 현대 | E33: 21 | F33: 1.35 | G33: 1.4 | H33: 1987.06 | I33: 728 | J33: 39.94 | K33: 70 | L33: 52 | M33: 21 | N33: 13500 | O33: 14000 | P33: -500 | Q33: 1.037037 | R33: 20500 | S33: 14500 | T33: 계단식 | U33: 3 | V33: 1 | W33: 52 | X33: 2021.09 | Y33: 0.03 | Z33: 21 | AA33: 13500 | AB33: 12500 | AC33: #DIV/0! | AD33: 0
A34: 용운동 | B34: 하 | C34: 중 | D34: 한화꿈에그린 | E34: 34 | F34: 2.8 | G34: 2.1 | H34: 2006.01 | I34: 641 | J34: 20.99 | K34: 112 | L34: 84 | M34: 34 | N34: 28000 | O34: 21000 | P34: 7000 | Q34: 0.75 | R34: 34000 | S34: 26000 | T34: 계단식 | U34: 3 | V34: 2 | W34: 435 | X34: 2020.1 | Y34: 0.02 | Z34: 34 | AA34: 25574 | AB34: 21429 | AC34: #DIV/0! | AD34: 0
A35: 용운동 | B35: 하 | C35: 중 | D35: 한화꿈에그린 | E35: 37 | F35: 0 | G35: 0 | H35: 2006.01 | I35: 641 | J35: 20.99 | K35: 123 | L35: 93 | M35: 37 | N35: 0 | O35: 0 | P35: 0 | Q35: #DIV/0! | R35: 0 | S35: 0 | T35: 계단식 | U35: 3 | V35: 2 | W35: 30 | X35: 2020.11 | Y35: 0.02 | Z35: 37 | AA35: 28150 | AB35: 25000 | AC35: #DIV/0! | AD35: 0
A36: 용운동 | B36: 하 | C36: 중 | D36: 한화꿈에그린 | E36: 46 | F36: 0 | G36: 0 | H36: 2006.01 | I36: 641 | J36: 20.99 | K36: 151 | L36: 122 | M36: 46 | N36: 0 | O36: 0 | P36: 0 | Q36: #DIV/0! | R36: 0 | S36: 0 | T36: 계단식 | U36: 4 | V36: 2 | W36: 120 | X36: 2020.11 | Y36: 0.03 | Z36: 46 | AA36: 28733 | AB36: 27000 | AC36: #DIV/0! | AD36: 0
A37: 용운동 | B37: 하 | C37: 중 | D37: 한화꿈에그린 | E37: 52 | F37: 0 | G37: 0 | H37: 2006.01 | I37: 641 | J37: 20.99 | K37: 173 | L37: 140 | M37: 52 | N37: 0 | O37: 0 | P37: 0 | Q37: #DIV/0! | R37: 0 | S37: 0 | T37: 계단식 | U37: 4 | V37: 2 | W37: 56 | Z37: 52 | AC37: #DIV/0! | AD37: 0
A38: 용전동 | B38: 하 | C38: 하 | D38: 한숲 | E38: 32 | F38: 2.8 | G38: 2.2 | H38: 1999.08 | I38: 1036 | J38: 27.92 | K38: 104A, 107B | L38: 84 | M38: 32 | N38: 28000 | O38: 22000 | P38: 6000 | Q38: 0.78571429 | R38: 36000 | S38: 27500 | T38: 계단식 | U38: 3 | V38: 2 | W38: 528 | X38: 2020.09 | Y38: 0.01 | Z38: 32 | AA38: 24089 | AB38: 19333 | AC38: #DIV/0! | AD38: 0
A39: 용전동 | B39: 하 | C39: 하 | D39: 한숲 | E39: 24 | F39: 2.4 | G39: 2.1 | H39: 1999.08 | I39: 1036 | J39: 27.92 | K39: 78A, 80B | L39: 59 | M39: 24 | N39: 24000 | O39: 21000 | P39: 3000 | Q39: 0.875 | R39: 28500 | S39: 21500 | T39: 계단식 | U39: 3 | V39: 1 | W39: 276 | X39: 2020.09 | Y39: 0.01 | Z39: 24 | AA39: 20323 | AB39: 17500 | AC39: #DIV/0! | AD39: 0
A40: 용전동 | B40: 하 | C40: 하 | D40: 한숲 | E40: 37 | F40: 0 | G40: 0 | H40: 1999.08 | I40: 1036 | J40: 27.92 | K40: 123 | L40: 99 | M40: 37 | N40: 0 | O40: 0 | P40: 0 | Q40: #DIV/0! | R40: 0 | S40: 0 | T40: 계단식 | U40: 3 | V40: 2 | W40: 72 | X40: 2022.06 | Y40: 0.03 | Z40: 37 | AA40: 35000 | AB40: 30000 | AC40: #DIV/0! | AD40: 0
...

Sheet 천안동남구
B1: 상 | C1: 중
B2: 하
A3: 84 | B3: 선호도 | E3: 단지정보 (30평) | AH3: 투자결과
B4: 생활권 | C4: 생활권 내 | D4: 단지코드 | E4: 단지명 | F4: 사용승인일 | G4: 총세대수 | H4: 나이 | I4: 타입 | J4: 공급면적 | K4: 전용면적 | L4: 평형 | M4: 구조 | N4: 방수 | O4: 욕실수 | P4: 평형별 세대수 | Q4: 매 | R4: 전 | S4: 차 | T4: 전세가율 | U4: 전고 | V4: 전저 | W4: 계/복 | X4: 방 | Y4: 화 | Z4: 면적세대수 | AA4: 시기(년) | AB4: (전세가율80%이상인)기간 | AC4: 평형 | AD4: 매매가 | AE4: 전세가 | AF4: 전세가율 | AG4: 투자금 | AH4: 시기(년) | AI4: 매매가 | AJ4: 수익금 | AK4: 상승율 | AL4: 수익율
A5: 신부동 | D5: 143063 | E5: 포레나천안신부 | F5: 2023.12 | G5: 602 | H5: =2026-F5+1 | I5: 110A, 111B | J5: 110 | K5: 84 | L5: 33 | M5: 계단식 | N5: 3 | O5: 2 | P5: 222 | Q5: 47000 | R5: 32000 | S5: =Q5-R5 | T5: =R5/Q5 | W5: 계단식 | X5: 3 | Y5: 2 | Z5: 222 | AA5: 2025.01 | AB5: 0.01 | AC5: =L5 | AD5: 36000 | AE5: 34000 | AF5: =AE5/AD5 | AG5: =AD5-AE5 | AH5: 2026.04 | AI5: 47000 | AJ5: =AI5-AD5 | AK5: =(AI5-AD5)/AD5 | AL5: =AJ5/AG5
A6: 청당동 | D6: 151758 | E6: 천안롯데캐슬더청당 | F6: 2025.08 | G6: 1199 | H6: =2026-F6+1 | I6: 113A, 114B, 114C | J6: 113 | K6: 84 | L6: 34 | M6: 계단식 | N6: 3 | O6: 2 | P6: 942 | Q6: 47000 | R6: 35000 | S6: =Q6-R6 | T6: =R6/Q6 | W6: 계단식 | X6: 3 | Y6: 2 | Z6: 942 | AC6: =L6 | AF6: =AE6/AD6 | AG6: =AD6-AE6 | AH6: 2026.04 | AI6: 47000 | AJ6: =AI6-AD6 | AK6: =(AI6-AD6)/AD6 | AL6: =AJ6/AG6
A7: 봉명동 | D7: 137226 | E7: 봉명역센트럴시티 | F7: 2025.01 | G7: 816 | H7: =2026-F7+1 | I7: 114A, 114B | J7: 114 | K7: 84 | L7: 34 | M7: 계단식 | N7: 3 | O7: 2 | P7: 146 | Q7: 43800 | R7: 30000 | S7: =Q7-R7 | T7: =R7/Q7 | W7: 계단식 | X7: 3 | Y7: 2 | Z7: 146 | AC7: =L7 | AF7: =AE7/AD7 | AG7: =AD7-AE7 | AH7: 2026.04 | AI7: 43800 | AJ7: =AI7-AD7 | AK7: =(AI7-AD7)/AD7 | AL7: =AJ7/AG7 | AV7: ★중요한 것은 스스로 생각해보고 결론 내어보고 매임까지 하면서 [검증]해 나가는 것
A8: 문화동 | D8: 121930 | E8: 힐스테이트천안(주상복합) | F8: 2021.03 | G8: 451 | H8: =2026-F8+1 | I8: 120 | J8: 120 | K8: 84 | L8: 36 | M8: 계단식 | N8: 3 | O8: 2 | P8: 164 | Q8: 42000 | R8: 28000 | S8: =Q8-R8 | T8: =R8/Q8 | U8: 45000 | V8: 39000 | W8: 계단식 | X8: 3 | Y8: 2 | Z8: 164 | AC8: =L8 | AF8: =AE8/AD8 | AG8: =AD8-AE8 | AH8: 2026.04 | AI8: 42000 | AJ8: =AI8-AD8 | AK8: =(AI8-AD8)/AD8 | AL8: =AJ8/AG8
A9: 삼룡동 | D9: 146718 | E9: 호반써밋포레센트 | F9: 2023.12 | G9: 594 | H9: =2026-F9+1 | I9: 109C, 109B, 111A | J9: 109 | K9: 84 | L9: 33 | M9: 계단식 | N9: 3 | O9: 2 | P9: 430 | Q9: 42000 | R9: 30000 | S9: =Q9-R9 | T9: =R9/Q9 | W9: 계단식 | X9: 3 | Y9: 2 | Z9: 430 | AC9: =L9 | AF9: =AE9/AD9 | AG9: =AD9-AE9 | AH9: 2026.04 | AI9: 42000 | AJ9: =AI9-AD9 | AK9: =(AI9-AD9)/AD9 | AL9: =AJ9/AG9
A10: 신부동 | D10: 143063 | E10: 포레나천안신부 | F10: 2023.12 | G10: 602 | H10: =2026-F10+1 | I10: 101 | J10: 101 | K10: 76 | L10: 31 | M10: 계단식 | N10: 3 | O10: 2 | P10: 123 | Q10: 42000 | R10: 32000 | S10: =Q10-R10 | T10: =R10/Q10 | W10: 계단식 | X10: 3 | Y10: 2 | Z10: 123 | AA10: 2024.03 | AB10: 0.06 | AC10: =L10 | AD10: 33000 | AE10: 28429 | AF10: =AE10/AD10 | AG10: =AD10-AE10 | AH10: 2026.04 | AI10: 42000 | AJ10: =AI10-AD10 | AK10: =(AI10-AD10)/AD10 | AL10: =AJ10/AG10
A11: 용곡동 | D11: 186759 | E11: 천안용곡두산위브 | F11: 2025.1 | G11: 409 | H11: =2026-F11+1 | I11: 109C | J11: 109 | K11: 84 | L11: 33 | M11: 계단식 | N11: 4 | O11: 2 | P11: 3 | Q11: 42000 | R11: 25000 | S11: =Q11-R11 | T11: =R11/Q11 | W11: 계단식 | X11: 4 | Y11: 2 | Z11: 3 | AC11: =L11 | AF11: =AE11/AD11 | AG11: =AD11-AE11 | AH11: 2026.04 | AI11: 42000 | AJ11: =AI11-AD11 | AK11: =(AI11-AD11)/AD11 | AL11: =AJ11/AG11
A12: 신부동 | D12: 152942 | E12: 더샵신부센트라 | F12: 2025.06 | G12: 592 | H12: =2026-F12+1 | I12: 110A, 112B, 112C | J12: 110 | K12: 84 | L12: 33 | M12: 계단식 | N12: 3 | O12: 2 | P12: 446 | Q12: 41760 | R12: 33000 | S12: =Q12-R12 | T12: =R12/Q12 | W12: 계단식 | X12: 3 | Y12: 2 | Z12: 446 | AC12: =L12 | AF12: =AE12/AD12 | AG12: =AD12-AE12 | AH12: 2026.04 | AI12: 41760 | AJ12: =AI12-AD12 | AK12: =(AI12-AD12)/AD12 | AL12: =AJ12/AG12
A13: 용곡동 | D13: 153265 | E13: 호반써밋센트럴파크Ⅰ | F13: 2025.12 | G13: 453 | H13: =2026-F13+1 | I13: 108B | J13: 108 | K13: 84 | L13: 33 | M13: 계단식 | N13: 3 | O13: 2 | P13: 85 | Q13: 41000 | R13: 28000 | S13: =Q13-R13 | T13: =R13/Q13 | W13: 계단식 | X13: 3 | Y13: 2 | Z13: 85 | AC13: =L13 | AF13: =AE13/AD13 | AG13: =AD13-AE13 | AH13: 2026.04 | AI13: 41000 | AJ13: =AI13-AD13 | AK13: =(AI13-AD13)/AD13 | AL13: =AJ13/AG13
A14: 청당동 | D14: 134767 | E14: 행정타운센트럴두산위브 | F14: 2023.02 | G14: 655 | H14: =2026-F14+1 | I14: 111A, 111D, 111C, 111B, 113F, 114E, 114G | J14: 111 | K14: 84 | L14: 34 | M14: 계단식 | N14: 3 | O14: 2 | P14: 399 | Q14: 40500 | R14: 33000 | S14: =Q14-R14 | T14: =R14/Q14 | V14: 37500 | W14: 계단식 | X14: 3 | Y14: 2 | Z14: 399 | AC14: =L14 | AF14: =AE14/AD14 | AG14: =AD14-AE14 | AH14: 2026.04 | AI14: 40500 | AJ14: =AI14-AD14 | AK14: =(AI14-AD14)/AD14 | AL14: =AJ14/AG14
A15: 삼룡동 | D15: 146718 | E15: 호반써밋포레센트 | F15: 2023.12 | G15: 594 | H15: =2026-F15+1 | I15: 100C, 101B, 102A | J15: 100 | K15: 76 | L15: 30 | M15: 계단식 | N15: 3 | O15: 2 | P15: 160 | Q15: 40000 | R15: 22000 | S15: =Q15-R15 | T15: =R15/Q15 | W15: 계단식 | X15: 3 | Y15: 2 | Z15: 160 | AC15: =L15 | AF15: =AE15/AD15 | AG15: =AD15-AE15 | AH15: 2026.04 | AI15: 40000 | AJ15: =AI15-AD15 | AK15: =(AI15-AD15)/AD15 | AL15: =AJ15/AG15
A16: 용곡동 | D16: 186759 | E16: 천안용곡두산위브 | F16: 2025.1 | G16: 409 | H16: =2026-F16+1 | I16: 109A, 110B | J16: 109 | K16: 84 | L16: 33 | M16: 계단식 | N16: 3 | O16: 2 | P16: 34 | Q16: 39500 | R16: 25000 | S16: =Q16-R16 | T16: =R16/Q16 | W16: 계단식 | X16: 3 | Y16: 2 | Z16: 34 | AC16: =L16 | AF16: =AE16/AD16 | AG16: =AD16-AE16 | AH16: 2026.04 | AI16: 39500 | AJ16: =AI16-AD16 | AK16: =(AI16-AD16)/AD16 | AL16: =AJ16/AG16
A17: 문화동 | D17: 126749 | E17: 천안역필하우스에듀시티1단지 | F17: 2022.04 | G17: 1532 | H17: =2026-F17+1 | I17: 112A, 113B, 114C, 114D | J17: 112 | K17: 84 | L17: 34 | M17: 계단식 | N17: 3 | O17: 2 | P17: 913 | Q17: 38800 | R17: 29000 | S17: =Q17-R17 | T17: =R17/Q17 | U17: 35500 | V17: 30000 | W17: 계단식 | X17: 3 | Y17: 2 | Z17: 913 | AC17: =L17 | AF17: =AE17/AD17 | AG17: =AD17-AE17 | AH17: 2026.04 | AI17: 38800 | AJ17: =AI17-AD17 | AK17: =(AI17-AD17)/AD17 | AL17: =AJ17/AG17
A18: 신부동 | D18: 110256 | E18: 힐스테이트천안신부 | F18: 2017.08 | G18: 984 | H18: =2026-F18+1 | I18: 113 | J18: 113 | K18: 84 | L18: 34 | M18: 계단식 | N18: 3 | O18: 2 | P18: 262 | Q18: 37800 | R18: 31000 | S18: =Q18-R18 | T18: =R18/Q18 | U18: 56000 | V18: 36600 | W18: 계단식 | X18: 3 | Y18: 2 | Z18: 262 | AC18: =L18 | AF18: =AE18/AD18 | AG18: =AD18-AE18 | AH18: 2026.04 | AI18: 37800 | AJ18: =AI18-AD18 | AK18: =(AI18-AD18)/AD18 | AL18: =AJ18/AG18
A19: 다가동 | D19: 145699 | E19: 천안극동스타클래스더퍼스트 | F19: 2025.01 | G19: 1225 | H19: =2026-F19+1 | I19: 112A, 113B | J19: 112 | K19: 84 | L19: 34 | M19: 계단식 | N19: 3 | O19: 2 | P19: 123 | Q19: 37000 | R19: 24000 | S19: =Q19-R19 | T19: =R19/Q19 | W19: 계단식 | X19: 3 | Y19: 2 | Z19: 123 | AC19: =L19 | AF19: =AE19/AD19 | AG19: =AD19-AE19 | AH19: 2026.04 | AI19: 37000 | AJ19: =AI19-AD19 | AK19: =(AI19-AD19)/AD19 | AL19: =AJ19/AG19
A20: 문화동 | D20: 121930 | E20: 힐스테이트천안(주상복합) | F20: 2021.03 | G20: 451 | H20: =2026-F20+1 | I20: 106 | J20: 106 | K20: 74 | L20: 32 | M20: 계단식 | N20: 3 | O20: 2 | P20: 123 | Q20: 37000 | R20: 25000 | S20: =Q20-R20 | T20: =R20/Q20 | U20: 41800 | V20: 39000 | W20: 계단식 | X20: 3 | Y20: 2 | Z20: 123 | AC20: =L20 | AF20: =AE20/AD20 | AG20: =AD20-AE20 | AH20: 2026.04 | AI20: 37000 | AJ20: =AI20-AD20 | AK20: =(AI20-AD20)/AD20 | AL20: =AJ20/AG20
A21: 봉명동 | D21: 124679 | E21: e편한세상봉명아너리움 | F21: 2020.06 | G21: 459 | H21: =2026-F21+1 | I21: 113 | J21: 113 | K21: 84 | L21: 34 | M21: 계단식 | N21: 3 | O21: 2 | P21: 98 | Q21: 37000 | R21: 30000 | S21: =Q21-R21 | T21: =R21/Q21 | V21: 34400 | W21: 계단식 | X21: 3 | Y21: 2 | Z21: 98 | AC21: =L21 | AF21: =AE21/AD21 | AG21: =AD21-AE21 | AH21: 2026.04 | AI21: 37000 | AJ21: =AI21-AD21 | AK21: =(AI21-AD21)/AD21 | AL21: =AJ21/AG21 | AV21: >>> 인사이트 (가격을 통해 찾은 내용)
A22: 신부동 | D22: 109735 | E22: 신부디이스트 | F22: 2018.05 | G22: 2144 | H22: =2026-F22+1 | I22: 113A, 114B | J22: 113 | K22: 84 | L22: 34 | M22: 계단식 | N22: 3 | O22: 2 | P22: 448 | Q22: 37000 | R22: 32000 | S22: =Q22-R22 | T22: =R22/Q22 | U22: 56800 | V22: 37500 | W22: 계단식 | X22: 3 | Y22: 2 | Z22: 448 | AA22: 2020.01 | AB22: 0.01 | AC22: =L22 | AD22: 33525 | AE22: 27167 | AF22: =AE22/AD22 | AG22: =AD22-AE22 | AH22: 2026.04 | AI22: 37000 | AJ22: =AI22-AD22 | AK22: =(AI22-AD22)/AD22 | AL22: =AJ22/AG22
A23: 청당동 | D23: 129755 | E23: 청당서희스타힐스 | F23: 2022.12 | G23: 741 | H23: =2026-F23+1 | I23: 111 | J23: 111 | K23: 84 | L23: 34 | M23: 계단식 | N23: 3 | O23: 2 | P23: 227 | Q23: 37000 | R23: 32000 | S23: =Q23-R23 | T23: =R23/Q23 | U23: 33020 | V23: 32500 | W23: 계단식 | X23: 3 | Y23: 2 | Z23: 227 | AC23: =L23 | AF23: =AE23/AD23 | AG23: =AD23-AE23 | AH23: 2026.04 | AI23: 37000 | AJ23: =AI23-AD23 | AK23: =(AI23-AD23)/AD23 | AL23: =AJ23/AG23
A24: 청당동 | D24: 134767 | E24: 행정타운센트럴두산위브 | F24: 2023.02 | G24: 655 | H24: =2026-F24+1 | I24: 98A, 98B | J24: 98 | K24: 74 | L24: 30 | M24: 계단식 | N24: 3 | O24: 2 | P24: 256 | Q24: 37000 | R24: 25000 | S24: =Q24-R24 | T24: =R24/Q24 | V24: 30300 | W24: 계단식 | X24: 3 | Y24: 2 | Z24: 256 | AC24: =L24 | AF24: =AE24/AD24 | AG24: =AD24-AE24 | AH24: 2026.04 | AI24: 37000 | AJ24: =AI24-AD24 | AK24: =(AI24-AD24)/AD24 | AL24: =AJ24/AG24
A25: 청당동 | D25: 107332 | E25: 청수포레나 | F25: 2015.07 | G25: 468 | H25: =2026-F25+1 | I25: 112B, 113A, 113C | J25: 112 | K25: 86 | L25: 34 | M25: 계단식 | N25: 3 | O25: 2 | P25: 416 | Q25: 36000 | R25: 25000 | S25: =Q25-R25 | T25: =R25/Q25 | U25: 52500 | V25: 33000 | W25: 계단식 | X25: 3 | Y25: 2 | Z25: 416 | AA25: 2020.01 | AB25: 0.01 | AC25: =L25 | AD25: 31900 | AE25: 27000 | AF25: =AE25/AD25 | AG25: =AD25-AE25 | AH25: 2026.04 | AI25: 36000 | AJ25: =AI25-AD25 | AK25: =(AI25-AD25)/AD25 | AL25: =AJ25/AG25
A26: 청수동 | D26: 133523 | E26: 청수행정타운금호어울림 | F26: 2023.01 | G26: 584 | H26: =2026-F26+1 | I26: 109 | J26: 109 | K26: 84 | L26: 33 | M26: 계단식 | N26: 3 | O26: 2 | P26: 102 | Q26: 36000 | R26: 23000 | S26: =Q26-R26 | T26: =R26/Q26 | V26: 30790 | W26: 계단식 | X26: 3 | Y26: 2 | Z26: 102 | AC26: =L26 | AF26: =AE26/AD26 | AG26: =AD26-AE26 | AH26: 2026.04 | AI26: 36000 | AJ26: =AI26-AD26 | AK26: =(AI26-AD26)/AD26 | AL26: =AJ26/AG26
A27: 봉명동 | D27: 113728 | E27: 봉서산아이파크 | F27: 2018.1 | G27: 665 | H27: =2026-F27+1 | I27: 114A, 114B, 115C | J27: 114 | K27: 84 | L27: 34 | M27: 계단식 | N27: 3 | O27: 2 | P27: 431 | Q27: 35000 | R27: 32000 | S27: =Q27-R27 | T27: =R27/Q27 | U27: 46800 | V27: 36000 | W27: 계단식 | X27: 3 | Y27: 2 | Z27: 431 | AC27: =L27 | AF27: =AE27/AD27 | AG27: =AD27-AE27 | AH27: 2026.04 | AI27: 35000 | AJ27: =AI27-AD27 | AK27: =(AI27-AD27)/AD27 | AL27: =AJ27/AG27
A28: 신방동 | D28: 135648 | E28: 천안신방삼부르네상스 | F28: 2023.05 | G28: 830 | H28: =2026-F28+1 | I28: 111A | J28: 111 | K28: 84 | L28: 34 | M28: 계단식 | N28: 3 | O28: 2 | P28: 94 | Q28: 35000 | R28: 30000 | S28: =Q28-R28 | T28: =R28/Q28 | V28: 32230 | W28: 계단식 | X28: 3 | Y28: 2 | Z28: 94 | AC28: =L28 | AF28: =AE28/AD28 | AG28: =AD28-AE28 | AH28: 2026.04 | AI28: 35000 | AJ28: =AI28-AD28 | AK28: =(AI28-AD28)/AD28 | AL28: =AJ28/AG28
A29: 청당동 | D29: 116435 | E29: 청당코오롱하늘채 | F29: 2019.12 | G29: 1534 | H29: =2026-F29+1 | I29: 111 | J29: 111 | K29: 84 | L29: 34 | M29: 계단식 | N29: 3 | O29: 2 | P29: 354 | Q29: 35000 | R29: 28000 | S29: =Q29-R29 | T29: =R29/Q29 | U29: 50200 | V29: 33800 | W29: 계단식 | X29: 3 | Y29: 2 | Z29: 354 | AA29: 2020.09 | AB29: 0.04 | AC29: =L29 | AD29: 30112 | AE29: 25857 | AF29: =AE29/AD29 | AG29: =AD29-AE29 | AH29: 2026.04 | AI29: 35000 | AJ29: =AI29-AD29 | AK29: =(AI29-AD29)/AD29 | AL29: =AJ29/AG29
A30: 문화동 | D30: 126749 | E30: 천안역필하우스에듀시티1단지 | F30: 2022.04 | G30: 1532 | H30: =2026-F30+1 | I30: 98A, 102C | J30: 98 | K30: 73 | L30: 30 | M30: 계단식 | N30: 3 | O30: 2 | P30: 401 | Q30: 34000 | R30: 27500 | S30: =Q30-R30 | T30: =R30/Q30 | U30: 32000 | V30: 30000 | W30: 계단식 | X30: 3 | Y30: 2 | Z30: 401 | AC30: =L30 | AF30: =AE30/AD30 | AG30: =AD30-AE30 | AH30: 2026.04 | AI30: 34000 | AJ30: =AI30-AD30 | AK30: =(AI30-AD30)/AD30 | AL30: =AJ30/AG30
A31: 봉명동 | D31: 137226 | E31: 봉명역센트럴시티 | F31: 2025.01 | G31: 816 | H31: =2026-F31+1 | I31: 101B, 101A | J31: 101 | K31: 74 | L31: 31 | M31: 계단식 | N31: 3 | O31: 2 | P31: 288 | Q31: 34000 | R31: 27000 | S31: =Q31-R31 | T31: =R31/Q31 | W31: 계단식 | X31: 3 | Y31: 2 | Z31: 288 | AC31: =L31 | AF31: =AE31/AD31 | AG31: =AD31-AE31 | AH31: 2026.04 | AI31: 34000 | AJ31: =AI31-AD31 | AK31: =(AI31-AD31)/AD31 | AL31: =AJ31/AG31
A32: 신부동 | D32: 109735 | E32: 신부디이스트 | F32: 2018.05 | G32: 2144 | H32: =2026-F32+1 | I32: 100A1, 100B1, 100C | J32: 100 | K32: 74 | L32: 30 | M32: 계단식 | N32: 3 | O32: 2 | P32: 633 | Q32: 34000 | R32: 30000 | S32: =Q32-R32 | T32: =R32/Q32 | U32: 48000 | V32: 29250 | W32: 계단식 | X32: 3 | Y32: 2 | Z32: 633 | AA32: 2020.01 | AB32: 0.02 | AC32: =L32 | AD32: 27623 | AE32: 23750 | AF32: =AE32/AD32 | AG32: =AD32-AE32 | AH32: 2026.04 | AI32: 34000 | AJ32: =AI32-AD32 | AK32: =(AI32-AD32)/AD32 | AL32: =AJ32/AG32
A33: 청당동 | D33: 129755 | E33: 청당서희스타힐스 | F33: 2022.12 | G33: 741 | H33: =2026-F33+1 | I33: 98A, 98B | J33: 98 | K33: 74 | L33: 30 | M33: 계단식 | N33: 3 | O33: 2 | P33: 389 | Q33: 34000 | R33: 27000 | S33: =Q33-R33 | T33: =R33/Q33 | U33: 35500 | V33: 27150 | W33: 계단식 | X33: 3 | Y33: 2 | Z33: 389 | AC33: =L33 | AF33: =AE33/AD33 | AG33: =AD33-AE33 | AH33: 2026.04 | AI33: 34000 | AJ33: =AI33-AD33 | AK33: =(AI33-AD33)/AD33 | AL33: =AJ33/AG33
A34: 청당동 | D34: 151758 | E34: 천안롯데캐슬더청당 | F34: 2025.08 | G34: 1199 | H34: =2026-F34+1 | I34: 82A, 82B | J34: 82 | K34: 59 | L34: 25 | M34: 계단식 | N34: 3 | O34: 2 | P34: 145 | Q34: 34000 | R34: 23000 | S34: =Q34-R34 | T34: =R34/Q34 | W34: 계단식 | X34: 3 | Y34: 2 | Z34: 145 | AC34: =L34 | AF34: =AE34/AD34 | AG34: =AD34-AE34 | AH34: 2026.04 | AI34: 34000 | AJ34: =AI34-AD34 | AK34: =(AI34-AD34)/AD34 | AL34: =AJ34/AG34
A35: 청당동 | D35: 111627 | E35: 청당한양수자인블루시티 | F35: 2018.03 | G35: 999 | H35: =2026-F35+1 | I35: 113A, 114B | J35: 113 | K35: 84 | L35: 34 | M35: 계단식 | N35: 3 | O35: 2 | P35: 622 | Q35: 33000 | R35: 28000 | S35: =Q35-R35 | T35: =R35/Q35 | U35: 50000 | V35: 29000 | W35: 계단식 | X35: 3 | Y35: 2 | Z35: 622 | AC35: =L35 | AF35: =AE35/AD35 | AG35: =AD35-AE35 | AH35: 2026.04 | AI35: 33000 | AJ35: =AI35-AD35 | AK35: =(AI35-AD35)/AD35 | AL35: =AJ35/AG35
A36: 봉명동 | D36: 124679 | E36: e편한세상봉명아너리움 | F36: 2020.06 | G36: 459 | H36: =2026-F36+1 | I36: 109 | J36: 109 | K36: 79 | L36: 33 | M36: 계단식 | N36: 3 | O36: 2 | P36: 80 | Q36: 32500 | R36: 27000 | S36: =Q36-R36 | T36: =R36/Q36 | U36: 37500 | V36: 32000 | W36: 계단식 | X36: 3 | Y36: 2 | Z36: 80 | AA36: 2024.06 | AB36: 0.01 | AC36: =L36 | AD36: 34100 | AE36: 28000 | AF36: =AE36/AD36 | AG36: =AD36-AE36 | AH36: 2026.04 | AI36: 32500 | AJ36: =AI36-AD36 | AK36: =(AI36-AD36)/AD36 | AL36: =AJ36/AG36 | AV36: {=- 엑셀에 값 입력 후 생각정리}
A37: 신부동 | D37: 110256 | E37: 힐스테이트천안신부 | F37: 2017.08 | G37: 984 | H37: =2026-F37+1 | I37: 100 | J37: 100 | K37: 74 | L37: 30 | M37: 계단식 | N37: 3 | O37: 2 | P37: 337 | Q37: 32500 | R37: 26000 | S37: =Q37-R37 | T37: =R37/Q37 | U37: 44300 | V37: 30000 | W37: 계단식 | X37: 3 | Y37: 2 | Z37: 337 | AA37: 2020.02 | AB37: 0.01 | AC37: =L37 | AD37: 29512 | AE37: 23750 | AF37: =AE37/AD37 | AG37: =AD37-AE37 | AH37: 2026.04 | AI37: 32500 | AJ37: =AI37-AD37 | AK37: =(AI37-AD37)/AD37 | AL37: =AJ37/AG37
A38: 문화동 | D38: 126749 | E38: 천안역필하우스에듀시티1단지 | F38: 2022.04 | G38: 1532 | H38: =2026-F38+1 | I38: 83A, 84B | J38: 83 | K38: 59 | L38: 25 | M38: 계단식 | N38: 3 | O38: 2 | P38: 144 | Q38: 32000 | R38: 25000 | S38: =Q38-R38 | T38: =R38/Q38 | V38: 26000 | W38: 계단식 | X38: 3 | Y38: 2 | Z38: 144 | AC38: =L38 | AF38: =AE38/AD38 | AG38: =AD38-AE38 | AH38: 2026.04 | AI38: 32000 | AJ38: =AI38-AD38 | AK38: =(AI38-AD38)/AD38 | AL38: =AJ38/AG38
A39: 신부동 | D39: 152942 | E39: 더샵신부센트라 | F39: 2025.06 | G39: 592 | H39: =2026-F39+1 | I39: 82B, 85A | J39: 82 | K39: 59 | L39: 25 | M39: 계단식 | N39: 3 | O39: 2 | P39: 102 | Q39: 32000 | R39: - | S39: =Q39-R39 | T39: =R39/Q39 | W39: 계단식 | X39: 3 | Y39: 2 | Z39: 102 | AC39: =L39 | AF39: =AE39/AD39 | AG39: =AD39-AE39 | AH39: 2026.04 | AI39: 32000 | AJ39: =AI39-AD39 | AK39: =(AI39-AD39)/AD39 | AL39: =AJ39/AG39
A40: 신부동 | D40: 26534 | E40: 휴먼시아 | F40: 2009.09 | G40: 497 | H40: =2026-F40+1 | I40: 112A, 112B, 113C, 113D | J40: 112 | K40: 84 | L40: 34 | M40: 계단식 | N40: 3 | O40: 2 | P40: 351 | Q40: 32000 | R40: 28000 | S40: =Q40-R40 | T40: =R40/Q40 | U40: 42700 | V40: 30200 | W40: 계단식 | X40: 3 | Y40: 2 | Z40: 351 | AA40: 2021.09 | AB40: 0.01 | AC40: =L40 | AD40: 35275 | AE40: 30667 | AF40: =AE40/AD40 | AG40: =AD40-AE40 | AH40: 2026.04 | AI40: 32000 | AJ40: =AI40-AD40 | AK40: =(AI40-AD40)/AD40 | AL40: =AJ40/AG40
...

Sheet 부산 남구
B1: 상 | C1: 중
B2: 하
A3: 84 | B3: 선호도 | E3: 단지정보 (30평) | AH3: 투자결과
B4: 생활권 | C4: 생활권 내 | D4: 단지코드 | E4: 단지명 | F4: 사용승인일 | G4: 총세대수 | H4: 나이 | I4: 타입 | J4: 공급면적 | K4: 전용면적 | L4: 평형 | M4: 구조 | N4: 방수 | O4: 욕실수 | P4: 평형별 세대수 | Q4: 매 | R4: 전 | S4: 차 | T4: 전세가율 | U4: 전고 | V4: 전저 | W4: 계/복 | X4: 방 | Y4: 화 | Z4: 면적세대수 | AA4: 시기(년) | AB4: (전세가율80%이상인)기간 | AC4: 평형 | AD4: 매매가 | AE4: 전세가 | AF4: 전세가율 | AG4: 투자금 | AH4: 시기(년) | AI4: 매매가 | AJ4: 수익금 | AK4: 상승율 | AL4: 수익율
A5: 대연동 | D5: 4526 | E5: 대우그린1차 | F5: 1997.09 | G5: 691 | H5: =2026-F5+1 | J5: 83 | K5: 59 | L5: 25 | M5: 복도식 | N5: 3 | O5: 1 | P5: 263 | Q5: 145000 | S5: =Q5-R5 | T5: =R5/Q5 | U5: 19250 | V5: 17300
A6: 대연동 | D6: 161501 | E6: 더비치푸르지오써밋 | F6: 2025.05 | G6: 1384 | H6: =2026-F6+1 | K6: 84 | M6: 계단식 | N6: 3 | O6: 2 | P6: 438 | Q6: 145000 | R6: 79000 | S6: =Q6-R6 | T6: =R6/Q6
A7: 대연동 | D7: 161501 | E7: 더비치푸르지오써밋 | F7: 2025.05 | G7: 1384 | H7: =2026-F7+1 | J7: 101 | K7: 76 | L7: 31 | M7: 계단식 | N7: 3 | O7: 2 | P7: 156 | Q7: 130000 | R7: 65000 | S7: =Q7-R7 | T7: =R7/Q7
A8: 대연동 | D8: 161501 | E8: 더비치푸르지오써밋 | F8: 2025.05 | G8: 1384 | H8: =2026-F8+1 | K8: 59 | M8: 계단식 | N8: 3 | O8: 2 | P8: 556 | Q8: 105000 | R8: 50000 | S8: =Q8-R8 | T8: =R8/Q8
A9: 대연동 | D9: 105323 | E9: 대연힐스테이트푸르지오 | F9: 2013.05 | G9: 2100 | H9: =2026-F9+1 | K9: 84 | M9: 계단식 | N9: 3 | O9: 2 | P9: 1060 | Q9: 95000 | R9: 55000 | S9: =Q9-R9 | T9: =R9/Q9 | U9: 111000 | V9: 61500
A10: 대연동 | D10: 110738 | E10: 대연SK뷰힐스 | F10: 2018.07 | G10: 994 | H10: =2026-F10+1 | K10: 84 | M10: 계단식 | N10: 3 | O10: 2 | P10: 614 | Q10: 92000 | R10: 50000 | S10: =Q10-R10 | T10: =R10/Q10 | U10: 96000 | V10: 43600
A11: 대연동 | D11: 113686 | E11: 대연자이 | F11: 2019.03 | G11: 965 | H11: =2026-F11+1 | K11: 84 | M11: 계단식 | N11: 4 | O11: 2 | P11: 160 | Q11: 90000 | R11: 43500 | S11: =Q11-R11 | T11: =R11/Q11 | U11: 107200 | V11: 73500
A12: 용호동 | D12: 22443 | E12: GS하이츠자이 | F12: 2008.04 | G12: 1149 | H12: =2026-F12+1 | K12: 84 | M12: 계단식 | N12: 3 | O12: 2 | P12: 290 | Q12: 87000 | R12: 50000 | S12: =Q12-R12 | T12: =R12/Q12 | U12: 99000 | V12: 70000
A13: 대연동 | D13: 110738 | E13: 대연SK뷰힐스 | F13: 2018.07 | G13: 994 | H13: =2026-F13+1 | J13: 98 | K13: 74 | L13: 30 | M13: 계단식 | N13: 3 | O13: 2 | P13: 72 | Q13: 84000 | R13: 45000 | S13: =Q13-R13 | T13: =R13/Q13 | U13: 72700 | V13: 39000
A14: 대연동 | D14: 145347 | E14: 힐스테이트대연센트럴 | F14: 2024.05 | G14: 449 | H14: =2026-F14+1 | K14: 84 | M14: 계단식 | N14: 3 | O14: 2 | P14: 109 | Q14: 82500 | R14: 52500 | S14: =Q14-R14 | T14: =R14/Q14
A15: 대연동 | D15: 113686 | E15: 대연자이 | F15: 2019.03 | G15: 965 | H15: =2026-F15+1 | J15: 95 | K15: 72 | L15: 29 | M15: 계단식 | N15: 3 | O15: 2 | P15: 54 | Q15: 82000 | R15: 43000 | S15: =Q15-R15 | T15: =R15/Q15 | U15: 90500 | V15: 65000
A16: 대연동 | D16: 105323 | E16: 대연힐스테이트푸르지오 | F16: 2013.05 | G16: 2100 | H16: =2026-F16+1 | J16: 80 | K16: 59 | L16: 24 | M16: 계단식 | N16: 3 | O16: 2 | P16: 93 | Q16: 79000 | R16: 39000 | S16: =Q16-R16 | T16: =R16/Q16 | U16: 75100 | V16: 58000
A17: 대연동 | D17: 145347 | E17: 힐스테이트대연센트럴 | F17: 2024.05 | G17: 449 | H17: =2026-F17+1 | K17: 74 | M17: 계단식 | N17: 3 | O17: 2 | P17: 177 | Q17: 77000 | R17: 42000 | S17: =Q17-R17 | T17: =R17/Q17
A18: 문현동 | D18: 114815 | E18: 문현경동리인1단지 | F18: 2020.07 | G18: 469 | H18: =2026-F18+1 | K18: 84 | M18: 계단식 | N18: 3 | O18: 2 | P18: 182 | Q18: 75000 | R18: 34000 | S18: =Q18-R18 | T18: =R18/Q18 | U18: 69300 | V18: 42700
A19: 대연동 | D19: 110738 | E19: 대연SK뷰힐스 | F19: 2018.07 | G19: 994 | H19: =2026-F19+1 | K19: 59 | M19: 계단식 | N19: 3 | O19: 2 | P19: 226 | Q19: 73000 | R19: 38000 | S19: =Q19-R19 | T19: =R19/Q19 | U19: 71900 | V19: 44000
A20: 대연동 | D20: 133976 | E20: 대연푸르지오클라센트 | F20: 2024.08 | G20: 1057 | H20: =2026-F20+1 | K20: 84 | M20: 계단식 | N20: 4 | O20: 2 | P20: 175 | Q20: 72000 | R20: 45000 | S20: =Q20-R20 | T20: =R20/Q20
A21: 대연동 | D21: 109359 | E21: 대연롯데캐슬레전드 | F21: 2018.02 | G21: 3149 | H21: =2026-F21+1 | K21: 84 | M21: 계단식 | N21: 3 | O21: 2 | P21: 1634 | Q21: 71000 | R21: 48000 | S21: =Q21-R21 | T21: =R21/Q21 | U21: 96000 | V21: 43600
A22: 대연동 | D22: 9861 | E22: 대연푸르지오 | F22: 2005.01 | G22: 678 | H22: =2026-F22+1 | J22: 107 | K22: 84 | L22: 32 | M22: 계단식 | N22: 3 | O22: 2 | P22: 100 | Q22: 71000 | R22: 40000 | S22: =Q22-R22 | T22: =R22/Q22 | U22: 43500 | V22: 28000
A23: 대연동 | D23: 104716 | E23: 대연롯데캐슬 | F23: 2015.01 | G23: 564 | H23: =2026-F23+1 | K23: 84 | M23: 계단식 | N23: 3 | O23: 2 | P23: 300 | Q23: 69000 | R23: 55000 | S23: =Q23-R23 | T23: =R23/Q23 | U23: 86000 | V23: 58000
A24: 대연동 | D24: 145347 | E24: 힐스테이트대연센트럴 | F24: 2024.05 | G24: 449 | H24: =2026-F24+1 | J24: 82 | K24: 59 | L24: 25 | M24: 계단식 | N24: 3 | O24: 2 | P24: 163 | Q24: 69000 | R24: 37000 | S24: =Q24-R24 | T24: =R24/Q24 | V24: 42945
A25: 대연동 | D25: 113686 | E25: 대연자이 | F25: 2019.03 | G25: 965 | H25: =2026-F25+1 | K25: 59 | M25: 계단식 | N25: 3 | O25: 2 | P25: 509 | Q25: 67000 | R25: 38000 | S25: =Q25-R25 | T25: =R25/Q25 | U25: 80000 | V25: 47500
A26: 대연동 | D26: 104716 | E26: 대연롯데캐슬 | F26: 2015.01 | G26: 564 | H26: =2026-F26+1 | J26: 84 | K26: 59 | L26: 25 | M26: 계단식 | N26: 3 | O26: 2 | P26: 42 | Q26: 64800 | R26: 34000 | S26: =Q26-R26 | T26: =R26/Q26 | U26: 70000 | V26: 47800
A27: 대연동 | D27: 109359 | E27: 대연롯데캐슬레전드 | F27: 2018.02 | G27: 3149 | H27: =2026-F27+1 | K27: 59 | M27: 계단식 | N27: 3 | O27: 2 | P27: 516 | Q27: 64000 | R27: 40000 | S27: =Q27-R27 | T27: =R27/Q27 | U27: 71900 | V27: 44000
A28: 대연동 | D28: 133976 | E28: 대연푸르지오클라센트 | F28: 2024.08 | G28: 1057 | H28: =2026-F28+1 | K28: 74 | M28: 계단식 | N28: 3 | O28: 2 | P28: 379 | Q28: 62000 | R28: 38000 | S28: =Q28-R28 | T28: =R28/Q28
A29: 대연동 | D29: 10107 | E29: 대연동원로얄듀크2차 | F29: 2005.02 | G29: 417 | H29: =2026-F29+1 | J29: 109 | K29: 84 | L29: 33 | M29: 계단식 | N29: 3 | O29: 2 | P29: 177 | Q29: 61000 | R29: 31000 | S29: =Q29-R29 | T29: =R29/Q29 | U29: 70500 | V29: 48500
A30: 문현동 | D30: 112774 | E30: 국제금융시티문현베스티움 | F30: 2019.04 | G30: 743 | H30: =2026-F30+1 | K30: 84 | M30: 계단식 | N30: 3 | O30: 2 | P30: 252 | Q30: 60000 | R30: 39000 | S30: =Q30-R30 | T30: =R30/Q30 | U30: 80000 | V30: 48500
A31: 문현동 | D31: 125376 | E31: 대연양우내안애퍼스트 | F31: 2022.02 | G31: 560 | H31: =2026-F31+1 | K31: 84 | M31: 계단식 | N31: 3 | O31: 2 | P31: 391 | Q31: 60000 | R31: 45000 | S31: =Q31-R31 | T31: =R31/Q31 | U31: 55908 | V31: 40000
A32: 대연동 | D32: 9861 | E32: 대연푸르지오 | F32: 2005.01 | G32: 678 | H32: =2026-F32+1 | J32: 93 | K32: 73 | L32: 28 | M32: 계단식 | N32: 3 | O32: 2 | P32: 98 | Q32: 58000 | R32: 42000 | S32: =Q32-R32 | T32: =R32/Q32 | U32: 72500 | V32: 53000
A33: 대연동 | D33: 133976 | E33: 대연푸르지오클라센트 | F33: 2024.08 | G33: 1057 | H33: =2026-F33+1 | K33: 59 | M33: 계단식 | N33: 3 | O33: 2 | P33: 270 | Q33: 56000 | R33: 36000 | S33: =Q33-R33 | T33: =R33/Q33 | V33: 42945
A34: 용호동 | D34: 9709 | E34: LG메트로시티4-1차 | F34: 2003.08 | G34: 1391 | H34: =2026-F34+1 | K34: 84 | M34: 계단식 | N34: 3 | O34: 2 | P34: 134 | Q34: 56000 | R34: 35000 | S34: =Q34-R34 | T34: =R34/Q34 | U34: 77000 | V34: 35000
A35: 문현동 | D35: 125376 | E35: 대연양우내안애퍼스트 | F35: 2022.02 | G35: 560 | H35: =2026-F35+1 | K35: 59 | M35: 계단식 | N35: 3 | O35: 2 | P35: 169 | Q35: 55000 | R35: 37000 | S35: =Q35-R35 | T35: =R35/Q35 | U35: 37000 | V35: 32000
A36: 용호동 | D36: 9708 | E36: LG메트로시티3차 | F36: 2002.11 | G36: 922 | H36: =2026-F36+1 | J36: 108 | K36: 84 | L36: 33 | M36: 계단식 | N36: 3 | O36: 2 | P36: 150 | Q36: 55000 | R36: 35000 | S36: =Q36-R36 | T36: =R36/Q36 | U36: 77900 | V36: 47300
A37: 용호동 | D37: 9710 | E37: LG메트로시티4-2차 | F37: 2003.08 | G37: 1258 | H37: =2026-F37+1 | K37: 84 | M37: 계단식 | N37: 3 | O37: 2 | P37: 198 | Q37: 55000 | R37: 35000 | S37: =Q37-R37 | T37: =R37/Q37 | U37: 77000 | V37: 35000
A38: 용호동 | D38: 127894 | E38: 데시앙해링턴플레이스파크시티 | F38: 2023.05 | G38: 1725 | H38: =2026-F38+1 | K38: 84 | M38: 계단식 | N38: 3 | O38: 2 | P38: 309 | Q38: 55000 | R38: 39000 | S38: =Q38-R38 | T38: =R38/Q38 | V38: 51000
A39: 용호동 | D39: 9710 | E39: LG메트로시티4-2차 | F39: 2003.08 | G39: 1258 | H39: =2026-F39+1 | K39: 85 | M39: 계단식 | N39: 3 | O39: 2 | P39: 200 | Q39: 53000 | R39: 35000 | S39: =Q39-R39 | T39: =R39/Q39 | U39: 77000 | V39: 35000
A40: 대연동 | D40: 110440 | E40: 대연파크푸르지오 | F40: 2018.06 | G40: 1422 | H40: =2026-F40+1 | K40: 84 | M40: 계단식 | N40: 3 | O40: 2 | P40: 668 | Q40: 52000 | R40: 38000 | S40: =Q40-R40 | T40: =R40/Q40 | U40: 80000 | V40: 45200
...

Sheet 부산수영구
B1: 상 | C1: 중
B2: 하
A3: 84 | B3: 선호도 | E3: 단지정보 (30평) | AD3: 투자결과
B4: 생활권 | C4: 생활권 내 | D4: 단지코드 | E4: 단지명 | F4: 사용승인일 | G4: 총세대수 | H4: 나이 | I4: 타입 | J4: 공급면적 | K4: 전용면적 | L4: 평형 | M4: 구조 | N4: 방수 | O4: 욕실수 | P4: 평형별 세대수 | Q4: 매 | R4: 전 | S4: 차 | T4: 전세가율 | U4: 전고 | V4: 전저 | W4: 시기(년) | X4: (전세가율80%이상인)기간 | Y4: 평형 | Z4: 매매가 | AA4: 전세가 | AB4: 전세가율 | AC4: 투자금 | AD4: 시기(년) | AE4: 매매가 | AF4: 수익금 | AG4: 상승율 | AH4: 수익율
A5: 남천동 | D5: 154302 | E5: 남천자이 | F5: 2023.01 | G5: 913 | H5: =2026-F5+1 | K5: 84 | M5: 계단식 | N5: 3 | O5: 2 | P5: 547 | Q5: 160000 | R5: 65000 | S5: =Q5-R5 | T5: =R5/Q5 | V5: 112000
A6: 남천동 | D6: 154302 | E6: 남천자이 | F6: 2023.01 | G6: 913 | H6: =2026-F6+1 | J6: 102 | K6: 77 | L6: 31 | M6: 계단식 | N6: 3 | O6: 2 | P6: 24 | Q6: 150000 | R6: 55000 | S6: =Q6-R6 | T6: =R6/Q6 | V6: 117500
A7: 남천동 | D7: 154302 | E7: 남천자이 | F7: 2023.01 | G7: 913 | H7: =2026-F7+1 | K7: 74 | M7: 계단식 | N7: 3 | O7: 2 | P7: 88 | Q7: 125000 | R7: 55000 | S7: =Q7-R7 | T7: =R7/Q7 | V7: 93000
A8: 남천동 | D8: 127133 | E8: 더샵남천프레스티지 | F8: 2022.09 | G8: 975 | H8: =2026-F8+1 | K8: 84 | M8: 계단식 | N8: 3 | O8: 2 | P8: 504 | Q8: 125000 | R8: 65000 | S8: =Q8-R8 | T8: =R8/Q8 | U8: 129000 | V8: 71000
A9: 남천동 | D9: 7770 | E9: 삼익비치타운 | F9: 1979.1 | G9: 3060 | H9: =2026-F9+1 | K9: 84 | M9: 복도식 | N9: 3 | O9: 1 | P9: 504 | Q9: 102000 | R9: 16000 | S9: =Q9-R9 | T9: =R9/Q9 | U9: 160000 | V9: 99000
A10: 광안동 | D10: 119208 | E10: 광안자이 | F10: 2020.08 | G10: 971 | H10: =2026-F10+1 | K10: 84 | M10: 계단식 | N10: 3 | O10: 2 | P10: 588 | Q10: 99000 | R10: 60000 | S10: =Q10-R10 | T10: =R10/Q10 | U10: 144500 | V10: 74000
A11: 남천동 | D11: 24896 | E11: 남천코오롱하늘채골든비치 | F11: 2009.01 | G11: 987 | H11: =2026-F11+1 | J11: 112 | K11: 84 | L11: 34 | M11: 복합식 | N11: 3 | O11: 2 | P11: 149 | Q11: 98000 | R11: 45000 | S11: =Q11-R11 | T11: =R11/Q11 | U11: 75000 | V11: 71000
A12: 남천동 | D12: 114752 | E12: 남천금호어울림더비치 | F12: 2019.07 | G12: 421 | H12: =2026-F12+1 | K12: 84 | M12: 계단식 | N12: 3 | O12: 2 | P12: 345 | Q12: 96000 | R12: 60000 | S12: =Q12-R12 | T12: =R12/Q12 | U12: 110000 | V12: 72500
A13: 수영동 | D13: 7914 | E13: 현대 | F13: 1988.04 | G13: 1180 | H13: =2026-F13+1 | J13: 102 | K13: 84 | L13: 31 | M13: 계단식 | N13: 3 | O13: 2 | P13: 450 | Q13: 95000 | R13: 25000 | S13: =Q13-R13 | T13: =R13/Q13 | U13: 131500 | V13: 65000
A14: 남천동 | D14: 154302 | E14: 남천자이 | F14: 2023.01 | G14: 913 | H14: =2026-F14+1 | K14: 59 | M14: 계단식 | N14: 3 | O14: 2 | P14: 116 | Q14: 93000 | R14: 43000 | S14: =Q14-R14 | T14: =R14/Q14 | V14: 76000
A15: 남천동 | D15: 7717 | E15: 뉴비치 | F15: 1986.05 | G15: 990 | H15: =2026-F15+1 | J15: 101 | K15: 84 | L15: 31 | M15: 계단식 | N15: 3 | O15: 2 | P15: 210 | Q15: 93000 | R15: 32000 | S15: =Q15-R15 | T15: =R15/Q15 | U15: 134500 | V15: 78300
A16: 남천동 | D16: 127133 | E16: 더샵남천프레스티지 | F16: 2022.09 | G16: 975 | H16: =2026-F16+1 | K16: 59 | M16: 계단식 | N16: 3 | O16: 2 | P16: 178 | Q16: 92000 | R16: 48000 | S16: =Q16-R16 | T16: =R16/Q16 | V16: 70000
A17: 남천동 | D17: 7770 | E17: 삼익비치타운 | F17: 1979.1 | G17: 3060 | H17: =2026-F17+1 | J17: 98 | K17: 73 | L17: 30 | M17: 복도식 | N17: 3 | O17: 1 | P17: 516 | Q17: 92000 | R17: 9000 | S17: =Q17-R17 | T17: =R17/Q17 | U17: 143700 | V17: 88000
A18: 광안동 | D18: 104037 | E18: 부산광안쌍용예가디오션 | F18: 2014.11 | G18: 928 | H18: =2026-F18+1 | J18: 85 | K18: 59 | L18: 26 | M18: 계단식 | N18: 3 | O18: 2 | P18: 39 | Q18: 90000 | R18: 45000 | S18: =Q18-R18 | T18: =R18/Q18 | U18: 90000 | V18: 73000
A19: 광안동 | D19: 119208 | E19: 광안자이 | F19: 2020.08 | G19: 971 | H19: =2026-F19+1 | J19: 104 | K19: 73 | L19: 31 | M19: 계단식 | N19: 3 | O19: 2 | P19: 226 | Q19: 88000 | R19: 47000 | S19: =Q19-R19 | T19: =R19/Q19 | U19: 96500 | V19: 65000
A20: 남천동 | D20: 7770 | E20: 삼익비치타운 | F20: 1979.1 | G20: 3060 | H20: =2026-F20+1 | K20: 61 | M20: 복도식 | N20: 3 | O20: 1 | P20: 168 | Q20: 88000 | S20: =Q20-R20 | T20: =R20/Q20 | U20: 128000 | V20: 71000
A21: 남천동 | D21: 7717 | E21: 뉴비치 | F21: 1986.05 | G21: 990 | H21: =2026-F21+1 | J21: 91 | K21: 75 | L21: 28 | M21: 계단식 | N21: 3 | O21: 1 | P21: 150 | Q21: 86000 | R21: 25000 | S21: =Q21-R21 | T21: =R21/Q21 | U21: 110000 | V21: 74200
A22: 광안동 | D22: 119208 | E22: 광안자이 | F22: 2020.08 | G22: 971 | H22: =2026-F22+1 | J22: 87 | K22: 59 | L22: 26 | M22: 계단식 | N22: 3 | O22: 2 | P22: 72 | Q22: 85000 | S22: =Q22-R22 | T22: =R22/Q22 | U22: 76000 | V22: 68000
A23: 민락동 | D23: 103401 | E23: 부산더샵센텀포레 | F23: 2014.07 | G23: 1006 | H23: =2026-F23+1 | K23: 84 | M23: 계단식 | N23: 3 | O23: 2 | P23: 550 | Q23: 85000 | R23: 52000 | S23: =Q23-R23 | T23: =R23/Q23 | U23: 109000 | V23: 57000
A24: 민락동 | D24: 108274 | E24: 센텀비스타동원 | F24: 2017.07 | G24: 840 | H24: =2026-F24+1 | K24: 84 | M24: 계단식 | N24: 3 | O24: 2 | P24: 661 | Q24: 85000 | R24: 49000 | S24: =Q24-R24 | T24: =R24/Q24 | U24: 109500 | V24: 56000
A25: 민락동 | D25: 117979 | E25: e편한세상오션테라스3단지 | F25: 2020.01 | G25: 316 | H25: =2026-F25+1 | K25: 84 | M25: 계단식 | N25: 3 | O25: 2 | P25: 156 | Q25: 83000 | R25: 45000 | S25: =Q25-R25 | T25: =R25/Q25 | U25: 93000 | V25: 72750
A26: 민락동 | D26: 103401 | E26: 부산더샵센텀포레 | F26: 2014.07 | G26: 1006 | H26: =2026-F26+1 | J26: 85 | K26: 59 | L26: 26 | M26: 계단식 | N26: 3 | O26: 2 | P26: 110 | Q26: 78000 | R26: 35000 | S26: =Q26-R26 | T26: =R26/Q26 | U26: 65000 | V26: 58000
A27: 남천동 | D27: 7770 | E27: 삼익비치타운 | F27: 1979.1 | G27: 3060 | H27: =2026-F27+1 | K27: 60 | M27: 복도식 | N27: 3 | O27: 1 | P27: 504 | Q27: 77000 | R27: 10000 | S27: =Q27-R27 | T27: =R27/Q27 | U27: 128000 | V27: 71000
A28: 수영동 | D28: 7914 | E28: 현대 | F28: 1988.04 | G28: 1180 | H28: =2026-F28+1 | K28: 68 | M28: 계단식 | N28: 3 | O28: 1 | P28: 420 | Q28: 76000 | R28: 21000 | S28: =Q28-R28 | T28: =R28/Q28 | U28: 105000 | V28: 70700
A29: 수영동 | D29: 10383 | E29: 수영협성르네상스타운 | F29: 2004.07 | G29: 684 | H29: =2026-F29+1 | K29: 84 | M29: 계단식 | N29: 3 | O29: 2 | P29: 384 | Q29: 75000 | R29: 40000 | S29: =Q29-R29 | T29: =R29/Q29 | U29: 92000 | V29: 58000
A30: 민락동 | D30: 117980 | E30: e편한세상오션테라스4단지 | F30: 2020.01 | G30: 308 | H30: =2026-F30+1 | K30: 84 | M30: 계단식 | N30: 3 | O30: 2 | P30: 152 | Q30: 73000 | R30: 50000 | S30: =Q30-R30 | T30: =R30/Q30 | U30: 162000 | V30: 75000
A31: 망미동 | D31: 111463 | E31: 수영SK뷰1단지 | F31: 2019.06 | G31: 1147 | H31: =2026-F31+1 | J31: 101 | K31: 73 | L31: 31 | M31: 계단식 | N31: 3 | O31: 2 | P31: 70 | Q31: 70000 | R31: 37000 | S31: =Q31-R31 | T31: =R31/Q31 | U31: 75000 | V31: 60000
A32: 망미동 | D32: 111463 | E32: 수영SK뷰1단지 | F32: 2019.06 | G32: 1147 | H32: =2026-F32+1 | J32: 116 | K32: 84 | L32: 35 | M32: 계단식 | N32: 4 | O32: 2 | P32: 594 | Q32: 69000 | R32: 40000 | S32: =Q32-R32 | T32: =R32/Q32 | U32: 87500 | V32: 51000
A33: 수영동 | D33: 7914 | E33: 현대 | F33: 1988.04 | G33: 1180 | H33: =2026-F33+1 | J33: 69 | K33: 52 | L33: 21 | M33: 복도식 | N33: 2 | O33: 1 | P33: 167 | Q33: 65000 | R33: 18000 | S33: =Q33-R33 | T33: =R33/Q33 | U33: 87200 | V33: 59000
A34: 남천동 | D34: 7717 | E34: 뉴비치 | F34: 1986.05 | G34: 990 | H34: =2026-F34+1 | J34: 62 | K34: 42 | L34: 19 | M34: 복도식 | N34: 2 | O34: 1 | P34: 135 | Q34: 63000 | R34: 18000 | S34: =Q34-R34 | T34: =R34/Q34 | U34: 79900 | V34: 48000
A35: 망미동 | D35: 19305 | E35: 더샵파크리치 | F35: 2007.09 | G35: 862 | H35: =2026-F35+1 | J35: 114 | K35: 84 | L35: 34 | M35: 계단식 | N35: 3 | O35: 2 | P35: 96 | Q35: 63000 | R35: 32000 | S35: =Q35-R35 | T35: =R35/Q35 | U35: 74800 | V35: 56500
A36: 민락동 | D36: 108276 | E36: e편한세상광안비치 | F36: 2016.09 | G36: 396 | H36: =2026-F36+1 | K36: 84 | M36: 계단식 | N36: 3 | O36: 2 | P36: 396 | Q36: 63000 | R36: 43000 | S36: =Q36-R36 | T36: =R36/Q36 | U36: 101500 | V36: 59500
A37: 남천동 | D37: 7770 | E37: 삼익비치타운 | F37: 1979.1 | G37: 3060 | H37: =2026-F37+1 | K37: 41 | M37: 복도식 | N37: 2 | O37: 1 | P37: 264 | Q37: 61500 | R37: 8000 | S37: =Q37-R37 | T37: =R37/Q37 | U37: 105000 | V37: 59000
A38: 수영동 | D38: 103803 | E38: 수영강동원로얄듀크 | F38: 2014.02 | G38: 423 | H38: =2026-F38+1 | K38: 84 | M38: 계단식 | N38: 3 | O38: 2 | P38: 191 | Q38: 61000 | R38: 37000 | S38: =Q38-R38 | T38: =R38/Q38 | U38: 66500 | V38: 60000
A39: 민락동 | D39: 11792 | E39: 롯데캐슬자이언트 | F39: 2003.11 | G39: 591 | H39: =2026-F39+1 | J39: 110 | K39: 84 | L39: 33 | M39: 계단식 | N39: 3 | O39: 2 | P39: 196 | Q39: 59000 | R39: 35000 | S39: =Q39-R39 | T39: =R39/Q39 | U39: 79000 | V39: 50000
A40: 남천동 | D40: 7717 | E40: 뉴비치 | F40: 1986.05 | G40: 990 | H40: =2026-F40+1 | J40: 55 | K40: 41 | L40: 17 | M40: 복도식 | N40: 2 | O40: 1 | P40: 195 | Q40: 58000 | R40: 16000 | S40: =Q40-R40 | T40: =R40/Q40 | U40: 74000 | V40: 48000
...

Sheet 창원성산구
B1: 상 | C1: 중
B2: 하
A3: 84 | B3: 선호도 | E3: 단지정보 (30평) | AH3: 투자결과
B4: 생활권 | C4: 생활권 내 | D4: 단지코드 | E4: 단지명 | F4: 사용승인일 | G4: 총세대수 | H4: 나이 | I4: 타입 | J4: 공급면적 | K4: 전용면적 | L4: 평형 | M4: 구조 | N4: 방수 | O4: 욕실수 | P4: 평형별 세대수 | Q4: 매 | R4: 전 | S4: 차 | T4: 전세가율 | U4: 전고 | V4: 전저 | W4: 계/복 | X4: 방 | Y4: 화 | Z4: 면적세대수 | AA4: 시기(년) | AB4: (전세가율80%이상인)기간 | AC4: 평형 | AD4: 매매가 | AE4: 전세가 | AF4: 전세가율 | AG4: 투자금 | AH4: 시기(년) | AI4: 매매가 | AJ4: 수익금 | AK4: 상승율 | AL4: 수익율
A5: 가음동 | D5: 16761 | E5: 은아 | F5: 1987.12 | G5: 500 | H5: =2026-F5+1 | J5: 59 | K5: 49 | L5: 18 | M5: 계단식 | N5: 2 | O5: 1 | P5: 500 | U5: 2.9 | V5: 1.9
A6: 가음동 | D6: 112175 | E6: 창원가음정한림풀에버 | F6: 2014.07 | G6: 266 | H6: =2026-F6+1 | J6: 90 | K6: 64 | L6: 27 | M6: 계단식 | N6: 3 | O6: 2 | P6: 78 | U6: 5.7 | V6: 4.23
A7: 가음동 | D7: 112175 | E7: 창원가음정한림풀에버 | F7: 2014.07 | G7: 266 | H7: =2026-F7+1 | J7: 112 | K7: 84 | L7: 34 | M7: 계단식 | N7: 3 | O7: 2 | P7: 188 | U7: 6.3 | V7: 5.02
A8: 가음동 | D8: 109672 | E8: 창원가음한화꿈에그린 | F8: 2017.07 | G8: 749 | H8: =2026-F8+1 | J8: 79 | K8: 59 | L8: 24 | M8: 계단식 | N8: 3 | O8: 2 | P8: 88 | U8: 5.9 | V8: 4.28
A9: 가음동 | D9: 109672 | E9: 창원가음한화꿈에그린 | F9: 2017.07 | G9: 749 | H9: =2026-F9+1 | J9: 94 | K9: 70 | L9: 28 | M9: 계단식 | N9: 3 | O9: 2 | P9: 54 | U9: 5.99 | V9: 4.8
A10: 가음동 | D10: 109672 | E10: 창원가음한화꿈에그린 | F10: 2017.07 | G10: 749 | H10: =2026-F10+1 | J10: 112 | K10: 84 | L10: 34 | M10: 계단식 | N10: 3 | O10: 2 | P10: 495 | U10: 7.75 | V10: 5.2
A11: 가음동 | D11: 109672 | E11: 창원가음한화꿈에그린 | F11: 2017.07 | G11: 749 | H11: =2026-F11+1 | J11: 131 | K11: 100 | L11: 40 | M11: 계단식 | N11: 4 | O11: 2 | P11: 85 | U11: 8.6 | V11: 6.25
A12: 가음동 | D12: 109672 | E12: 창원가음한화꿈에그린 | F12: 2017.07 | G12: 749 | H12: =2026-F12+1 | J12: 144 | K12: 110 | L12: 44 | M12: 계단식 | N12: 4 | O12: 2 | P12: 27
A13: 가음동 | D13: 109271 | E13: 창원더샵센트럴파크1단지 | F13: 2017.04 | G13: 386 | H13: =2026-F13+1 | J13: 107 | K13: 84 | L13: 32 | M13: 계단식 | N13: 3 | O13: 2 | P13: 196 | U13: 7.6 | V13: 5.1
A14: 가음동 | D14: 109271 | E14: 창원더샵센트럴파크1단지 | F14: 2017.04 | G14: 386 | H14: =2026-F14+1 | J14: 125 | K14: 98 | L14: 38 | M14: 계단식 | N14: 4 | O14: 2 | P14: 98 | U14: 7.8 | V14: 6.06
A15: 가음동 | D15: 109271 | E15: 창원더샵센트럴파크1단지 | F15: 2017.04 | G15: 386 | H15: =2026-F15+1 | J15: 147 | K15: 117 | L15: 44 | M15: 계단식 | N15: 4 | O15: 2 | P15: 92 | U15: 9 | V15: 7.98
A16: 가음동 | D16: 109272 | E16: 창원더샵센트럴파크2단지 | F16: 2017.04 | G16: 624 | H16: =2026-F16+1 | J16: 78 | K16: 59 | L16: 24 | M16: 계단식 | N16: 3 | O16: 2 | P16: 100 | U16: 5.89 | V16: 4.55
A17: 가음동 | D17: 109272 | E17: 창원더샵센트럴파크2단지 | F17: 2017.04 | G17: 624 | H17: =2026-F17+1 | J17: 110 | K17: 84 | L17: 33 | M17: 계단식 | N17: 3 | O17: 2 | P17: 424 | U17: 7.75 | V17: 5.4
A18: 가음동 | D18: 109272 | E18: 창원더샵센트럴파크2단지 | F18: 2017.04 | G18: 624 | H18: =2026-F18+1 | J18: 129 | K18: 98 | L18: 39 | M18: 계단식 | N18: 4 | O18: 2 | P18: 100 | U18: 8.2 | V18: 6.4
A19: 가음동 | D19: 109273 | E19: 창원더샵센트럴파크3단지 | F19: 2017.04 | G19: 448 | H19: =2026-F19+1 | J19: 93 | K19: 71 | L19: 28 | M19: 계단식 | N19: 3 | O19: 2 | P19: 160 | U19: 6.48 | V19: 4.82
A20: 가음동 | D20: 109273 | E20: 창원더샵센트럴파크3단지 | F20: 2017.04 | G20: 448 | H20: =2026-F20+1 | J20: 110 | K20: 84 | L20: 33 | M20: 계단식 | N20: 3 | O20: 2 | P20: 236 | U20: 7.6 | V20: 5.55
A21: 가음동 | D21: 109273 | E21: 창원더샵센트럴파크3단지 | F21: 2017.04 | G21: 448 | H21: =2026-F21+1 | J21: 129 | K21: 98 | L21: 39 | M21: 계단식 | N21: 4 | O21: 2 | P21: 52 | U21: 8.2 | V21: 5.5
A22: 가음동 | D22: 118728 | E22: 창원센텀푸르지오 | F22: 2018.01 | G22: 975 | H22: =2026-F22+1 | J22: 84 | K22: 59 | L22: 25 | M22: 계단식 | N22: 3 | O22: 2 | P22: 224 | U22: 6.15 | V22: 4.2
A23: 가음동 | D23: 118728 | E23: 창원센텀푸르지오 | F23: 2018.01 | G23: 975 | H23: =2026-F23+1 | J23: 98 | K23: 73 | L23: 30 | M23: 계단식 | N23: 3 | O23: 2 | P23: 216 | U23: 7.1 | V23: 4.9
A24: 가음동 | D24: 118728 | E24: 창원센텀푸르지오 | F24: 2018.01 | G24: 975 | H24: =2026-F24+1 | J24: 111 | K24: 84 | L24: 34 | M24: 계단식 | N24: 4 | O24: 2 | P24: 491 | U24: 8.2 | V24: 5.9
A25: 가음동 | D25: 118728 | E25: 창원센텀푸르지오 | F25: 2018.01 | G25: 975 | H25: =2026-F25+1 | J25: 131 | K25: 101 | L25: 40 | M25: 계단식 | N25: 4 | O25: 2 | P25: 44 | U25: 8.8 | V25: 7.05
A26: 가음동 | D26: 151284 | E26: 창원자이시그니처 | F26: 2025.04 | G26: 786 | H26: =2026-F26+1 | J26: 81 | K26: 59 | L26: 25 | M26: 계단식 | N26: 3 | O26: 2 | P26: 279
A27: 가음동 | D27: 151284 | E27: 창원자이시그니처 | F27: 2025.04 | G27: 786 | H27: =2026-F27+1 | J27: 99 | K27: 75 | L27: 30 | M27: 계단식 | N27: 3 | O27: 2 | P27: 239
A28: 가음동 | D28: 151284 | E28: 창원자이시그니처 | F28: 2025.04 | G28: 786 | H28: =2026-F28+1 | J28: 110 | K28: 84 | L28: 33 | M28: 계단식 | N28: 3 | O28: 2 | P28: 268
A29: 가음정동 | D29: 7600 | E29: 소라 | F29: 1990.01 | G29: 348 | H29: =2026-F29+1 | J29: 83 | K29: 59 | L29: 25 | M29: 복도식 | N29: 3 | O29: 1 | P29: 252 | U29: 1.38 | V29: 0.92
A30: 가음정동 | D30: 7600 | E30: 소라 | F30: 1990.01 | G30: 348 | H30: =2026-F30+1 | J30: 102 | K30: 84 | L30: 31 | M30: 계단식 | N30: 3 | O30: 2 | P30: 96 | U30: 1.83 | V30: 1.75
A31: 남산동 | D31: 115783 | E31: 남산효성해링턴플레이스 | F31: 2018.06 | G31: 460 | H31: =2026-F31+1 | J31: 79 | K31: 59 | L31: 24 | M31: 계단식 | N31: 3 | O31: 2 | P31: 222 | U31: 2.7 | V31: 2.32
A32: 남산동 | D32: 115783 | E32: 남산효성해링턴플레이스 | F32: 2018.06 | G32: 460 | H32: =2026-F32+1 | J32: 101 | K32: 79 | L32: 31 | M32: 계단식 | N32: 3 | O32: 2 | P32: 112 | U32: 3.18 | V32: 2.75
A33: 남산동 | D33: 115783 | E33: 남산효성해링턴플레이스 | F33: 2018.06 | G33: 460 | H33: =2026-F33+1 | J33: 108 | K33: 84 | L33: 33 | M33: 계단식 | N33: 3 | O33: 2 | P33: 126 | U33: 3.34 | V33: 3
A34: 남산동 | D34: 7616 | E34: 대우1차 | F34: 1991.09 | G34: 636 | H34: =2026-F34+1 | J34: 51 | K34: 37 | L34: 15 | M34: 복도식 | N34: 2 | O34: 1 | P34: 61 | U34: 0.74 | V34: 0.55
A35: 남산동 | D35: 7616 | E35: 대우1차 | F35: 1991.09 | G35: 636 | H35: =2026-F35+1 | J35: 66 | K35: 48 | L35: 20 | M35: 복도식 | N35: 3 | O35: 1 | P35: 60 | U35: 1.1 | V35: 0.8
A36: 남산동 | D36: 7610 | E36: 대우2차 | F36: 1991.09 | G36: 408 | H36: =2026-F36+1 | J36: 65 | K36: 48 | L36: 20 | M36: 복도식 | N36: 2 | O36: 1 | P36: 192 | U36: 1.1 | V36: 0.8
A37: 남산동 | D37: 7610 | E37: 대우2차 | F37: 1991.09 | G37: 408 | H37: =2026-F37+1 | J37: 83 | K37: 67 | L37: 25 | M37: 계단식 | N37: 3 | O37: 1 | P37: 72 | U37: 1.7 | V37: 1.3
A38: 남산동 | D38: 7610 | E38: 대우2차 | F38: 1991.09 | G38: 408 | H38: =2026-F38+1 | J38: 84 | K38: 68 | L38: 25 | M38: 계단식 | N38: 3 | O38: 1 | P38: 72 | U38: 1.7 | V38: 1.3
A39: 남산동 | D39: 7610 | E39: 대우2차 | F39: 1991.09 | G39: 408 | H39: =2026-F39+1 | J39: 96 | K39: 78 | L39: 29 | M39: 계단식 | N39: 3 | O39: 2 | P39: 24
A40: 남산동 | D40: 7610 | E40: 대우2차 | F40: 1991.09 | G40: 408 | H40: =2026-F40+1 | J40: 98 | K40: 80 | L40: 30 | M40: 계단식 | N40: 3 | O40: 1 | P40: 48 | U40: 1.85 | V40: 1.45
...

Sheet 송파구
B2: 상 | C2: 중 | G2: 위례신동시트램정보 | J2: 거여·마천뉴타운, | M2: 한 달 5kg 감량하며 깨달은 의지력 없이 성과를 내는 '환경셋팅'의 비밀 [골드트윈] | P2: 성동구치소 개발 논란 - 나무위키
B3: 하 | G3: 재건축·재개발 이주 난항 | J3: 특전사 부대 이전북(北)위례신도시' | M3: 지방투자실전반 '임장보고서' 20장 쓰는 방법_입지편 [성공루틴]
A4: 84 | B4: 선호도 | E4: 단지정보 (30평) | AH4: 투자결과
B5: 생활권 | C5: 생활권 내 | D5: 단지코드 | E5: 단지명 | F5: 전용면적 | G5: 매 | H5: 전 | I5: 차 | J5: 전세가율 | K5: 사용승인일 | L5: 총세대수 | M5: 나이 | N5: 평형별 세대수 | O5: 타입 | P5: 공급면적 | Q5: 평형 | R5: 구조 | S5: 방수 | T5: 욕실수 | U5: 전고 | V5: 전저 | W5: 계/복 | X5: 방 | Y5: 화 | Z5: 면적세대수 | AA5: 시기(년) | AB5: (전세가율80%이상인)기간 | AC5: 평형 | AD5: 매매가 | AE5: 전세가 | AF5: 전세가율 | AG5: 투자금 | AH5: 시기(년) | AI5: 매매가 | AJ5: 수익금 | AK5: 상승율 | AL5: 수익율
A6: 가락동 | D6: 594 | E6: 가락금호 | F6: 59 | G6: 184500 | H6: 75000 | I6: =G6-H6 | J6: =H6/G6 | K6: 1997.08 | L6: 915 | M6: =2026-INT(K6)+1 | N6: 19 | P6: 80 | Q6: 24 | R6: 복도식 | S6: 3 | T6: 1 | U6: 14 | V6: 7.5 | W6: 복도식 | X6: 3 | Y6: 1 | Z6: 19
A7: 가락동 | D7: 594 | E7: 가락금호 | F7: 59 | I7: =G7-H7 | J7: =H7/G7 | K7: 1997.08 | L7: 915 | M7: =2026-INT(K7)+1 | N7: 322 | P7: 81 | Q7: 25 | R7: 복도식 | S7: 3 | T7: 2 | U7: 14 | V7: 7.5 | W7: 복도식 | X7: 3 | Y7: 2 | Z7: 322
A8: 가락동 | D8: 594 | E8: 가락금호 | F8: 59 | I8: =G8-H8 | J8: =H8/G8 | K8: 1997.08 | L8: 915 | M8: =2026-INT(K8)+1 | N8: 117 | P8: 81 | Q8: 25 | R8: 복도식 | S8: 2 | T8: 1 | U8: 14 | V8: 7.5 | W8: 복도식 | X8: 2 | Y8: 1 | Z8: 117
A9: 가락동 | D9: 594 | E9: 가락금호 | F9: 84 | G9: 217000 | H9: 90000 | I9: =G9-H9 | J9: =H9/G9 | K9: 1997.08 | L9: 915 | M9: =2026-INT(K9)+1 | N9: 52 | P9: 107 | Q9: 32 | R9: 계단식 | S9: 3 | T9: 2 | U9: 16.15 | V9: 10.5 | W9: 계단식 | X9: 3 | Y9: 2 | Z9: 52
A10: 가락동 | D10: 594 | E10: 가락금호 | F10: 85 | I10: =G10-H10 | J10: =H10/G10 | K10: 1997.08 | L10: 915 | M10: =2026-INT(K10)+1 | N10: 405 | P10: 108 | Q10: 33 | R10: 계단식 | S10: 3 | T10: 2 | U10: 16.15 | V10: 10.5 | W10: 계단식 | X10: 3 | Y10: 2 | Z10: 405
A11: 가락동 | D11: 595 | E11: 가락대림 | F11: 59 | G11: 131001 | H11: 50401 | I11: =G11-H11 | J11: =H11/G11 | K11: 1988.11 | L11: 443 | M11: =2026-INT(K11)+1 | N11: 30 | P11: 73 | Q11: 22 | R11: 계단식 | S11: 2 | T11: 1 | U11: 12.15 | V11: 8.5 | W11: 계단식 | X11: 2 | Y11: 1 | Z11: 30
A12: 가락동 | D12: 595 | E12: 가락대림 | F12: 68 | I12: =G12-H12 | J12: =H12/G12 | K12: 1988.11 | L12: 443 | M12: =2026-INT(K12)+1 | N12: 45 | P12: 88 | Q12: 27 | R12: 복도식 | S12: 2 | T12: 1 | V12: 9.4 | W12: 복도식 | X12: 2 | Y12: 1 | Z12: 45
A13: 가락동 | D13: 595 | E13: 가락대림 | F13: 69 | G13: 160000 | H13: 52501 | I13: =G13-H13 | J13: =H13/G13 | K13: 1988.11 | L13: 443 | M13: =2026-INT(K13)+1 | N13: 30 | P13: 90 | Q13: 27 | R13: 복도식 | S13: 2 | T13: 1 | U13: 12.85 | V13: 9.4 | W13: 복도식 | X13: 2 | Y13: 1 | Z13: 30
A14: 가락동 | D14: 595 | E14: 가락대림 | F14: 76 | I14: =G14-H14 | J14: =H14/G14 | K14: 1988.11 | L14: 443 | M14: =2026-INT(K14)+1 | N14: 30 | P14: 95 | Q14: 29 | R14: 계단식 | S14: 3 | T14: 1 | V14: 10 | W14: 계단식 | X14: 3 | Y14: 1 | Z14: 30
A15: 가락동 | D15: 595 | E15: 가락대림 | F15: 84 | G15: 189000 | H15: 72001 | I15: =G15-H15 | J15: =H15/G15 | K15: 1988.11 | L15: 443 | M15: =2026-INT(K15)+1 | N15: 168 | P15: 101 | Q15: 31 | R15: 계단식 | S15: 3 | T15: 1 | U15: 14.3 | V15: 10.8 | W15: 계단식 | X15: 3 | Y15: 1 | Z15: 168
A16: 가락동 | D16: 595 | E16: 가락대림 | F16: 99 | I16: =G16-H16 | J16: =H16/G16 | K16: 1988.11 | L16: 443 | M16: =2026-INT(K16)+1 | N16: 56 | P16: 118 | Q16: 36 | R16: 계단식 | S16: 3 | T16: 1 | U16: 14.38 | V16: 11.9 | W16: 계단식 | X16: 3 | Y16: 1 | Z16: 56
A17: 가락동 | D17: 595 | E17: 가락대림 | F17: 113 | I17: =G17-H17 | J17: =H17/G17 | K17: 1988.11 | L17: 443 | M17: =2026-INT(K17)+1 | N17: 28 | P17: 133 | Q17: 40 | R17: 계단식 | S17: 4 | T17: 2 | W17: 계단식 | X17: 4 | Y17: 2 | Z17: 28
A18: 가락동 | D18: 595 | E18: 가락대림 | F18: 120 | I18: =G18-H18 | J18: =H18/G18 | K18: 1988.11 | L18: 443 | M18: =2026-INT(K18)+1 | N18: 56 | P18: 141 | Q18: 43 | R18: 계단식 | S18: 3 | T18: 1 | U18: 17 | W18: 계단식 | X18: 3 | Y18: 1 | Z18: 56
A19: 가락동 | D19: 2997 | E19: 가락동부센트레빌 | F19: 115 | I19: =G19-H19 | J19: =H19/G19 | K19: 2001.11 | L19: 264 | M19: =2026-INT(K19)+1 | N19: 135 | P19: 141 | Q19: 43 | R19: 복합식 | S19: 4 | T19: 2 | U19: 18.2 | V19: 15.85 | W19: 복합식 | X19: 4 | Y19: 2 | Z19: 135
